Workbook

Sheet Fund I RYG
B2: Fund I Portfolio Health
B3: Company | C3: Initial Inv. Date | D3: Initial Inv. Series | E3: Current Inv. Series | F3: Last Valuation | G3: SV Holding Value | H3: FD% | I3: $ Invested | J3: % of Invested Cost | K3: Current Market Value | L3: Portfolio Value | M3: MOIC | N3: 2025E Rev | O3: 2024A Rev | P3: 2025E ARR | Q3: 2024 ARR | R3: Rev/ARR Growth YoY | S3: Rev Multiple | T3: Q2 Status | U3: Current Q3 Status | V3: Rationale | W3: Fundraising/Current Runway | X3: Other key highlights
B4: Spring | C4: 43244 | D4: Seed | E4: E | F4: 3300000000 | G4: 3300000000 | H4: 0.0087 | I4: 1449990.3 | J4: =I4/$I$25 -> 0.095270258 | K4: 28841289 | L4: =K4/$K$25 -> 0.31465487 | M4: =K4/I4 -> 19.890677 | N4: No FS | O4: No FS | P4: 750000000 | Q4: No FS | R4: No data | S4: - | T4: 1 | U4: 1 | V4: Continues to beat plan and is approaching profitability | W4: Potential IPO Candidate | X4: In Oct 2025, released the “VERA‑MH” initiative, described as the first open-source evaluation framework for validating AI in mental-health care
B5: Rightway Health | C5: 43768 | D5: A | E5: C | F5: 625000000 | G5: 625000000 | H5: 0.0215 | I5: 999998.47 | J5: =I5/$I$25 -> 0.065703964 | K5: 13426663 | L5: =K5/$K$25 -> 0.14648322 | M5: =K5/I5 -> 13.426684 | N5: 45000000 | O5: 25972982 | P5: 83000000 | Q5: 49300395 | R5: =N5/O5-1 -> 0.73256964 | S5: =F5/N5 -> 13.888889 | T5: 1 | U5: 1 | V5: ARR is projected to to grow to $132M or by 60% by H12026. Strong retention and growth metrics | W5: 36 months | X5: Rebranded logo & reported: ~113% revenue retention, >97% client retention, and year-over-year member growth of 100%+ in 2025
B6: Human Interest | C6: 43670 | D6: B | E6: D | F6: 3000000000 | G6: 3000000000 | H6: 0.0041973601 | I6: 1090002.1 | J6: =I6/$I$25 -> 0.071617565 | K6: 10700000 | L6: =K6/$K$25 -> 0.11673567 | M6: =K6/I6 -> 9.8164952 | N6: =108402000/3*4 -> 144536000 | O6: 105094000 | P6: 161840913 | Q6: 119029044 | R6: =N6/O6-1 -> 0.37530211 | S6: =F6/N6 -> 20.756075 | T6: 1 | U6: 1 | V6: Strong revenue growth, working with 37% of all new 401(k) plans. Recent regulatory push to bring alternatives into plans. Q3 ARR at ~$162M
B7: Multiverse | C7: 43395 | D7: Seed | E7: D | F7: 1700000000 | G7: 1700000000 | H7: 0.0055 | I7: 834995.61 | J7: =I7/$I$25 -> 0.054862605 | K7: 9377802.2 | L7: =K7/$K$25 -> 0.10231065 | M7: =K7/I7 -> 11.23096 | N7: 100000000 | O7: No FS | P7: No data | Q7: No FS | R7: No data | S7: =+G7/N7 -> 17 | T7: 1 | U7: 1 | V7: AI retraining and upskilling providing tailwind, will finish Q4 with just over $70m of bookings, exceeding $62m forecast. Reported revenue was over $100m. Finished the year with Q4 growth YoY at 100%​, GM in Q4 reached 84%, +8pp YoY. Added > 250 new logos to customer list, launched in US, $38M Revenue in Q3 | W7: 44 months
B8: Rula | C8: 43719 | D8: Seed | E8: C | F8: 1250000000 | G8: 1250000000 | H8: 0.0055704752 | I8: 496199.35 | J8: =I8/$I$25 -> 0.032602314 | K8: 6277910.6 | L8: =K8/$K$25 -> 0.068491223 | M8: =K8/I8 -> 12.651993 | N8: 236000000 | O8: 121610000 | P8: 786000000 | R8: =N8/O8-1 -> 0.94062988 | S8: =F8/N8 -> 5.2966102 | T8: 1 | U8: 1 | V8: Forecasting ~2x y/y growth with revenue run rate above $200M by year end
B9: Carrot | C9: 43333 | D9: Seed | E9: D | F9: 600000000 | G9: 600000000 | H9: 0.0094339757 | I9: 999996.37 | J9: =I9/$I$25 -> 0.065703826 | K9: 5663568.2 | L9: =K9/$K$25 -> 0.061788824 | M9: =K9/I9 -> 5.6635888 | N9: No FS | O9: No FS | P9: No FS | Q9: No FS | R9: N/A | S9: - | T9: 1 | U9: 1 | V9: Scaling well with significant partnerships helping cover over 17,000 providers nationwide, expanded its U.S provider network significantly: adding ~4,200 new clinics/providers across all 50 states
B10: Pelago | C10: 43558 | D10: Seed | E10: C | F10: 365000000 | G10: 365000000 | H10: 0.01145385 | I10: 549993.11 | J10: =I10/$I$25 -> 0.036136783 | K10: 4289097.2 | L10: =K10/$K$25 -> 0.046793516 | M10: =K10/I10 -> 7.7984561 | N10: =15400000+5750000 -> 21150000 | O10: 22182779 | P10: 20000000 | Q10: 15029622 | R10: =N10/O10-1 -> -0.046557692 | S10: =F10/N10 -> 17.257683 | T10: 1 | U10: 0 | V10: Revenue is down slightly, sig decrease in 2025 ARR but forecasted ARR $10M in H1 2026 | W10: 13 months
B11: Galileo | C11: 43866 | D11: B | E11: C | F11: 361500000 | G11: 361500000 | H11: 0.0077 | I11: =1499992.69+252000 -> 1751992.7 | J11: =I11/$I$25 -> 0.11511304 | K11: 4040579.9 | L11: =K11/$K$25 -> 0.044082223 | M11: =K11/I11 -> 2.3062767 | N11: 47000000 | O11: 39582208 | P11: 20150000 | Q11: 6021046 | R11: =N11/O11-1 -> 0.18740218 | S11: =F11/N11 -> 7.6914894 | T11: -1 | U11: 0 | V11: Completed recap in Q3, completing transition away from shared savings to FFS / Capitated, $16M loan from SVB | W11: Budget in flux | X11: Barbara Wachsman joined the Galileo team as Head of Employer Strategy.
B12: XP | C12: 43817 | D12: Seed | E12: B | F12: 120000000 | G12: 120000000 | H12: 0.016510945 | I12: 800000 | J12: =I12/$I$25 -> 0.052563251 | K12: 1981323 | L12: =K12/$K$25 -> 0.021615987 | M12: =K12/I12 -> 2.4766537 | N12: =8889758+3653000 -> 12542758 | O12: 9100316 | P12: 13806000 | Q12: 11207000 | R12: =N12/O12-1 -> 0.37827719 | S12: =F12/N12 -> 9.5672738 | T12: 1 | U12: 0 | V12: Slight ARR growth in Q3/25 with the launch of a few smaller clients, followed by material growth in Q4/25 . Based upon the implemented expense reductions, included a substantial reduction of our staff, we expect to reach breakeven without the need for external capital | W12: - | X12: how is enterprise adoption panning out?, Ameriflex partnership?
B13: Fountain | C13: 43789 | D13: B | E13: C | F13: 860000000 | G13: 860000000 | H13: 0.0019508497 | I13: 499996.82 | J13: =I13/$I$25 -> 0.032851823 | K13: 1772396.1 | L13: =K13/$K$25 -> 0.01933662 | M13: =K13/I13 -> 3.5448147 | N13: =24222597+8497000 -> 32719597 | O13: 36517866 | P13: 33851000 | Q13: 31676017 | R13: =N13/O13-1 -> -0.10401125 | S13: =F13/N13 -> 26.283942 | T13: 0 | U13: 0 | V13: Revenue is down, ARR forecasts revised down from ~41M to $34M | W13: 34 months | X13: Announced its “Agentic-First Frontline Operating System” at HR Tech 2025 featuring a 12-product suite spanning hiring, onboarding, shift-management, referrals, communications and compliance.
B14: Karat | C14: 43592 | D14: B | E14: C | F14: 1111200000 | G14: Pref Stack - $168.8M | H14: 0.004707841 | I14: 999994.83 | J14: =I14/$I$25 -> 0.065703724 | K14: 999994.83 | L14: =K14/$K$25 -> 0.010909819 | M14: =K14/I14 -> 1 | N14: =16734498+6826439 -> 23560937 | O14: 16800000 | R14: =N14/O14-1 -> 0.40243673 | S14: =F14/N14 -> 47.16281 | T14: 0 | U14: 0 | V14: Holding at preference stack, modest growth (1.4x) but 2+ years of runway. | W14: 24 months | X14: Acquired Byteboard in early 2025, skill based technical assessment company, how is this acq progressing? New add on services?
B15: Ladder | C15: 43866 | D15: C | E15: D | F15: 330000000 | G15: 330000000 | H15: 0.0024800544 | I15: 749994.59 | J15: =I15/$I$25 -> 0.049277693 | K15: 759917.21 | L15: =K15/$K$25 -> 0.0082906021 | M15: =K15/I15 -> 1.0132302 | N15: =26013880*2 -> 52027760 | O15: 49313412 | P15: No forecasts provided | R15: =N15/O15-1 -> 0.055042794 | S15: =F15/N15 -> 6.3427678 | T15: 0 | U15: 0 | V15: Recapitalized business, at $50M revenue run rate
B16: Brightside Benefit | C16: 43775 | D16: A | E16: B | F16: 170000000 | G16: 170000000 | H16: 0.0011185071 | I16: 499999.53 | J16: =I16/$I$25 -> 0.032852001 | K16: 438844.21 | L16: =K16/$K$25 -> 0.0047877357 | M16: =K16/I16 -> 0.87768924 | N16: 29602894 | O16: 19460502 | P16: 32000000 | Q16: 31348884 | R16: =N16/O16-1 -> 0.52117833 | S16: =F16/N16 -> 5.7426818 | T16: 0 | U16: 0 | V16: Closed a round and scaled to $30M ARR with major partnerships
B17: Charthop | C17: 43740 | D17: Seed | E17: C | F17: 270000000 | G17: Pref Stack - $75M | H17: 0.0082354955 | I17: 1200001.7 | J17: =I17/$I$25 -> 0.078844987 | K17: 1200001.7 | L17: =K17/$K$25 -> 0.013091869 | M17: =K17/I17 -> 1 | N17: 8668373 | O17: 7936982 | P17: 8074878 | Q17: 9445102 | R17: =N17/O17-1 -> 0.092149762 | S17: =F17/N17 -> 31.147714 | T17: -1 | U17: -1 | V17: Revenue forecast is up ~9%, signed new business with Kraken, ~1.5 yrs of runway, holding at preference stack, forecasting ~12M by end of 2026. ARR up 7% YOY | W17: 16 months | X17: introduced ChartHop AI, a new capability that merges people data with business metrics and overlays role-based security controls, new VP of sales hired, feedback from HR Tech?
B18: Terminal | C18: 43727 | D18: B | E18: B | F18: 137000000 | G18: 0 | H18: 0.0041771259 | I18: 599999.73 | J18: =I18/$I$25 -> 0.039422421 | K18: 0 | L18: =K18/$K$25 -> 0 | M18: =K18/I18 -> 0 | N18: 47509757 | O18: 47067203 | P18: 49275176 | Q18: 41384666 | R18: =N18/O18-1 -> 0.0094025982 | S18: =F18/N18 -> 2.8836182 | T18: -1 | U18: -1 | V18: Cash flow positive mid-next year, revenue is flat
B19: Hone | C19: 43262 | D19: Seed | E19: B | F19: 126200000 | G19: 126200000 | H19: 0.013943702 | I19: 682666.27 | J19: =I19/$I$25 -> 0.044853948 | K19: 1756737.3 | L19: =K19/$K$25 -> 0.019165785 | M19: =K19/I19 -> 2.5733472 | N19: 7921721 | O19: 7590763 | P19: 8554337 | Q19: 7118996 | R19: =N19/O19-1 -> 0.043600097 | S19: =F19/N19 -> 15.930882 | T19: 0 | U19: -1 | V19: Revenue is flat, opportunity to reinvigorate growth via AI automation? 8 month runway left | W19: <1 year | X19: Hone has rolled out an AI Coach feature to reinforce skills “in the flow of work” alongside live classes.
B20: Hatch | C20: 43665 | D20: Seed | E20: Seed | F20: 25000000 | G20: 25000000 | H20: 0.0058239338 | I20: 258903.8 | J20: =I20/$I$25 -> 0.017011032 | K20: 133950.81 | L20: =K20/$K$25 -> 0.0014613866 | M20: =K20/I20 -> 0.51737674 | N20: 2974911 | O20: 760642 | P20: 1219314 | Q20: 848711 | R20: =N20/O20-1 -> 2.9110528 | S20: =F20/N20 -> 8.4036127 | T20: 0 | U20: -1 | V20: Strong rev growth, ARR seems stalled ~$1M, not much info
B21: Cleo | C21: 43328 | D21: A | E21: C | F21: 231000000 | G21: 0 | H21: 0.0016734774 | I21: 100000 | J21: =I21/$I$25 -> 0.0065704064 | K21: 0 | L21: =K21/$K$25 -> 0 | M21: =K21/I21 -> 0 | N21: No FS | O21: No FS | P21: No data | Q21: No FS | R21: No data | T21: -1 | U21: -1 | V21: N/A - proactive write-off
B22: Enrich | C22: 43829 | D22: Seed | E22: Seed | F22: 11000000 | G22: 0 | H22: 0.038095113 | I22: 399999.44 | J22: =I22/$I$25 -> 0.026281589 | K22: 0 | L22: =K22/$K$25 -> 0 | M22: =K22/I22 -> 0 | N22: 1038000 | O22: 622163 | Q22: 608121 | R22: =N22/O22-1 -> 0.66837308 | S22: =F22/N22 -> 10.597303 | T22: -1 | U22: -1 | V22: N/A - proactive write-off | W22: 30 months
B23: Vetty | C23: 43857 | D23: Seed | E23: A | F23: 13000000 | G23: 0 | H23: N/A | I23: 255034 | J23: =I23/$I$25 -> 0.01675677 | K23: 0 | L23: =K23/$K$25 -> 0 | M23: =K23/I23 -> 0 | N23: =7588530+3119277 -> 10707807 | O23: 10000000 | P23: 12477107 | Q23: 12000000 | R23: =N23/O23-1 -> 0.0707807 | S23: =F23/N23 -> 1.2140675 | T23: -1 | U23: -1 | V23: N/A - proactive write-off, ARR revised down from $14M to $12M, 4 months of runway | W23: 4 months
I25: =SUM(I4:I23) -> 15219759 | K25: =SUM(K4:K23) -> 91660075 | S25: =AVERAGE(S10:S18) -> 17.119998

Sheet Fund I Inv Char
M1: 21000000
B2: Fund I Current Investment Characteristics
B3: Company | C3: Series | D3: FD% | E3: Initial Cost | F3: Last Valuation | G3: Holding Value | H3: Potential Post Money | I3: $ Invested | J3: Current Market Value | K3: New Mark | L3: Multiple | N3: 2025 E Revenue/ARR | O3: Holding Value Implied Mult. | P3: EV at 10x | Q3: 10x EV> Holding Value | R3: 10x EV? Total Raised | S3: Raised to Date | V3: Additional Value | W3: Expected Gross MOIC | X3: Additional TVPI
B4: Spring | C4: E | D4: 0.0087 | E4: 23000000 | F4: 3300000000 | G4: 3300000000 | I4: 1449990.3 | J4: 28841289 | L4: =J4/I4 -> 19.890677 | M4: 2225.9968 | S4: $467M
B5: Rightway Health | C5: C | D5: 0.0215 | E5: 35000000 | F5: 625000000 | G5: 625000000 | H5: =ROUND(34.5/18.79*G5,-6) -> 1148000000 | I5: 999998.47 | J5: 13426663 | K5: =H5*D5 -> 24682000 | L5: =J5/I5 -> 13.426684 | M5: 12548.721 | V5: =K5-J5 -> 11255337 | W5: =K5/I5 -> 24.682038 | X5: =V5/20730000 -> 0.5429492
B6: Multiverse | C6: D | D6: 0.0055 | E6: 26000000 | F6: 1700000000 | G6: 1700000000 | I6: 834995.61 | J6: 9377802.2 | L6: =J6/I6 -> 11.23096 | M6: 1506.0563 | N6: 10554783 | O6: 11.956665 | P6: 105547830 | Q6: No | S6: $415M
B7: Rula | C7: C | D7: 0.0055704752 | E7: 12000000 | F7: 1250000000 | G7: 1250000000 | I7: 496199.35 | J7: 6277910.6 | L7: =J7/I7 -> 12.651993 | M7: 2153.0683 | Y7: 10x net revenue for a competitor
B8: Carrot | C8: D | D8: 0.0094339757 | E8: 10000000 | F8: 600000000 | G8: 600000000 | I8: 999996.37 | J8: 5663568.2 | L8: =J8/I8 -> 5.6635888 | M8: 3901.7482
B9: Human Interest | C9: F | D9: 0.0041973601 | E9: 37000000 | F9: 1250000000 | G9: 1250000000 | H9: 3000000000 | I9: 1090002.1 | J9: 5589792.5 | K9: 10743747 | L9: =J9/I9 -> 5.1282403 | M9: 1833.4447 | N9: 20000000 | O9: 18.25 | P9: 200000000 | Q9: No | S9: $700M | V9: =K9-J9 -> 5153954.5 | W9: =K9/I9 -> 9.85663 | X9: =V9/20730000 -> 0.24862299
B10: Pelago | C10: C | D10: 0.01145385 | E10: 18000000 | F10: 365000000 | G10: 365000000 | I10: 549993.11 | J10: 4289097.2 | L10: =J10/I10 -> 7.7984561 | M10: 4460.6435 | N10: 21900000 | O10: 50.739726 | P10: 219000000 | Q10: No
B11: Galileo | C11: C | D11: 0.0064925049 | E11: 106000000 | F11: 600000000 | G11: 361500000 | I11: =1499992.69+252000 -> 1751992.7 | J11: 2656434 | L11: =J11/I11 -> 1.5162358 | M11: 3605.8102 | N11: 2111099 | O11: 11.842173 | P11: 21110990 | Q11: No
B12: XP | C12: B | D12: 0.016510945 | E12: 12000000 | F12: 120000000 | G12: 120000000 | I12: 800000 | J12: 1981323 | L12: =J12/I12 -> 2.4766537 | M12: 3769.8759
B13: Fountain | C13: C | D13: 0.0019508497 | E13: 79000000 | F13: 860000000 | G13: 860000000 | I13: 499996.82 | J13: 1772396.1 | L13: =J13/I13 -> 3.5448147 | M13: 2132.4175 | N13: 21000000 | O13: 15.952381 | P13: 210000000 | Q13: No
B14: Hone | C14: B | D14: 0.013943702 | E14: 8000000 | F14: 126200000 | G14: 126200000 | I14: 682666.27 | J14: 1756737.3 | L14: =J14/I14 -> 2.5733472 | M14: 5027.3802 | N14: 41337300 | O14: 3.3141981 | P14: 413373000 | Q14: Yes
B15: Charthop | C15: C | D15: 0.0082354955 | E15: 25000000 | F15: 270000000 | G15: Preference Stack - $74M | I15: 1200001.7 | J15: 1200001.7 | L15: =J15/I15 -> 1 | M15: 2549.9376 | N15: 9744878 | O15: 27.706863 | P15: 97448780 | Q15: No
B16: Karat | C16: C | D16: 0.004707841 | E16: 138000000 | F16: 1111200000 | G16: Preference Stack - $170M | I16: 999994.83 | J16: 999994.83 | L16: =J16/I16 -> 1 | M16: 965.57517 | N16: 70638024 | O16: 8.8479259 | P16: 706380240 | Q16: Yes
B17: Ladder | C17: D | D17: 0.0024800544 | E17: 234000000 | F17: 330000000 | G17: 330000000 | I17: 749994.59 | J17: 759917.21 | L17: =J17/I17 -> 1.0132302 | M17: 18775.026 | N17: 37421387 | O17: 4.5428567 | P17: 3.7421387e+08 | Q17: Yes
B18: Brightside Benefit | C18: B | D18: 0.0011185071 | E18: 135000000 | F18: 170000000 | G18: 170000000 | I18: 499999.53 | J18: 438844.21 | L18: =J18/I18 -> 0.87768924 | M18: 10764.54 | N18: 50000000 | O18: 17.2 | P18: 500000000 | Q18: No
B19: Hatch | C19: Seed | D19: 0.0058239338 | E19: 25000000 | F19: 25000000 | G19: 25000000 | I19: 258903.8 | J19: 133950.81 | L19: =J19/I19 -> 0.51737674 | M19: 1271.8836
B20: Cleo | C20: C | D20: 0.0016734774 | E20: 33000000 | F20: 231000000 | G20: 0 | I20: 100000 | J20: 0 | L20: =J20/I20 -> 0 | M20: 551.25181
B21: Terminal | C21: B | D21: 0.0041771259 | E21: 137000000 | F21: 137000000 | G21: 0 | I21: 599999.73 | J21: 0 | L21: =J21/I21 -> 0 | M21: #VALUE!
B22: Enrich | C22: Seed | D22: 0.038095113 | E22: 11000000 | F22: 11000000 | G22: 0 | I22: 399999.44 | J22: 0 | L22: =J22/I22 -> 0 | M22: 8467.5563
B23: Vetty | C23: A | D23: N/A | E23: 13000000 | F23: 13000000 | G23: 0 | I23: 255034 | J23: 0 | L23: =J23/I23 -> 0 | M23: 3234.4989 | N23: 28530046 | O23: 21.03046 | P23: 285300460 | Q23: No
I25: =SUM(I4:I23) -> 15219759 | J25: =SUM(J4:J23) -> 85165722 | L25: =J25/I25 -> 5.595734 | V25: =SUM(V4:V23) -> 16409291 | X25: =V25/20730000 -> 0.79157218
B27: *excludes investments that have been completely w/o /realized or are public

Sheet Fund II RYG
B2: Fund II Portfolio Health
B3: Company | C3: Initial Inv. Date | D3: Initial Inv. Series | E3: Current Inv. Series | F3: Last Valuation | G3: SV Holding Value | H3: FD % | I3: $ Invested | K3: Current Market Value | L3: Portfolio Value | M3: MOIC | N3: 2025E Rev | O3: 2024A Rev | P3: 2025E ARR | Q3: 2024 ARR | R3: Rev/ARR Growth YoY | S3: Rev Multiple | T3: Q2 Status | U3: Current Q3 Status | V3: Rationale | W3: Fundraising/Current Runway | X3: Other key highlights
B4: Midi | C4: 44455 | D4: Seed | E4: D | F4: 1150000000 | G4: =F4 -> 1150000000 | H4: =VLOOKUP(B4,Sheet1!$K$4:$N$32,4,0) -> 0.0483 | I4: 5531507 | J4: =I4/$I$32 -> 0.093436992 | K4: =24143029.3692*1.995 -> 48165344 | L4: =K4/$K$32 -> 0.33444623 | M4: =K4/I4 -> 8.7074542 | N4: =190000000 -> 190000000 | O4: 37586650 | P4: 129267358 | Q4: 58853221 | R4: =N4/O4-1 -> 4.0549863 | S4: =F4/N4 -> 6.0526316 | T4: 1 | U4: 1 | V4: Beating and raising, ~$190M in revenue growing ~5x y/y
B5: Rula | C5: 44265 | D5: A | E5: C | F5: 1250000000 | G5: =F5 -> 1250000000 | H5: =VLOOKUP(B5,Sheet1!$K$4:$N$32,4,0) -> 0.019806577 | I5: 4500000 | J5: =I5/$I$32 -> 0.076013004 | K5: 25285301 | L5: =K5/$K$32 -> 0.17557382 | M5: =K5/I5 -> 5.6189558 | N5: 236000000 | O5: 121610000 | P5: 786000000 | R5: =N5/O5-1 -> 0.94062988 | S5: =F5/N5 -> 5.2966102 | T5: 1 | U5: 1 | V5: Forecasting 2x y/y growth with revenue run rate above $200M by year end
B6: Remote | C6: 44398 | D6: B | E6: D | F6: 3000000000 | G6: =F6 -> 3000000000 | H6: =VLOOKUP(B6,Sheet1!$K$4:$N$32,4,0) -> 0.003599981 | I6: 4781446 | J6: =I6/$I$32 -> 0.080767127 | K6: 10354762 | L6: =K6/$K$32 -> 0.071900472 | M6: =K6/I6 -> 2.165613 | N6: No FS | O6: No FS | P6: 350000000 | Q6: No FS | R6: - | S6: =F6/P6 -> 8.5714286 | T6: 1 | U6: 1 | V6: Forecasting to accelerate above $350M ARR, continued tailwinds from global workforce | X6: Launched AI powered workflows - next gen payroll
B7: Ashby | C7: 44599 | D7: B | E7: C | F7: 500000000 | G7: =F7 -> 500000000 | H7: =VLOOKUP(B7,Sheet1!$K$4:$N$32,4,0) -> 0.020715715 | I7: 5000000 | J7: =I7/$I$32 -> 0.084458893 | K7: 10135319 | L7: =K7/$K$32 -> 0.070376727 | M7: =K7/I7 -> 2.0270638 | N7: =16207350+10621813 -> 26829163 | O7: 14028342 | P7: 47144781 | Q7: 21606717 | R7: =N7/O7-1 -> 0.91249707 | S7: =F7/N7 -> 18.636437 | T7: 1 | U7: 1 | V7: Closed a $50M Series D at a ~2x step-up from previous round, strong growth
B8: Liftoff | C8: 45064 | D8: Seed | E8: Seed | F8: 39000000 | G8: =F8 -> 39000000 | H8: =VLOOKUP(B8,Sheet1!$K$4:$N$32,4,0) -> 0.05 | I8: 886565.66 | J8: =I8/$I$32 -> 0.014975671 | K8: 1896344.2 | L8: =K8/$K$32 -> 0.013167666 | M8: =K8/I8 -> 2.1389777 | N8: 14000 | O8: 12600 | P8: No data | Q8: No data | R8: =N8/O8-1 -> 0.11111111 | S8: N/A | T8: 1 | U8: 1 | V8: Came out of stealth in Oct 25, good organic growth, no real monetization yet, positive for now but will need to watch the story unfold from here | W8: 30 months
B9: Brightline | C9: 44047 | D9: A | E9: C | F9: 705200000 | G9: =F9 -> 705200000 | H9: =VLOOKUP(B9,Sheet1!$K$4:$N$32,4,0) -> 0.0060300575 | I9: 1499987 | J9: =I9/$I$32 -> 0.025337449 | K9: 4521963.7 | L9: =K9/$K$32 -> 0.031399209 | M9: =K9/I9 -> 3.0146685 | N9: 46580844 | O9: 52238905 | P9: No data | Q9: No data | R9: =N9/O9-1 -> -0.10831125 | S9: =F9/N9 -> 15.139271 | T9: 1 | U9: 0 | V9: Revenue is down slightly yoy, profitable this year. Focusing on delivering care in person, opened 3rd clinic in NY, leadership change, revenue growth -ve, have they de-risked the hybrid model yet? Can it grow and scale? Valuation multiple seems high given the fact pattern | X9: The company expanded its leadership team (operations, product & engineering) in support of its hybrid care strategy and deeper insurer partnerships
B10: CoverGo | C10: 44621 | D10: A | E10: A | F10: 43000000 | G10: =F10 -> 43000000 | H10: =VLOOKUP(B10,Sheet1!$K$4:$N$32,4,0) -> 0.093023256 | I10: 4000000 | J10: =I10/$I$32 -> 0.067567115 | K10: 5294506.9 | L10: =K10/$K$32 -> 0.036763526 | M10: =K10/I10 -> 1.3236267 | N10: =4476975+2898051+3272929 -> 10647955 | O10: 7131378 | P10: 7994010 | Q10: 4957248 | R10: =N10/O10-1 -> 0.49311325 | S10: =F10/N10 -> 4.0383341 | T10: 0 | U10: 0 | V10: Reaccelerated growth, forecasting 2x y/y growth and close to breakeven, yellow for now, will see how the raise goes | W10: 6 months, starting B raise in Q4/Q1'26
B11: Cocoon | C11: 44232 | D11: Seed | E11: A | F11: 1.6250158e+08 | G11: Pref Stack - $26M | H11: =VLOOKUP(B11,Sheet1!$K$4:$N$32,4,0) -> 0.027242491 | I11: 4224996.6 | J11: =I11/$I$32 -> 0.071367707 | K11: 4224996.6 | L11: =K11/$K$32 -> 0.029337155 | M11: =K11/I11 -> 1 | N11: =4118018+2153019 -> 6271037 | O11: 4222643 | P11: 9626246 | Q11: 5424822 | R11: =N11/O11-1 -> 0.4850976 | S11: =F11/N11 -> 25.913032 | T11: 0 | U11: 0 | V11: Contracted ARR at ~$10M, strong product expansion and channel traction with Gurdian/Sedgewick moving into enterprises, moved into variable hourly workers market (increased TAM?). Increased distribution scale + partner validation should move this into green? Rev multiple seems high | W11: 8 months | X11: Gaurdian PEO Distribution - massive channel and disty partnership, will reduce CAC, Enterprise with Sedgewick, SMB/PEO Market capture with Gaurdian, HCM partnerships with workday, adp, paychex
B12: Gable | C12: 44848 | D12: A | E12: A | F12: 50000000 | G12: =F12 -> 50000000 | H12: =VLOOKUP(B12,Sheet1!$K$4:$N$32,4,0) -> 0.08 | I12: 4000000 | J12: =I12/$I$32 -> 0.067567115 | K12: 4000000 | L12: =K12/$K$32 -> 0.027774844 | M12: =K12/I12 -> 1 | N12: 5591913 | O12: 1865748 | P12: =2184011+1284518 -> 3468529 | Q12: 1423910 | R12: =N12/O12-1 -> 1.9971427 | S12: =F12/N12 -> 8.9414839 | T12: 0 | U12: 0 | V12: Forecasting $7.8M ARR by end of Q1'26. Sep run rate at $3.6M. Raised internal bridge round, forecasting ~3x growth and scale appropriate for Series B. Reduced burn, have reduced costs and improved EBITDA. Rev multiple seems high, would want to keep this at yellow. | W12: 13 months
B13: Mosey | C13: 44707 | D13: A | E13: A | F13: 88000000 | G13: =F13 -> 88000000 | H13: =VLOOKUP(B13,Sheet1!$K$4:$N$32,4,0) -> 0.045455 | I13: 3999998.9 | J13: =I13/$I$32 -> 0.067567096 | K13: 3999998.9 | L13: =K13/$K$32 -> 0.027774836 | M13: =K13/I13 -> 1 | N13: =685409*2 -> 1370818 | O13: 938232 | P13: 1481268 | Q13: 1057993 | R13: =N13/O13-1 -> 0.46106507 | S13: =F13/N13 -> 64.195247 | T13: 0 | U13: 0 | V13: Revenue growing ~46% y/y and significant integrations into payroll providers, val multiple too high | W13: 24 months
B14: Nayya | C14: 44344 | D14: B | E14: C | F14: 4.8781374e+08 | G14: =F14 -> 4.8781374e+08 | H14: =VLOOKUP(B14,Sheet1!$K$4:$N$32,4,0) -> 0.0076636442 | I14: 2699987.1 | J14: =I14/$I$32 -> 0.045607585 | K14: 3853385.4 | L14: =K14/$K$32 -> 0.026756794 | M14: =K14/I14 -> 1.4271866 | N14: =19723132+8128680 -> 27851812 | O14: 16056400 | P14: 35344400 | Q14: 28364777 | R14: =N14/O14-1 -> 0.7346237 | S14: =F14/N14 -> 17.514614 | T14: 1 | U14: 0 | V14: Reduced ARR forecast by 20%, reduced growth <2x, strong partnerships are encouraging but needs to convert to ARR contribution and signed deployments. Would suggest yellow. | W14: 17 months | X14: Contract with Google, Acquired Northstar (financial wellness company), Strada announces “exclusive” Nayya partnership at Workday Rising
B15: Origin | C15: 44307 | D15: A | E15: B | F15: 401250000 | G15: Pref Stack - $136.5M | H15: =VLOOKUP(B15,Sheet1!$K$4:$N$32,4,0) -> 0.027099272 | I15: 3699992.1 | J15: =I15/$I$32 -> 0.062499448 | K15: 3699992.1 | L15: =K15/$K$32 -> 0.025691676 | M15: =K15/I15 -> 1 | N15: =5525377*2 -> 11050754 | O15: No data yet | P15: 15000000 | Q15: 9910000 | T15: 0 | U15: 0 | V15: Wrote down to preference stack, undergoing pivot away from B2B model | W15: 19 months
B16: ianacare | C16: 44547 | D16: A | E16: A | F16: 60000000 | G16: =F16 -> 60000000 | H16: =VLOOKUP(B16,Sheet1!$K$4:$N$32,4,0) -> 0.01664562 | I16: 2999984.9 | J16: =I16/$I$32 -> 0.05067508 | K16: 2999984.9 | L16: =K16/$K$32 -> 0.020831028 | M16: =K16/I16 -> 1 | N16: =1614535+380000 -> 1994535 | O16: 1044591 | P16: 2000000 | Q16: 246432 | R16: =N16/O16-1 -> 0.90939325 | S16: =F16/N16 -> 30.0822 | T16: 0 | U16: 0 | V16: Regulatory tailwinds from GUIDE program driving growth as company shifts away from employer. Expect GUIDE revenue to ramp from 6 digit ARR to 7 digit ARR in the next 6-9 months. They revised 2025E ARR projectons down by 25% but expect visibility into GUIDE related ARR to dramatically increase over next 12 months. | W16: 12 months
B17: Delfina | C17: 44621 | D17: Seed | E17: A | F17: 50000000 | G17: =F17 -> 50000000 | H17: =VLOOKUP(B17,Sheet1!$K$4:$N$32,4,0) -> 0.041920188 | I17: 1549999.9 | J17: =I17/$I$32 -> 0.026182256 | K17: 2097344.6 | L17: =K17/$K$32 -> 0.014563355 | M17: =K17/I17 -> 1.3531256 | N17: 2266666 | O17: 1333980 | P17: No FS | Q17: No FS | R17: =N17/O17-1 -> 0.6991754 | S17: =F17/N17 -> 22.05883 | T17: 0 | U17: 0 | V17: Didn't provide revenue projections but taking a hit due to Medicaid budget cuts. Actuals down from projections
B18: Galileo | C18: 44232 | D18: C | E18: C | F18: 361500000 | G18: 361500000 | H18: =VLOOKUP(B18,Sheet1!$K$4:$N$32,4,0) -> 0.0041856851 | I18: 2163902 | J18: =I18/$I$32 -> 0.036552154 | K18: 1724879 | L18: =K18/$K$32 -> 0.011977061 | M18: =K18/I18 -> 0.79711512 | N18: =19556915+10625000 -> 30181915 | O18: 39582208 | P18: 20150000 | Q18: 6021046 | R18: =N18/O18-1 -> -0.23748784 | S18: =F18/N18 -> 11.977371 | T18: -1 | U18: 0 | V18: Completed recap in Q3, completing transition away from shared savings to FFS / Capitated | X18: Galileo Launches First Fully Bilingual Health Care Platform Delivering 24/7 Primary and Multi-Specialty Care
B19: Pinwheel | C19: 44105 | D19: A | E19: B | F19: 4.965001e+08 | G19: Pref Stack - $78M | H19: =VLOOKUP(B19,Sheet1!$K$4:$N$32,4,0) -> 0.0057927248 | I19: 1453156.1 | J19: =I19/$I$32 -> 0.024546391 | K19: 1453156.1 | L19: =K19/$K$32 -> 0.010090296 | M19: =K19/I19 -> 1 | N19: =8180288+3100000 -> 11280288 | O19: 8972963 | P19: 13000000 | Q19: 9916578 | R19: =N19/O19-1 -> 0.25714193 | S19: =F19/N19 -> 44.014843 | T19: 0 | U19: 0 | V19: 30 months of runway, undergoing CEO change, written-down to cost in Q3 | W19: 30 months
B20: Formally | C20: 45006 | D20: Seed | E20: Seed | F20: 25000000 | G20: =F20 -> 25000000 | H20: =VLOOKUP(B20,Sheet1!$K$4:$N$32,4,0) -> 0.04 | I20: 1000000 | J20: =I20/$I$32 -> 0.016891779 | K20: 1000000 | L20: =K20/$K$32 -> 0.006943711 | M20: =K20/I20 -> 1 | N20: No FS | O20: No FS | P20: No FS | Q20: No FS | T20: 0 | U20: 0 | V20: Legal AI is driving renewed interest and company continues to sell well into legal firms
B21: a.team | C21: 44567 | D21: A | E21: A | F21: 325000000 | G21: =F21 -> 325000000 | H21: =VLOOKUP(B21,Sheet1!$K$4:$N$32,4,0) -> 0.0030769253 | I21: 999998.86 | J21: =I21/$I$32 -> 0.016891759 | K21: 999998.86 | L21: =K21/$K$32 -> 0.0069437031 | M21: =K21/I21 -> 1 | N21: No FS | O21: No FS | P21: No FS | Q21: No FS | T21: 0 | U21: 0 | V21: Over 2 years of runway, $10M+ ARR
B22: Finch | C22: 44435 | D22: A | E22: B | F22: 200000000 | G22: =F22 -> 200000000 | H22: =VLOOKUP(B22,Sheet1!$K$4:$N$32,4,0) -> 0.0032205422 | I22: 500003.42 | J22: =I22/$I$32 -> 0.0084459471 | K22: 740862.12 | L22: =K22/$K$32 -> 0.0051443324 | M22: =K22/I22 -> 1.4817141 | N22: =2000000*4 -> 8000000 | O22: 6847796 | P22: 7893656 | Q22: 8900000 | R22: =N22/O22-1 -> 0.1682591 | S22: =F22/N22 -> 25 | T22: 1 | U22: 0 | V22: HR Tech API, Modest growth in Rev, ARR is down ~10% when compared to product traction (seems substantial), high growth margins ~80%, val multiples seem high when compared to industry (peaking at ~20x), retention/churn metrics and high val multiple would suggest yellow (high yellow - cautious but positive) | W22: 34 months | X22: Connected to over 220+ systems, ~80% U.S. employer coverage, 52,000+ employers
B23: Patch | C23: 44879 | D23: Seed | E23: Seed | F23: 8000000 | G23: Acq | H23: Acq | I23: 411246 | J23: =I23/$I$32 -> 0.0069466764 | K23: 586415 | L23: =K23/$K$32 -> 0.0040718963 | M23: =K23/I23 -> 1.425947 | N23: No FS | O23: No FS | P23: No FS | Q23: No FS | T23: 1 | U23: 0 | V23: Acquired by Wellthy, our share is valued at ~600k. No access to FI
B24: Rightfoot | C24: 44175 | D24: Seed | E24: A | F24: 55000000 | G24: 0 | H24: =VLOOKUP(B24,Sheet1!$K$4:$N$32,4,0) -> 0.012564741 | I24: 399999.32 | J24: =I24/$I$32 -> 0.0067567 | K24: 0 | L24: =K24/$K$32 -> 0 | M24: =K24/I24 -> 0 | T24: 0 | U24: 0 | V24: Showing signs of significant growth after undergoing pivot, monitoring to write back up to cost
B25: Vivante | C25: 44552 | D25: A | E25: B | F25: 84077296 | G25: =F25 -> 84077296 | H25: =VLOOKUP(B25,Sheet1!$K$4:$N$32,4,0) -> 0.037179658 | I25: 2204142.3 | J25: =I25/$I$32 -> 0.037231884 | K25: 3130662 | L25: =K25/$K$32 -> 0.021738412 | M25: =K25/I25 -> 1.4203538 | N25: 15200000 | O25: 17400000 | R25: =N25/O25-1 -> -0.12643678 | S25: =F25/N25 -> 5.531401 | T25: 1 | U25: -1 | V25: Down round, strucured pay to play with punitive provisions
B26: Violet | C26: 44722 | D26: Seed | E26: Seed | F26: 22000000 | G26: =F26 -> 22000000 | H26: =VLOOKUP(B26,Sheet1!$K$4:$N$32,4,0) -> 0.12409 | I26: 2599995.3 | J26: =I26/$I$32 -> 0.043918545 | K26: 2599995.3 | L26: =K26/$K$32 -> 0.018053616 | M26: =K26/I26 -> 1 | N26: 1870752 | P26: 2500000 | Q26: 1624000 | R26: =P26/Q26-1 -> 0.53940887 | S26: =F26/P26 -> 8.8 | T26: 0 | U26: -1 | V26: Modest growth yoy (1.53x) Actively pursuing M&A, UCare contract cancelled as Medicaid related churn coming to fruition, $2.7M ARR Churn (230k/month) | W26: Cash & AR: $592k ($395k cash + $197k AR) Additional guaranteed Rev til EOM Jan: $287k Total: $879k Burn: $230k / month = 3.82 months cash out date
B27: Bravely | C27: 44379 | D27: A | E27: A | F27: 67500000 | G27: =F27 -> 67500000 | H27: =VLOOKUP(B27,Sheet1!$K$4:$N$32,4,0) -> 0.018518542 | I27: 1249999.6 | J27: =I27/$I$32 -> 0.021114716 | K27: 1249999.6 | L27: =K27/$K$32 -> 0.0086796356 | M27: =K27/I27 -> 1 | N27: No FS | O27: No FS | P27: No FS | Q27: No FS | R27: N/A | S27: N/A | T27: -1 | U27: -1 | V27: Looking to capture AI tailwinds with a $5M+ install base
B28: Murmur | C28: 44098 | D28: Seed | E28: Seed | F28: 28000000 | G28: 0 | H28: =VLOOKUP(B28,Sheet1!$K$4:$N$32,4,0) -> 0.064069691 | I28: 1574998 | J28: =I28/$I$32 -> 0.026604518 | K28: 0 | L28: =K28/$K$32 -> 0 | M28: =K28/I28 -> 0 | N28: N/A | O28: N/A | P28: N/A | Q28: N/A | R28: N/A | S28: N/A | T28: -1 | U28: -1 | V28: N/A - shutdown
B29: Cleo | C29: 44155 | D29: B | E29: C | F29: 231000000 | G29: 0 | H29: =VLOOKUP(B29,Sheet1!$K$4:$N$32,4,0) -> 0.0040460588 | I29: 599997.84 | J29: =I29/$I$32 -> 0.010135031 | K29: 0 | L29: =K29/$K$32 -> 0 | M29: =K29/I29 -> 0 | N29: No FS | O29: No FS | P29: No FS | Q29: No FS | R29: N/A | S29: N/A | T29: -1 | U29: -1 | V29: N/A - proactive write-off
B30: Praisidio | C30: 44370 | D30: Seed | E30: Seed | F30: 20000000 | G30: 0 | H30: =VLOOKUP(B30,Sheet1!$K$4:$N$32,4,0) -> 0.01 | I30: 200000 | J30: =I30/$I$32 -> 0.0033783557 | K30: 0 | L30: =K30/$K$32 -> 0 | M30: =K30/I30 -> 0 | N30: No FS | O30: No FS | P30: No FS | Q30: No FS | R30: N/A | S30: N/A | T30: -1 | U30: -1 | V30: N/A - proactive write-off
I32: =SUM(I5:I31) -> 59200397 | K32: =SUM(K4:K31) -> 1.4401521e+08
M36: =SUM(K4:K7) -> 93940725
M37: =SUM(I4:I7) -> 19812953
M38: =M36/M37 -> 4.7413793
M47: =141/5.75% -> 2452.1739

Sheet Sheet1
N1: Updated as of 9.30 | V1: =74*10^6 -> 74000000
B2: Initial Investment Characteristics | K2: Current Investment Characteristics | AM2: VOTING - "overall" by IC member | AU2: Avg Vote - by category | AY2: *Missing Vote | AZ2: Double-check | BD2: Scorecards - by category
B3: Company | C3: Date | D3: Series | E3: Sector | F3: $ Invested | G3: VC Syndicate | H3: FD% | I3: Avg. Cost | K3: Company | L3: Series | M3: $ Invested | N3: FD% | O3: Initital Cost | P3: Avg. Cost | Q3: Last Valuation | R3: Holding Value | S3: $ Invested | T3: Market Value | U3: Multiple | V3: RTF | X3: 44285 | Y3: 44469 | Z3: 44742 | AA3: 44926 | AB3: 45107 | AC3: 45291 | AD3: 45473 | AE3: 45565 | AF3: 45657 | AG3: 45838 | AH3: 45930 | AI3: Rationale | AM3: ABG | AN3: CBOU | AO3: Colin | AP3: Greg | AQ3: Robby | AS3: Overall | AT3: Team | AU3: Tech | AV3: TAM | AW3: Timing | AX3: Terms | BB3: Lead | BC3: Qual. Total | BD3: Quant. Total | BE3: Deal Terms | BF3: Total | BG3: Notes
B4: Brightline | C4: =INDEX('[1]Statement of Investments'!$C$5:$C$220,MATCH('[1]Investment Characteristics'!$B4,'[1]Statement of Investments'!$B$5:$B$220,0)) -> 44047 | D4: A | E4: Healthtech | F4: =INDEX('[1]Statement of Investments'!$L$5:$L$220,MATCH('[1]Investment Characteristics'!$B4,'[1]Statement of Investments'!$B$5:$B$220,0)) -> 499998.47 | G4: GV, Oak HC/FT, Threshold | H4: 0.006249969 | I4: 80000000 | K4: =B4 -> Brightline | L4: C | M4: =INDEX('[1]Statement of Investments'!$L$5:$L$220,MATCH('[1]Investment Characteristics'!$K4,'[1]Statement of Investments'!$E$5:$E$220,0)) -> 1499987 | N4: 0.0060300575 | O4: =I4 -> 80000000 | P4: =IFERROR(ROUND(S4/N4,-5),0) -> 248800000 | Q4: 757442906 | R4: =+Q4 -> 757442906 | S4: =INDEX('[1]Statement of Investments'!$L$5:$L$220,MATCH(B4,'[1]Statement of Investments'!$E$5:$E$220,0)) -> 1499987 | T4: =INDEX('[1]Statement of Investments'!$O$5:$O$220,MATCH(B4,'[1]Statement of Investments'!$E$5:$E$220,0)) -> 4521963.7 | U4: =T4/S4 -> 3.0146685 | V4: =+$V$1/N4/10^6 -> 12271.857 | X4: 0 | Y4: 0 | Z4: -1 | AA4: 0 | AB4: 0 | AC4: 1 | AD4: 1 | AE4: 1 | AF4: 1 | AI4: Grew 7x y/y - forecasting minimal growth as company shifts towards profitability | AM4: 2 | AN4: 1 | AO4: 2 | AP4: 1 | AQ4: 2 | AS4: 1.6 | AT4: 1.8 | AU4: 0.6 | AV4: 2 | AW4: 2 | AX4: 0.2 | BB4: ABG | BC4: 49.8 | BD4: 6.5 | BE4: 7 | BF4: 63.3
B5: Murmur | C5: =INDEX('[1]Statement of Investments'!$C$5:$C$220,MATCH('[1]Investment Characteristics'!$B5,'[1]Statement of Investments'!$B$5:$B$220,0)) -> 44098 | D5: Seed | E5: Workforce | F5: =INDEX('[1]Statement of Investments'!$L$5:$L$220,MATCH('[1]Investment Characteristics'!$B5,'[1]Statement of Investments'!$B$5:$B$220,0)) -> 225000 | G5: Lerer Hippeau, Human Ventures | H5: 0.026471511 | I5: =IFERROR(ROUND(F5/H5,-5),0) -> 8500000 | K5: Murmur | L5: Seed | M5: =INDEX('[1]Statement of Investments'!$L$5:$L$220,MATCH('[1]Investment Characteristics'!$K5,'[1]Statement of Investments'!$E$5:$E$220,0)) -> 1574998 | N5: 0.064069691 | O5: =I5 -> 8500000 | P5: =IFERROR(ROUND(S5/N5,-5),0) -> 24600000 | Q5: =28*10^6 -> 28000000 | R5: 0 | S5: =INDEX('[1]Statement of Investments'!$L$5:$L$220,MATCH(B5,'[1]Statement of Investments'!$E$5:$E$220,0)) -> 1574998 | T5: =INDEX('[1]Statement of Investments'!$O$5:$O$220,MATCH(B5,'[1]Statement of Investments'!$E$5:$E$220,0)) -> 0 | U5: =T5/S5 -> 0 | V5: =+$V$1/N5/10^6 -> 1154.9923 | X5: 0 | Y5: 0 | Z5: 1 | AA5: 0 | AB5: 0 | AC5: 1 | AD5: 0 | AE5: 0 | AF5: -1 | AG5: -1 | AH5: -1 | AI5: Pivoting product, plenty of runway but looking for PMF but likely writeoff in Q1 | AM5: 1 | AN5: 1 | AO5: 1 | AP5: 1 | AQ5: 1 | AS5: 1 | AT5: 1.3 | AU5: 0.7 | AV5: 1.7 | AW5: 2 | AX5: 2 | BB5: ABG | BC5: 44 | BD5: 8 | BE5: 9 | BF5: 61
B6: Pinwheel | C6: =INDEX('[1]Statement of Investments'!$C$5:$C$220,MATCH('[1]Investment Characteristics'!$B6,'[1]Statement of Investments'!$B$5:$B$220,0)) -> 44105 | D6: A | E6: Financial | F6: =INDEX('[1]Statement of Investments'!$L$5:$L$220,MATCH('[1]Investment Characteristics'!$B6,'[1]Statement of Investments'!$B$5:$B$220,0)) -> 499997.04 | G6: Coatue, First Round, Upfront | H6: 0.005 | I6: =IFERROR(ROUND(F6/H6,-5),0) -> 100000000 | K6: Pinwheel | L6: B | M6: =INDEX('[1]Statement of Investments'!$L$5:$L$220,MATCH('[1]Investment Characteristics'!$K6,'[1]Statement of Investments'!$E$5:$E$220,0)) -> 1453156.1 | N6: 0.0057927248 | O6: =I6 -> 100000000 | P6: =IFERROR(ROUND(S6/N6,-5),0) -> 250900000 | Q6: 5.0637434e+08 | R6: Pref Stack - $78M | S6: =INDEX('[1]Statement of Investments'!$L$5:$L$220,MATCH(B6,'[1]Statement of Investments'!$E$5:$E$220,0)) -> 1453156.1 | T6: =INDEX('[1]Statement of Investments'!$O$5:$O$220,MATCH(B6,'[1]Statement of Investments'!$E$5:$E$220,0)) -> 1453156.1 | U6: =T6/S6 -> 1 | V6: =+$V$1/N6/10^6 -> 12774.644 | X6: 0 | Y6: 1 | Z6: 1 | AA6: 1 | AB6: 0 | AC6: 0 | AD6: 0 | AE6: 0 | AF6: 0 | AI6: Growth has slowed but plenty of runway and increasing profitability | AM6: 2 | AN6: 1 | AO6: 1 | AP6: 1 | AQ6: 1 | AS6: 1.2 | AT6: 1 | AU6: 0.6 | AV6: 2 | AW6: 1.8 | AX6: 0.2 | BB6: RP/ABG | BC6: 46.5 | BD6: 10.5 | BE6: 7 | BF6: 64
B7: Cleo | C7: =INDEX('[1]Statement of Investments'!$C$5:$C$220,MATCH('[1]Investment Characteristics'!$B7,'[1]Statement of Investments'!$B$5:$B$220,0)) -> 44155 | D7: B | E7: Healthtech | F7: =INDEX('[1]Statement of Investments'!$L$5:$L$220,MATCH('[1]Investment Characteristics'!$B7,'[1]Statement of Investments'!$B$5:$B$220,0)) -> 599997.84 | G7: Felicis, Forerunner, Greylock | H7: =F7/115000000 -> 0.0052173725 | I7: =IFERROR(ROUND(F7/H7,-5),0) -> 115000000 | K7: Cleo | L7: C | M7: =INDEX('[1]Statement of Investments'!$L$5:$L$220,MATCH('[1]Investment Characteristics'!$K7,'[1]Statement of Investments'!$E$5:$E$220,0)) -> 599997.84 | N7: 0.0040460588 | O7: =I7 -> 115000000 | P7: =IFERROR(ROUND(S7/N7,-5),0) -> 148300000 | Q7: 231000000 | R7: 0 | S7: =INDEX('[1]Statement of Investments'!$L$5:$L$220,MATCH(B7,'[1]Statement of Investments'!$E$5:$E$220,0)) -> 599997.84 | T7: =INDEX('[1]Statement of Investments'!$O$5:$O$220,MATCH(B7,'[1]Statement of Investments'!$E$5:$E$220,0)) -> 0 | U7: =T7/S7 -> 0 | V7: =+$V$1/N7/10^6 -> 18289.403 | X7: 1 | Y7: 1 | Z7: 1 | AA7: 0 | AB7: -1 | AC7: 0 | AD7: -1 | AE7: -1 | AF7: -1 | AG7: -1 | AH7: -1 | AI7: No financials provided, investment already written off | AM7: 1 | AN7: 2 | AO7: 1 | AP7: 1 | AQ7: 2 | AS7: 1.4 | AT7: 1.4 | AU7: 1 | AV7: 1.2 | AW7: 2 | AX7: 1.8 | BB7: RP | BC7: 35.3 | BD7: 12 | BE7: 7 | BF7: 54.3
B8: Rightfoot | C8: =INDEX('[1]Statement of Investments'!$C$5:$C$220,MATCH('[1]Investment Characteristics'!$B8,'[1]Statement of Investments'!$B$5:$B$220,0)) -> 44175 | D8: Seed | E8: Financial | F8: =INDEX('[1]Statement of Investments'!$L$5:$L$220,MATCH('[1]Investment Characteristics'!$B8,'[1]Statement of Investments'!$B$5:$B$220,0)) -> 399999.32 | G8: Bain Capital, LSVP | H8: 0.02 | I8: =IFERROR(ROUND(F8/H8,-5),0) -> 20000000 | K8: Rightfoot | L8: A | M8: =INDEX('[1]Statement of Investments'!$L$5:$L$220,MATCH('[1]Investment Characteristics'!$K8,'[1]Statement of Investments'!$E$5:$E$220,0)) -> 399999.32 | N8: 0.012564741 | O8: =I8 -> 20000000 | P8: =IFERROR(ROUND(S8/N8,-5),0) -> 31800000 | Q8: =55*10^6 -> 55000000 | R8: 0 | S8: =INDEX('[1]Statement of Investments'!$L$5:$L$220,MATCH(B8,'[1]Statement of Investments'!$E$5:$E$220,0)) -> 399999.32 | T8: =INDEX('[1]Statement of Investments'!$O$5:$O$220,MATCH(B8,'[1]Statement of Investments'!$E$5:$E$220,0)) -> 0 | U8: =T8/S8 -> 0 | V8: =+$V$1/N8/10^6 -> 5889.4968 | X8: 0 | Y8: 0 | Z8: 1 | AA8: 0 | AB8: 0 | AC8: -1 | AD8: -1 | AE8: -1 | AF8: -1 | AG8: -1 | AH8: -1 | AI8: Written off - company has runway but looking for PMF | AM8: 1 | AN8: 2 | AO8: 1 | AP8: 1 | AQ8: 1 | AS8: 1.2 | AT8: 1.2 | AU8: 1.4 | AV8: 1 | AW8: 1.6 | AX8: 1.8 | BB8: CH | BC8: 41 | BD8: 9.8 | BE8: 4 | BF8: 54.8
B9: Mathison | C9: =INDEX('[1]Statement of Investments'!$C$5:$C$220,MATCH('[1]Investment Characteristics'!$B9,'[1]Statement of Investments'!$B$5:$B$220,0)) -> 44176 | D9: Seed | E9: Workforce | F9: =INDEX('[1]Statement of Investments'!$L$5:$L$220,MATCH('[1]Investment Characteristics'!$B9,'[1]Statement of Investments'!$B$5:$B$220,0)) -> 299999.56 | G9: Bain Capital | H9: 0.020000165 | I9: =IFERROR(ROUND(F9/H9,-5),0) -> 15000000 | K9: Mathison | L9: Acq. | M9: =INDEX('[1]Statement of Investments'!$L$5:$L$220,MATCH('[1]Investment Characteristics'!$K9,'[1]Statement of Investments'!$E$5:$E$220,0)) -> 2049994.2 | N9: 0.04 | O9: =I9 -> 15000000 | P9: =IFERROR(ROUND(S9/N9,-5),0) -> 51200000 | Q9: 70000000 | R9: =+Q9 -> 70000000 | S9: =INDEX('[1]Statement of Investments'!$L$5:$L$220,MATCH(B9,'[1]Statement of Investments'!$E$5:$E$220,0)) -> 2049994.2 | T9: =INDEX('[1]Statement of Investments'!$O$5:$O$220,MATCH(B9,'[1]Statement of Investments'!$E$5:$E$220,0)) -> 272298.82 | U9: =T9/S9 -> 0.13282907 | V9: =+$V$1/N9/10^6 -> 1850 | X9: 1 | Y9: 1 | Z9: 1 | AA9: -1 | AB9: -1 | AC9: -1 | AM9: 2 | AN9: 2 | AO9: 2 | AP9: 1 | AQ9: 1 | AS9: 1.6 | AT9: 0.8 | AU9: 1 | AV9: 1.2 | AW9: 2 | AX9: 1.8 | BB9: ABG | BC9: 46 | BD9: 15 | BE9: 4 | BF9: 65
B10: Galileo | C10: =INDEX('[1]Statement of Investments'!$C$5:$C$220,MATCH('[1]Investment Characteristics'!$B10,'[1]Statement of Investments'!$B$5:$B$220,0)) -> 44232 | D10: C | E10: Healthtech | F10: =INDEX('[1]Statement of Investments'!$L$5:$L$220,MATCH('[1]Investment Characteristics'!$B10,'[1]Statement of Investments'!$B$5:$B$220,0)) -> 1999999.2 | G10: Foresite Capital, Oak HC/FT, 8VC | H10: 0.0050633027 | I10: =IFERROR(ROUND(F10/H10,-5),0) -> 395000000 | K10: Galileo | L10: C | M10: =INDEX('[1]Statement of Investments'!$L$5:$L$220,MATCH('[1]Investment Characteristics'!$K10,'[1]Statement of Investments'!$E$5:$E$220,0)) -> 2163901.7 | N10: 0.0041856851 | O10: =I10 -> 395000000 | P10: =IFERROR(ROUND(S10/N10,-5),0) -> 517000000 | Q10: =600*10^6 -> 600000000 | R10: =+Q10 -> 600000000 | S10: =INDEX('[1]Statement of Investments'!$L$5:$L$220,MATCH(B10,'[1]Statement of Investments'!$E$5:$E$220,0)) -> 2163901.7 | T10: =INDEX('[1]Statement of Investments'!$O$5:$O$220,MATCH(B10,'[1]Statement of Investments'!$E$5:$E$220,0)) -> 1724878.8 | U10: =T10/S10 -> 0.79711515 | V10: =+$V$1/N10/10^6 -> 17679.304 | X10: 1 | Y10: 0 | Z10: 0 | AA10: 2 | AB10: 0 | AC10: -1 | AD10: -1 | AE10: -1 | AF10: -1 | AI10: Revenue doubled in 2024 and forecasted to grow 1.5x+ in 2025, north of $50M. High burn, currently fundraising | AM10: 1 | AN10: 1 | AO10: 1 | AP10: 2 | AQ10: 2 | AS10: 1.4 | AT10: 2 | AU10: 1.2 | AV10: 2 | AW10: 1.8 | AX10: -0.4 | BB10: GG | BC10: 45.5 | BD10: 10.5 | BE10: 7 | BF10: 63
B11: Cocoon | C11: =INDEX('[1]Statement of Investments'!$C$5:$C$220,MATCH('[1]Investment Characteristics'!$B11,'[1]Statement of Investments'!$B$5:$B$220,0)) -> 44232 | D11: Seed | E11: Workforce | F11: =INDEX('[1]Statement of Investments'!$L$5:$L$220,MATCH('[1]Investment Characteristics'!$B11,'[1]Statement of Investments'!$B$5:$B$220,0)) -> 224999.42 | G11: Index Ventures, XYZ Capital | H11: 0.0073744678 | I11: =IFERROR(ROUND(F11/H11,-5),0) -> 30500000 | K11: Cocoon | L11: A | M11: =INDEX('[1]Statement of Investments'!$L$5:$L$220,MATCH('[1]Investment Characteristics'!$K11,'[1]Statement of Investments'!$E$5:$E$220,0)) -> 4224996.6 | N11: 0.027242491 | O11: =I11 -> 30500000 | P11: =IFERROR(ROUND(S11/N11,-5),0) -> 155100000 | Q11: 1.6250158e+08 | R11: Pref Stack - $26M | S11: =INDEX('[1]Statement of Investments'!$L$5:$L$220,MATCH(B11,'[1]Statement of Investments'!$E$5:$E$220,0)) -> 4224996.6 | T11: =INDEX('[1]Statement of Investments'!$O$5:$O$220,MATCH(B11,'[1]Statement of Investments'!$E$5:$E$220,0)) -> 4224996.6 | U11: =T11/S11 -> 1 | V11: =+$V$1/N11/10^6 -> 2716.3448 | X11: 1 | Y11: 1 | Z11: 1 | AA11: 1 | AB11: 1 | AC11: 1 | AD11: 0 | AE11: 0 | AF11: 0 | AI11: Written to preference stack, ARR forecasting to grow ~2x but lower runway | AM11: 1 | AN11: 1 | AO11: 1 | AQ11: 1 | AS11: 1 | AT11: 1.5 | AU11: 0.8 | AV11: 1.5 | AW11: 1.5 | AX11: 1 | BB11: RP | BC11: 48.5 | BD11: 11.3 | BF11: 59.8
B12: Rula | C12: =INDEX('[1]Statement of Investments'!$C$5:$C$220,MATCH('[1]Investment Characteristics'!$B12,'[1]Statement of Investments'!$B$5:$B$220,0)) -> 44265 | D12: A | E12: Healthtech | F12: =INDEX('[1]Statement of Investments'!$L$5:$L$220,MATCH('[1]Investment Characteristics'!$B12,'[1]Statement of Investments'!$B$5:$B$220,0)) -> 1500000 | G12: Wing Ventures, Upfront Ventures | H12: 0.023774266 | I12: =IFERROR(ROUND(F12/H12,-5),0) -> 63100000 | K12: Rula | L12: C | M12: =INDEX('[1]Statement of Investments'!$L$5:$L$220,MATCH('[1]Investment Characteristics'!$K12,'[1]Statement of Investments'!$E$5:$E$220,0)) -> 4500000 | N12: 0.019806577 | O12: =I12 -> 63100000 | P12: =IFERROR(ROUND(S12/N12,-5),0) -> 227200000 | Q12: 1250000000 | R12: =+Q12 -> 1250000000 | S12: =INDEX('[1]Statement of Investments'!$L$5:$L$220,MATCH(B12,'[1]Statement of Investments'!$E$5:$E$220,0)) -> 4500000 | T12: =INDEX('[1]Statement of Investments'!$O$5:$O$220,MATCH(B12,'[1]Statement of Investments'!$E$5:$E$220,0)) -> 25285301 | U12: =T12/S12 -> 5.6189558 | V12: =+$V$1/N12/10^6 -> 3736.1327 | X12: 1 | Y12: 1 | Z12: 1 | AA12: 1 | AB12: 1 | AC12: 1 | AD12: 1 | AE12: 1 | AF12: 1 | AI12: Closed 2024 north of $100M in revenue, forecasting 2x+ growth in 2025 | AM12: 1 | AN12: 1 | AP12: 1 | AQ12: 2 | AS12: 1.3 | AT12: 1.3 | AU12: 0 | AV12: 1.5 | AW12: 2 | AX12: 1 | BB12: RP | BC12: 45.5 | BD12: 10 | BE12: 7 | BF12: 62.5
B13: Origin | C13: =INDEX('[1]Statement of Investments'!$C$5:$C$220,MATCH('[1]Investment Characteristics'!$B13,'[1]Statement of Investments'!$B$5:$B$220,0)) -> 44307 | D13: A | E13: Financial | F13: =INDEX('[1]Statement of Investments'!$L$5:$L$220,MATCH('[1]Investment Characteristics'!$B13,'[1]Statement of Investments'!$B$5:$B$220,0)) -> 1699997.1 | G13: Felicis, 01 Advisors, General Catalyst | H13: 0.013599977 | I13: =IFERROR(ROUND(F13/H13,-5),0) -> 125000000 | K13: Origin | L13: B | M13: =INDEX('[1]Statement of Investments'!$L$5:$L$220,MATCH('[1]Investment Characteristics'!$K13,'[1]Statement of Investments'!$E$5:$E$220,0)) -> 3699992.1 | N13: 0.027099272 | O13: =I13 -> 125000000 | P13: =IFERROR(ROUND(S13/N13,-5),0) -> 136500000 | Q13: 401250000 | R13: =P13 -> 136500000 | S13: =INDEX('[1]Statement of Investments'!$L$5:$L$220,MATCH(B13,'[1]Statement of Investments'!$E$5:$E$220,0)) -> 3699992.1 | T13: =INDEX('[1]Statement of Investments'!$O$5:$O$220,MATCH(B13,'[1]Statement of Investments'!$E$5:$E$220,0)) -> 3699992.1 | U13: =T13/S13 -> 1 | V13: =+$V$1/N13/10^6 -> 2730.7007 | X13: 1 | Y13: 1 | Z13: 1 | AA13: 0 | AB13: 0 | AC13: 0 | AD13: 0 | AE13: 0 | AF13: 0 | AI13: Slowing growth as the company pivots to a D2C model, 2+ years of runway | AM13: 1 | AN13: 2 | AQ13: 2 | AS13: 1.7 | AT13: 2 | AU13: 1 | AV13: 1.7 | AW13: 1.3 | AX13: 1 | BB13: CH/RP | BC13: 50.5 | BD13: 8 | BE13: 6.5 | BF13: 65
B14: Nayya | C14: =INDEX('[1]Statement of Investments'!$C$5:$C$220,MATCH('[1]Investment Characteristics'!$B14,'[1]Statement of Investments'!$B$5:$B$220,0)) -> 44344 | D14: B | E14: Healthtech | F14: =INDEX('[1]Statement of Investments'!$L$5:$L$220,MATCH('[1]Investment Characteristics'!$B14,'[1]Statement of Investments'!$B$5:$B$220,0)) -> 500000 | G14: Felicis, Iconiq, SVB Capital | H14: 0.002173913 | I14: =IFERROR(ROUND(F14/H14,-5),0) -> 230000000 | K14: Nayya | L14: C | M14: =INDEX('[1]Statement of Investments'!$L$5:$L$220,MATCH('[1]Investment Characteristics'!$K14,'[1]Statement of Investments'!$E$5:$E$220,0)) -> 2699987.1 | N14: 0.0076636442 | O14: =I14 -> 230000000 | P14: =IFERROR(ROUND(S14/N14,-5),0) -> 352300000 | Q14: 5.049535e+08 | R14: =+Q14 -> 5.049535e+08 | S14: =INDEX('[1]Statement of Investments'!$L$5:$L$220,MATCH(B14,'[1]Statement of Investments'!$E$5:$E$220,0)) -> 2699987.1 | T14: =INDEX('[1]Statement of Investments'!$O$5:$O$220,MATCH(B14,'[1]Statement of Investments'!$E$5:$E$220,0)) -> 3853385.4 | U14: =T14/S14 -> 1.4271866 | V14: =+$V$1/N14/10^6 -> 9655.9806 | X14: 1 | Y14: 1 | Z14: 0 | AA14: 0 | AB14: 0 | AC14: 1 | AD14: 1 | AE14: 1 | AF14: 1 | AI14: Revenue forecasted to 2x y/y with significant ramp from partnership distribution | AM14: 1 | AN14: 1 | AP14: 1 | AQ14: 1 | AS14: 1 | AT14: 1 | AU14: 1.5 | AV14: 1.8 | AW14: 1.5 | AX14: 0.3 | BB14: RP | BC14: 47.5 | BF14: 47.5
B15: Praisidio | C15: =INDEX('[1]Statement of Investments'!$C$5:$C$220,MATCH('[1]Investment Characteristics'!$B15,'[1]Statement of Investments'!$B$5:$B$220,0)) -> 44370 | D15: Seed | E15: Workforce | F15: =INDEX('[1]Statement of Investments'!$L$5:$L$220,MATCH('[1]Investment Characteristics'!$B15,'[1]Statement of Investments'!$B$5:$B$220,0)) -> 200000 | G15: Signal Fire, Storm Ventures | H15: 0.01 | I15: =IFERROR(ROUND(F15/H15,-5),0) -> 20000000 | K15: Praisidio | L15: Seed | M15: =INDEX('[1]Statement of Investments'!$L$5:$L$220,MATCH('[1]Investment Characteristics'!$K15,'[1]Statement of Investments'!$E$5:$E$220,0)) -> 200000 | N15: 0.01 | O15: =I15 -> 20000000 | P15: =IFERROR(ROUND(S15/N15,-5),0) -> 20000000 | Q15: 20000000 | R15: 0 | S15: =INDEX('[1]Statement of Investments'!$L$5:$L$220,MATCH(B15,'[1]Statement of Investments'!$E$5:$E$220,0)) -> 200000 | T15: =INDEX('[1]Statement of Investments'!$O$5:$O$220,MATCH(B15,'[1]Statement of Investments'!$E$5:$E$220,0)) -> 0 | U15: =T15/S15 -> 0 | V15: =+$V$1/N15/10^6 -> 7400 | X15: 1 | Y15: 1 | Z15: 0 | AA15: 0 | AB15: 0 | AC15: 0 | AD15: 0 | AE15: 0 | AF15: -1 | AG15: -1 | AH15: -1 | AI15: Written down to 0 | AM15: 2 | AN15: 2 | AP15: 1 | AQ15: 1 | AS15: 1.5 | AT15: 1.5 | AU15: 1 | AV15: 1 | AW15: 2 | AX15: 1.8 | BB15: ABG | BC15: 46.5 | BD15: 13 | BE15: 9 | BF15: 68.5
B16: Bravely | C16: =INDEX('[1]Statement of Investments'!$C$5:$C$220,MATCH('[1]Investment Characteristics'!$B16,'[1]Statement of Investments'!$B$5:$B$220,0)) -> 44379 | D16: A | E16: Workforce | F16: =INDEX('[1]Statement of Investments'!$L$5:$L$220,MATCH('[1]Investment Characteristics'!$B16,'[1]Statement of Investments'!$B$5:$B$220,0)) -> 1249999.6 | G16: Telescope Partners, Primary Venture Partners | H16: 0.018518542 | I16: =IFERROR(ROUND(F16/H16,-5),0) -> 67500000 | K16: Bravely | L16: A | M16: =INDEX('[1]Statement of Investments'!$L$5:$L$220,MATCH('[1]Investment Characteristics'!$K16,'[1]Statement of Investments'!$E$5:$E$220,0)) -> 1249999.6 | N16: 0.018518542 | O16: =I16 -> 67500000 | P16: =IFERROR(ROUND(S16/N16,-5),0) -> 67500000 | Q16: 67500000 | R16: =+Q16 -> 67500000 | S16: =INDEX('[1]Statement of Investments'!$L$5:$L$220,MATCH(B16,'[1]Statement of Investments'!$E$5:$E$220,0)) -> 1249999.6 | T16: =INDEX('[1]Statement of Investments'!$O$5:$O$220,MATCH(B16,'[1]Statement of Investments'!$E$5:$E$220,0)) -> 1249999.6 | U16: =T16/S16 -> 1 | V16: =+$V$1/N16/10^6 -> 3995.995 | X16: 1 | Y16: 1 | Z16: 0 | AA16: -1 | AB16: -1 | AC16: -1 | AD16: -1 | AE16: -1 | AF16: -1 | AI16: Close to breakeven with significant runway as the company looks to reinvigorate growth | AM16: 2 | AN16: 1 | AO16: 1 | AP16: 1 | AQ16: 1 | AS16: 1.2 | AT16: 1.2 | AU16: 0.4 | AV16: 1.4 | AW16: 2 | AX16: 1.6 | BB16: ABG | BC16: 45 | BD16: 13.5 | BF16: 58.5 | BG16: No scorecard, pulled from Investment Diligence
B17: Remote | C17: =INDEX('[1]Statement of Investments'!$C$5:$C$220,MATCH('[1]Investment Characteristics'!$B17,'[1]Statement of Investments'!$B$5:$B$220,0)) -> 44398 | D17: B | E17: Workforce | F17: =INDEX('[1]Statement of Investments'!$L$5:$L$220,MATCH('[1]Investment Characteristics'!$B17,'[1]Statement of Investments'!$B$5:$B$220,0)) -> 3999979.6 | G17: Accel, General Catalyst, Index, Sequoia | H17: 0.0039999789 | I17: =IFERROR(ROUND(F17/H17,-5),0) -> 1000000000 | K17: Remote | L17: C | M17: =INDEX('[1]Statement of Investments'!$L$5:$L$220,MATCH('[1]Investment Characteristics'!$K17,'[1]Statement of Investments'!$E$5:$E$220,0)) -> 4781446 | N17: 0.003599981 | O17: =I17 -> 1000000000 | P17: =IFERROR(ROUND(S17/N17,-5),0) -> 1328200000 | Q17: 3000000000 | R17: =+Q17 -> 3000000000 | S17: =INDEX('[1]Statement of Investments'!$L$5:$L$220,MATCH(B17,'[1]Statement of Investments'!$E$5:$E$220,0)) -> 4781446 | T17: =INDEX('[1]Statement of Investments'!$O$5:$O$220,MATCH(B17,'[1]Statement of Investments'!$E$5:$E$220,0)) -> 10354762 | U17: =T17/S17 -> 2.165613 | V17: =+$V$1/N17/10^6 -> 20555.664 | X17: 1 | Y17: 1 | Z17: 0 | AA17: 0 | AB17: 1 | AC17: 1 | AD17: 1 | AE17: 1 | AF17: 1 | AI17: Lower visibility into financial figures, but strong ecosystem feedback and ramp from employer channel | AM17: 2 | AN17: 1 | AP17: 1 | AQ17: 2 | AS17: 1.5 | AT17: 2 | AU17: 1.8 | AV17: 2 | AW17: 1.8 | AX17: 0.3 | BB17: RP | BC17: 52.5 | BD17: 14.3 | BF17: 66.8
B18: Finch | C18: =INDEX('[1]Statement of Investments'!$C$5:$C$220,MATCH('[1]Investment Characteristics'!$B18,'[1]Statement of Investments'!$B$5:$B$220,0)) -> 44435 | D18: A | E18: Financial | F18: =INDEX('[1]Statement of Investments'!$L$5:$L$220,MATCH('[1]Investment Characteristics'!$B18,'[1]Statement of Investments'!$B$5:$B$220,0)) -> 500003.42 | G18: Menlo, General Catalyst, Box Group | H18: 0.0043467434 | I18: =IFERROR(ROUND(F18/H18,-5),0) -> 115000000 | K18: Finch | L18: B | M18: =INDEX('[1]Statement of Investments'!$L$5:$L$220,MATCH('[1]Investment Characteristics'!$K18,'[1]Statement of Investments'!$E$5:$E$220,0)) -> 500003.42 | N18: 0.0032205422 | O18: =I18 -> 115000000 | P18: =IFERROR(ROUND(S18/N18,-5),0) -> 155300000 | Q18: 230000392 | R18: =+Q18 -> 230000392 | S18: =INDEX('[1]Statement of Investments'!$L$5:$L$220,MATCH(B18,'[1]Statement of Investments'!$E$5:$E$220,0)) -> 500003.42 | T18: =INDEX('[1]Statement of Investments'!$O$5:$O$220,MATCH(B18,'[1]Statement of Investments'!$E$5:$E$220,0)) -> 740862.12 | U18: =T18/S18 -> 1.4817141 | V18: =+$V$1/N18/10^6 -> 22977.498 | X18: 1 | Y18: 1 | Z18: 1 | AA18: 1 | AB18: 1 | AC18: 1 | AD18: 1 | AE18: 1 | AF18: 1 | AI18: 3 years of runway, forecasting 1.5x y/y growth and deepening key distribution partnerships | AM18: 1 | AN18: 1 | AQ18: 1 | AS18: 1 | AT18: 1 | AU18: 1.7 | AV18: 1.3 | AW18: 1.7 | AX18: 0.3 | BB18: RP | BC18: 46.5 | BD18: 14 | BE18: 2 | BF18: 62.5
B19: Midi | C19: =INDEX('[1]Statement of Investments'!$C$5:$C$220,MATCH('[1]Investment Characteristics'!$B19,'[1]Statement of Investments'!$B$5:$B$220,0)) -> 44455 | D19: Seed | E19: Healthtech | F19: =INDEX('[1]Statement of Investments'!$L$5:$L$220,MATCH('[1]Investment Characteristics'!$B19,'[1]Statement of Investments'!$B$5:$B$220,0)) -> 510137 | G19: Icon Ventures | H19: =F19/10000000 -> 0.0510137 | I19: =IFERROR(ROUND(F19/H19,-5),0) -> 10000000 | K19: Midi | L19: D | M19: =INDEX('[1]Statement of Investments'!$L$5:$L$220,MATCH('[1]Investment Characteristics'!$K19,'[1]Statement of Investments'!$E$5:$E$220,0)) -> 5531507 | N19: 0.0483 | O19: =I19 -> 10000000 | P19: =IFERROR(ROUND(S19/N19,-5),0) -> 114500000 | Q19: 1150000000 | R19: =+Q19 -> 1150000000 | S19: =INDEX('[1]Statement of Investments'!$L$5:$L$220,MATCH(B19,'[1]Statement of Investments'!$E$5:$E$220,0)) -> 5531507 | T19: =INDEX('[1]Statement of Investments'!$O$5:$O$220,MATCH(B19,'[1]Statement of Investments'!$E$5:$E$220,0)) -> 48185999 | U19: =T19/S19 -> 8.7111883 | V19: =+$V$1/N19/10^6 -> 1532.0911 | X19: 1 | Y19: 1 | Z19: 1 | AA19: 1 | AB19: 1 | AC19: 1 | AD19: 1 | AE19: 1 | AF19: 1 | AG19: 1 | AH19: 1 | AI19: Forecasting to reach $100M+ of net revenue in 2025, expecting to close new round of financing at markup | AM19: 2 | AN19: 2 | AO19: 1 | AP19: 1 | AQ19: 1 | AS19: 1.4 | AT19: 1.6 | AU19: 0.2 | AV19: 1.8 | AW19: 1.4 | AX19: 1.8 | BB19: ABG | BC19: 41.5 | BD19: 8 | BF19: 49.5 | BG19: No scorecard, pulled from Investment Diligence
B20: ianacare | C20: =INDEX('[1]Statement of Investments'!$C$5:$C$220,MATCH('[1]Investment Characteristics'!$B20,'[1]Statement of Investments'!$B$5:$B$220,0)) -> 44547 | D20: A | E20: Healthtech | F20: =INDEX('[1]Statement of Investments'!$L$5:$L$220,MATCH('[1]Investment Characteristics'!$B20,'[1]Statement of Investments'!$B$5:$B$220,0)) -> 999984.87 | G20: Greycroft, 8VC | H20: 0.016666456 | I20: =IFERROR(ROUND(F20/H20,-5),0) -> 60000000 | K20: ianacare | L20: A | M20: =INDEX('[1]Statement of Investments'!$L$5:$L$220,MATCH('[1]Investment Characteristics'!$K20,'[1]Statement of Investments'!$E$5:$E$220,0)) -> 2999984.9 | N20: 0.01664562 | O20: =I20 -> 60000000 | P20: =+O20 -> 60000000 | Q20: =P20 -> 60000000 | R20: =+Q20 -> 60000000 | S20: =INDEX('[1]Statement of Investments'!$L$5:$L$220,MATCH(B20,'[1]Statement of Investments'!$E$5:$E$220,0)) -> 2999984.9 | T20: =INDEX('[1]Statement of Investments'!$O$5:$O$220,MATCH(B20,'[1]Statement of Investments'!$E$5:$E$220,0)) -> 2999984.9 | U20: =T20/S20 -> 1 | V20: =+$V$1/N20/10^6 -> 4445.6139 | Y20: 1 | Z20: 1 | AA20: 1 | AB20: 1 | AC20: 0 | AD20: -1 | AE20: -1 | AF20: 0 | AI20: Potential new channel through GUIDE CMS reimbursement is accelerating growth and Elevance expanding partnership | AM20: 2 | AN20: 1 | AO20: 2 | AP20: 1 | AQ20: 1 | AS20: 1.4 | AT20: 2 | AU20: 1.4 | AV20: 1 | AW20: 1.8 | AX20: 1 | BB20: ABG | BC20: 47.8 | BD20: 15 | BF20: 62.8
B21: Vivante | C21: =INDEX('[1]Statement of Investments'!$C$5:$C$220,MATCH('[1]Investment Characteristics'!$B21,'[1]Statement of Investments'!$B$5:$B$220,0)) -> 44552 | D21: A | E21: Healthtech | F21: =INDEX('[1]Statement of Investments'!$L$5:$L$220,MATCH('[1]Investment Characteristics'!$B21,'[1]Statement of Investments'!$B$5:$B$220,0)) -> 999999 | G21: 7Wire, NFP | H21: 0.045928552 | I21: =IFERROR(ROUND(F21/H21,-5),0) -> 21800000 | K21: Vivante | L21: B | M21: =INDEX('[1]Statement of Investments'!$L$5:$L$220,MATCH('[1]Investment Characteristics'!$K21,'[1]Statement of Investments'!$E$5:$E$220,0)) -> 2204142.3 | N21: 0.037179658 | O21: =I21 -> 21800000 | P21: =IFERROR(ROUND(S21/N21,-5),0) -> 59300000 | Q21: 84077296 | R21: =+Q21 -> 84077296 | S21: =INDEX('[1]Statement of Investments'!$L$5:$L$220,MATCH(B21,'[1]Statement of Investments'!$E$5:$E$220,0)) -> 2204142.3 | T21: =INDEX('[1]Statement of Investments'!$O$5:$O$220,MATCH(B21,'[1]Statement of Investments'!$E$5:$E$220,0)) -> 3130662 | U21: =T21/S21 -> 1.4203538 | V21: =+$V$1/N21/10^6 -> 1990.3357 | Y21: 1 | Z21: 1 | AA21: -1 | AB21: 1 | AC21: 1 | AD21: 1 | AE21: 1 | AF21: 1 | AI21: Steady 1.5x y/y growth last year, forecasted into 2025 - currently fundraising | AM21: 1 | AN21: 2 | AP21: 1 | AQ21: 2 | AS21: 1.5 | AT21: 1.3 | AU21: 1 | AV21: 1.8 | AW21: 1.5 | AX21: 2 | BB21: RP | BC21: 49.5 | BF21: 49.5
B22: a.team | C22: =INDEX('[1]Statement of Investments'!$C$5:$C$220,MATCH('[1]Investment Characteristics'!$B22,'[1]Statement of Investments'!$B$5:$B$220,0)) -> 44567 | D22: A | E22: Workforce | F22: =INDEX('[1]Statement of Investments'!$L$5:$L$220,MATCH('[1]Investment Characteristics'!$B22,'[1]Statement of Investments'!$B$5:$B$220,0)) -> 999998.86 | G22: Spruce, Tiger, Insight, BoxGroup | H22: 0.003076922 | I22: =IFERROR(ROUND(F22/H22,-5),0) -> 325000000 | K22: a.team | L22: A | M22: =INDEX('[1]Statement of Investments'!$L$5:$L$220,MATCH('[1]Investment Characteristics'!$K22,'[1]Statement of Investments'!$E$5:$E$220,0)) -> 999998.86 | N22: 0.0030769253 | O22: =I22 -> 325000000 | P22: =IFERROR(ROUND(S22/N22,-5),0) -> 325000000 | Q22: =P22 -> 325000000 | R22: =+Q22 -> 325000000 | S22: =INDEX('[1]Statement of Investments'!$L$5:$L$220,MATCH(B22,'[1]Statement of Investments'!$E$5:$E$220,0)) -> 999998.86 | T22: =INDEX('[1]Statement of Investments'!$O$5:$O$220,MATCH(B22,'[1]Statement of Investments'!$E$5:$E$220,0)) -> 999998.86 | U22: =T22/S22 -> 1 | V22: =+$V$1/N22/10^6 -> 24049.983 | Y22: 1 | Z22: 1 | AA22: 1 | AB22: 0 | AC22: 1 | AD22: 0 | AE22: 0 | AF22: 0 | AI22: runway++ | AY22: Double-check | BB22: ABG | BC22: 51.5 | BD22: 17.8 | BF22: 69.3
