Workbook

Sheet Fund Dashboard
B2: SemperVirens Fund II Summary
C3: ="As of "&TEXT('Statement of Investments'!$C$1,"mm/dd/yyyy") -> As of 12/31/2025 | F3: ="As of "&TEXT('Statement of Investments'!$C$1,"mm/dd/yyyy") -> As of 12/31/2025
B5: Fund Capital: | E5: Quarterly Invested Capital:
B6: Committed Capital | C6: 20730000 | E6: New Investments | F6: =SUMIF('Investment Rollover'!$C$4:$C$31,"=0",'Investment Rollover'!$D$4:$D$31) -> 5749995
B7: Capital Called | C7: =-SUM(#REF!) -> #REF! | E7: Follow-Ons | F7: =SUMIF('Investment Rollover'!$C$4:$C$31,">0",'Investment Rollover'!$D$4:$D$31) -> 5680282.5
B8: Percent Called | C8: =C7/C6 -> #REF! | E8: Total New Investments | F8: =SUM(F6:F7) -> 11430277
B10: Investment Summary: | E10: Pro-Forma Net Peformance:
B11: Invested Capital | C11: ='Investment Performance Summary'!E41 -> 70623804 | E11: Contributions | F11: =-#REF! -> #REF!
B12: Total Value | C12: ='Investment Performance Summary'!H41 -> 92399729 | E12: Distributions | F12: =#REF! -> #REF!
B13: MOIC | C13: =C12/C11 -> 1.3083369 | E13: NAV | F13: =#REF! -> #REF!
B14: Gross IRR | C14: ='Investment Performance Summary'!J41 -> 0.23573356 | E14: TVPI | F14: =(F13+F12)/F11 -> #REF!
E15: DPI | F15: =F12/F11 -> #REF!
E16: Net IRR | F16: =#REF! -> #REF!

Sheet Investment Performance Summary
B2: SemperVirens Fund III Investment Summary | K2: Markup
B4: ="As of "&TEXT('Statement of Investments'!$C$1,"mm/dd/yyyy") -> As of 12/31/2025 | C4: Initial Inv. | D4: Initial Exit | E4: Dollars | F4: Unrealized | G4: Realized | H4: Total | I4: Gross | J4: Gross
B5: Company | C5: Date | D5: Date | E5: Invested | F5: Value | G5: Value | H5: Value | I5: Multiple | J5: IRR
B7: Unrealized Portfolio
B9: Laguna Health | C9: =INDEX('Statement of Investments'!$C$5:$C$205,MATCH('Investment Performance Summary'!$B9,'Statement of Investments'!$B$5:$B$205,0)) -> 45021 | D9: - | E9: =INDEX('Statement of Investments'!$L$5:$L$205,MATCH($B9,'Statement of Investments'!$E$5:$E$205,0)) -> 4999999.7 | F9: =INDEX('Statement of Investments'!$O$5:$O$205,MATCH($B9,'Statement of Investments'!$E$5:$E$205,0)) -> 4999999.7 | G9: 0 | H9: =F9+G9 -> 4999999.7 | I9: =H9/E9 -> 1 | J9: =INDEX('Statement of Investments'!$R$5:$R$205,MATCH($B9,'Statement of Investments'!$E$5:$E$205,0)) -> 2.9802322e-09 | K9: N
B10: Stepful | C10: =INDEX('Statement of Investments'!$C$5:$C$205,MATCH('Investment Performance Summary'!$B10,'Statement of Investments'!$B$5:$B$205,0)) -> 45183 | D10: - | E10: =INDEX('Statement of Investments'!$L$5:$L$205,MATCH($B10,'Statement of Investments'!$E$5:$E$205,0)) -> 7878030.5 | F10: =INDEX('Statement of Investments'!$O$5:$O$205,MATCH($B10,'Statement of Investments'!$E$5:$E$205,0)) -> 13609280 | G10: 0 | H10: =F10+G10 -> 13609280 | I10: =H10/E10 -> 1.7274977 | J10: =INDEX('Statement of Investments'!$R$5:$R$205,MATCH($B10,'Statement of Investments'!$E$5:$E$205,0)) -> 0.38251794 | K10: Y
B11: Summer | C11: =INDEX('Statement of Investments'!$C$5:$C$205,MATCH('Investment Performance Summary'!$B11,'Statement of Investments'!$B$5:$B$205,0)) -> 45209 | D11: - | E11: =INDEX('Statement of Investments'!$L$5:$L$205,MATCH($B11,'Statement of Investments'!$E$5:$E$205,0)) -> 3250000 | F11: =INDEX('Statement of Investments'!$O$5:$O$205,MATCH($B11,'Statement of Investments'!$E$5:$E$205,0)) -> 3250000 | G11: 0 | H11: =F11+G11 -> 3250000 | I11: =H11/E11 -> 1 | J11: =INDEX('Statement of Investments'!$R$5:$R$205,MATCH($B11,'Statement of Investments'!$E$5:$E$205,0)) -> 4.8828125e-09 | K11: N
B12: Wagmo | C12: =INDEX('Statement of Investments'!$C$5:$C$205,MATCH('Investment Performance Summary'!$B12,'Statement of Investments'!$B$5:$B$205,0)) -> 45209 | D12: - | E12: =INDEX('Statement of Investments'!$L$5:$L$205,MATCH($B12,'Statement of Investments'!$E$5:$E$205,0)) -> 1499998 | F12: =INDEX('Statement of Investments'!$O$5:$O$205,MATCH($B12,'Statement of Investments'!$E$5:$E$205,0)) -> 1499998 | G12: 0 | H12: =F12+G12 -> 1499998 | I12: =H12/E12 -> 1 | J12: =INDEX('Statement of Investments'!$R$5:$R$205,MATCH($B12,'Statement of Investments'!$E$5:$E$205,0)) -> 4.8828125e-09 | K12: N
B13: Kubera | C13: =INDEX('Statement of Investments'!$C$5:$C$205,MATCH('Investment Performance Summary'!$B13,'Statement of Investments'!$B$5:$B$205,0)) -> 45274 | D13: - | E13: =INDEX('Statement of Investments'!$L$5:$L$205,MATCH($B13,'Statement of Investments'!$E$5:$E$205,0)) -> 528082.67 | F13: =INDEX('Statement of Investments'!$O$5:$O$205,MATCH($B13,'Statement of Investments'!$E$5:$E$205,0)) -> 1011413.2 | G13: 0 | H13: =F13+G13 -> 1011413.2 | I13: =H13/E13 -> 1.9152554 | J13: =INDEX('Statement of Investments'!$R$5:$R$205,MATCH($B13,'Statement of Investments'!$E$5:$E$205,0)) -> 0.46074747 | K13: N
B14: Solara | C14: =INDEX('Statement of Investments'!$C$5:$C$205,MATCH('Investment Performance Summary'!$B14,'Statement of Investments'!$B$5:$B$205,0)) -> 45329 | D14: - | E14: =INDEX('Statement of Investments'!$L$5:$L$205,MATCH($B14,'Statement of Investments'!$E$5:$E$205,0)) -> 4552198.8 | F14: =INDEX('Statement of Investments'!$O$5:$O$205,MATCH($B14,'Statement of Investments'!$E$5:$E$205,0)) -> 5296211.2 | G14: 0 | H14: =F14+G14 -> 5296211.2 | I14: =H14/E14 -> 1.1634402 | J14: =INDEX('Statement of Investments'!$R$5:$R$205,MATCH($B14,'Statement of Investments'!$E$5:$E$205,0)) -> 0.17761299 | K14: N
B15: Salsa | C15: =INDEX('Statement of Investments'!$C$5:$C$205,MATCH('Investment Performance Summary'!$B15,'Statement of Investments'!$B$5:$B$205,0)) -> 45329 | D15: - | E15: =INDEX('Statement of Investments'!$L$5:$L$205,MATCH($B15,'Statement of Investments'!$E$5:$E$205,0)) -> 5499997.9 | F15: =INDEX('Statement of Investments'!$O$5:$O$205,MATCH($B15,'Statement of Investments'!$E$5:$E$205,0)) -> 5912934 | G15: 0 | H15: =F15+G15 -> 5912934 | I15: =H15/E15 -> 1.0750793 | J15: =INDEX('Statement of Investments'!$R$5:$R$205,MATCH($B15,'Statement of Investments'!$E$5:$E$205,0)) -> 0.058040698 | K15: Y
B16: Hireguide | C16: =INDEX('Statement of Investments'!$C$5:$C$205,MATCH('Investment Performance Summary'!$B16,'Statement of Investments'!$B$5:$B$205,0)) -> 45351 | D16: - | E16: =INDEX('Statement of Investments'!$L$5:$L$205,MATCH($B16,'Statement of Investments'!$E$5:$E$205,0)) -> 3000000 | F16: =INDEX('Statement of Investments'!$O$5:$O$205,MATCH($B16,'Statement of Investments'!$E$5:$E$205,0)) -> 500000 | G16: 0 | H16: =F16+G16 -> 500000 | I16: =H16/E16 -> 0.16666667 | J16: =INDEX('Statement of Investments'!$R$5:$R$205,MATCH($B16,'Statement of Investments'!$E$5:$E$205,0)) -> -0.62267676 | K16: N
B17: Take2 AI | C17: =INDEX('Statement of Investments'!$C$5:$C$205,MATCH('Investment Performance Summary'!$B17,'Statement of Investments'!$B$5:$B$205,0)) -> 45376 | D17: - | E17: =INDEX('Statement of Investments'!$L$5:$L$205,MATCH($B17,'Statement of Investments'!$E$5:$E$205,0)) -> 700000 | F17: =INDEX('Statement of Investments'!$O$5:$O$205,MATCH($B17,'Statement of Investments'!$E$5:$E$205,0)) -> 700000 | G17: 0 | H17: =F17+G17 -> 700000 | I17: =H17/E17 -> 1 | J17: =INDEX('Statement of Investments'!$R$5:$R$205,MATCH($B17,'Statement of Investments'!$E$5:$E$205,0)) -> 4.8828125e-09 | K17: N
B18: Techwolf | C18: =INDEX('Statement of Investments'!$C$5:$C$205,MATCH('Investment Performance Summary'!$B18,'Statement of Investments'!$B$5:$B$205,0)) -> 45467 | D18: - | E18: =INDEX('Statement of Investments'!$L$5:$L$205,MATCH($B18,'Statement of Investments'!$E$5:$E$205,0)) -> 5037377 | F18: =INDEX('Statement of Investments'!$O$5:$O$205,MATCH($B18,'Statement of Investments'!$E$5:$E$205,0)) -> 5037377 | G18: 0 | H18: =F18+G18 -> 5037377 | I18: =H18/E18 -> 1 | J18: =INDEX('Statement of Investments'!$R$5:$R$205,MATCH($B18,'Statement of Investments'!$E$5:$E$205,0)) -> 4.8828125e-09 | K18: N
B19: Thatch | C19: =INDEX('Statement of Investments'!$C$5:$C$205,MATCH('Investment Performance Summary'!$B19,'Statement of Investments'!$B$5:$B$205,0)) -> 45513 | D19: - | E19: =INDEX('Statement of Investments'!$L$5:$L$205,MATCH($B19,'Statement of Investments'!$E$5:$E$205,0)) -> 4040625.2 | F19: =INDEX('Statement of Investments'!$O$5:$O$205,MATCH($B19,'Statement of Investments'!$E$5:$E$205,0)) -> 10304094 | G19: 0 | H19: =F19+G19 -> 10304094 | I19: =H19/E19 -> 2.5501238 | J19: =INDEX('Statement of Investments'!$R$5:$R$205,MATCH($B19,'Statement of Investments'!$E$5:$E$205,0)) -> 1.4000929 | K19: Y
B20: Multimodal | C20: =INDEX('Statement of Investments'!$C$5:$C$205,MATCH('Investment Performance Summary'!$B20,'Statement of Investments'!$B$5:$B$205,0)) -> 45614 | D20: - | E20: =INDEX('Statement of Investments'!$L$5:$L$205,MATCH($B20,'Statement of Investments'!$E$5:$E$205,0)) -> 2000000 | F20: =INDEX('Statement of Investments'!$O$5:$O$205,MATCH($B20,'Statement of Investments'!$E$5:$E$205,0)) -> 2000000 | G20: 0 | H20: =F20+G20 -> 2000000 | I20: =H20/E20 -> 1 | J20: =INDEX('Statement of Investments'!$R$5:$R$205,MATCH($B20,'Statement of Investments'!$E$5:$E$205,0)) -> 4.8828125e-09 | K20: N
... B23: Sully.AI | C23: =INDEX('Statement of Investments'!$C$5:$C$205,MATCH('Investment Performance Summary'!$B23,'Statement of Investments'!$B$5:$B$205,0)) -> 45666 | D23: - | E23: =INDEX('Statement of Investments'!$L$5:$L$205,MATCH($B23,'Statement of Investments'!$E$5:$E$205,0)) -> 3999999.5 | F23: =INDEX('Statement of Investments'!$O$5:$O$205,MATCH($B23,'Statement of Investments'!$E$5:$E$205,0)) -> 3999999.5 | G23: 0 | H23: =F23+G23 -> 3999999.5 | I23: =H23/E23 -> 1 | J23: =INDEX('Statement of Investments'!$R$5:$R$205,MATCH($B23,'Statement of Investments'!$E$5:$E$205,0)) -> -4.8828125e-09 | K23: N
B24: Athena.AI | C24: =INDEX('Statement of Investments'!$C$5:$C$205,MATCH('Investment Performance Summary'!$B24,'Statement of Investments'!$B$5:$B$205,0)) -> 45778 | D24: - | E24: =INDEX('Statement of Investments'!$L$5:$L$205,MATCH($B24,'Statement of Investments'!$E$5:$E$205,0)) -> 3150000 | F24: =INDEX('Statement of Investments'!$O$5:$O$205,MATCH($B24,'Statement of Investments'!$E$5:$E$205,0)) -> 3150000 | G24: 0 | H24: =F24+G24 -> 3150000 | I24: =H24/E24 -> 1 | J24: =INDEX('Statement of Investments'!$R$5:$R$205,MATCH($B24,'Statement of Investments'!$E$5:$E$205,0)) -> 4.8828125e-09
B25: Onboarded | C25: =INDEX('Statement of Investments'!$C$5:$C$205,MATCH('Investment Performance Summary'!$B25,'Statement of Investments'!$B$5:$B$205,0)) -> 45824 | D25: - | E25: =INDEX('Statement of Investments'!$L$5:$L$205,MATCH($B25,'Statement of Investments'!$E$5:$E$205,0)) -> 5000000 | F25: =INDEX('Statement of Investments'!$O$5:$O$205,MATCH($B25,'Statement of Investments'!$E$5:$E$205,0)) -> 5000000 | G25: 0 | H25: =F25+G25 -> 5000000 | I25: =H25/E25 -> 1 | J25: =INDEX('Statement of Investments'!$R$5:$R$205,MATCH($B25,'Statement of Investments'!$E$5:$E$205,0)) -> 4.8828125e-09
B26: PenguinAI | C26: =INDEX('Statement of Investments'!$C$5:$C$205,MATCH('Investment Performance Summary'!$B26,'Statement of Investments'!$B$5:$B$205,0)) -> 45821 | D26: - | E26: =INDEX('Statement of Investments'!$L$5:$L$205,MATCH($B26,'Statement of Investments'!$E$5:$E$205,0)) -> 4000000 | F26: =INDEX('Statement of Investments'!$O$5:$O$205,MATCH($B26,'Statement of Investments'!$E$5:$E$205,0)) -> 4000000 | G26: 0 | H26: =F26+G26 -> 4000000 | I26: =H26/E26 -> 1 | J26: =INDEX('Statement of Investments'!$R$5:$R$205,MATCH($B26,'Statement of Investments'!$E$5:$E$205,0)) -> 4.8828125e-09
B27: Clasp | C27: =INDEX('Statement of Investments'!$C$5:$C$205,MATCH('Investment Performance Summary'!$B27,'Statement of Investments'!$B$5:$B$205,0)) -> 45807 | D27: - | E27: =INDEX('Statement of Investments'!$L$5:$L$205,MATCH($B27,'Statement of Investments'!$E$5:$E$205,0)) -> 250000 | F27: =INDEX('Statement of Investments'!$O$5:$O$205,MATCH($B27,'Statement of Investments'!$E$5:$E$205,0)) -> 250000 | G27: 0 | H27: =F27+G27 -> 250000 | I27: =H27/E27 -> 1 | J27: =INDEX('Statement of Investments'!$R$5:$R$205,MATCH($B27,'Statement of Investments'!$E$5:$E$205,0)) -> 4.8828125e-09
B28: Sunny Health | C28: =INDEX('Statement of Investments'!$C$5:$C$205,MATCH('Investment Performance Summary'!$B28,'Statement of Investments'!$B$5:$B$205,0)) -> 45806 | D28: - | E28: =INDEX('Statement of Investments'!$L$5:$L$205,MATCH($B28,'Statement of Investments'!$E$5:$E$205,0)) -> 50000 | F28: =INDEX('Statement of Investments'!$O$5:$O$205,MATCH($B28,'Statement of Investments'!$E$5:$E$205,0)) -> 50000 | G28: 0 | H28: =F28+G28 -> 50000 | I28: =H28/E28 -> 1 | J28: =INDEX('Statement of Investments'!$R$5:$R$205,MATCH($B28,'Statement of Investments'!$E$5:$E$205,0)) -> 4.8828125e-09
B29: Outro Health | C29: =INDEX('Statement of Investments'!$C$5:$C$205,MATCH('Investment Performance Summary'!$B29,'Statement of Investments'!$B$5:$B$205,0)) -> 45806 | D29: - | E29: =INDEX('Statement of Investments'!$L$5:$L$205,MATCH($B29,'Statement of Investments'!$E$5:$E$205,0)) -> 250000 | F29: =INDEX('Statement of Investments'!$O$5:$O$205,MATCH($B29,'Statement of Investments'!$E$5:$E$205,0)) -> 250000 | G29: 0 | H29: =F29+G29 -> 250000 | I29: =H29/E29 -> 1 | J29: =INDEX('Statement of Investments'!$R$5:$R$205,MATCH($B29,'Statement of Investments'!$E$5:$E$205,0)) -> 4.8828125e-09
B30: Tezi | C30: =INDEX('Statement of Investments'!$C$5:$C$205,MATCH('Investment Performance Summary'!$B30,'Statement of Investments'!$B$5:$B$205,0)) -> 45869 | D30: - | E30: =INDEX('Statement of Investments'!$L$5:$L$205,MATCH($B30,'Statement of Investments'!$E$5:$E$205,0)) -> 1999997 | F30: =INDEX('Statement of Investments'!$O$5:$O$205,MATCH($B30,'Statement of Investments'!$E$5:$E$205,0)) -> 1999997 | G30: 0 | H30: =F30+G30 -> 1999997 | I30: =H30/E30 -> 1 | J30: =INDEX('Statement of Investments'!$R$5:$R$205,MATCH($B30,'Statement of Investments'!$E$5:$E$205,0)) -> 4.8828125e-09
B31: Trial Library | C31: =INDEX('Statement of Investments'!$C$5:$C$205,MATCH('Investment Performance Summary'!$B31,'Statement of Investments'!$B$5:$B$205,0)) -> 45877 | D31: - | E31: =INDEX('Statement of Investments'!$L$5:$L$205,MATCH($B31,'Statement of Investments'!$E$5:$E$205,0)) -> 2999998 | F31: =INDEX('Statement of Investments'!$O$5:$O$205,MATCH($B31,'Statement of Investments'!$E$5:$E$205,0)) -> 2999998 | G31: 0 | H31: =F31+G31 -> 2999998 | I31: =H31/E31 -> 1 | J31: =INDEX('Statement of Investments'!$R$5:$R$205,MATCH($B31,'Statement of Investments'!$E$5:$E$205,0)) -> 4.8828125e-09
B32: TrueClaim | C32: =INDEX('Statement of Investments'!$C$5:$C$205,MATCH('Investment Performance Summary'!$B32,'Statement of Investments'!$B$5:$B$205,0)) -> 45924 | E32: =INDEX('Statement of Investments'!$L$5:$L$205,MATCH($B32,'Statement of Investments'!$E$5:$E$205,0)) -> 250000 | F32: =INDEX('Statement of Investments'!$O$5:$O$205,MATCH($B32,'Statement of Investments'!$E$5:$E$205,0)) -> 250000 | G32: 0 | H32: =F32+G32 -> 250000 | I32: =H32/E32 -> 1 | J32: =INDEX('Statement of Investments'!$R$5:$R$205,MATCH($B32,'Statement of Investments'!$E$5:$E$205,0)) -> 4.8828125e-09
B33: Andel | C33: =INDEX('Statement of Investments'!$C$5:$C$205,MATCH('Investment Performance Summary'!$B33,'Statement of Investments'!$B$5:$B$205,0)) -> 45924 | E33: =INDEX('Statement of Investments'!$L$5:$L$205,MATCH($B33,'Statement of Investments'!$E$5:$E$205,0)) -> 250000 | F33: =INDEX('Statement of Investments'!$O$5:$O$205,MATCH($B33,'Statement of Investments'!$E$5:$E$205,0)) -> 250000 | G33: 0 | H33: =F33+G33 -> 250000 | I33: =H33/E33 -> 1 | J33: =INDEX('Statement of Investments'!$R$5:$R$205,MATCH($B33,'Statement of Investments'!$E$5:$E$205,0)) -> 4.8828125e-09
B34: Second Door | C34: =INDEX('Statement of Investments'!$C$5:$C$205,MATCH('Investment Performance Summary'!$B34,'Statement of Investments'!$B$5:$B$205,0)) -> 45924 | E34: =INDEX('Statement of Investments'!$L$5:$L$205,MATCH($B34,'Statement of Investments'!$E$5:$E$205,0)) -> 250000 | F34: =INDEX('Statement of Investments'!$O$5:$O$205,MATCH($B34,'Statement of Investments'!$E$5:$E$205,0)) -> 250000 | G34: 0 | H34: =F34+G34 -> 250000 | I34: =H34/E34 -> 1 | J34: =INDEX('Statement of Investments'!$R$5:$R$205,MATCH($B34,'Statement of Investments'!$E$5:$E$205,0)) -> 4.8828125e-09
B39: Total Unrealized Portfolio | E39: =SUM(E9:E38) -> 70623804 | F39: =SUM(F9:F38) -> 92399729 | G39: =SUM(G9:G38) -> 0 | H39: =SUM(H9:H38) -> 92399729 | I39: =H39/E39 -> 1.3083369 | J39: ='Statement of Investments'!R203 -> 0.23849095
B41: Total Portfolio | E41: =E39 -> 70623804 | F41: =F39 -> 92399729 | G41: =G39 -> 0 | H41: =H39 -> 92399729 | I41: =H41/E41 -> 1.3083369 | J41: ='Statement of Investments'!R205 -> 0.23573356
B44: =3/50 -> 0.06

Sheet Supporting Worksheets -->

Sheet Sheet2
B3: Exit Value | C3: Proceeds | D3: Deal MOIC | E3: Fund MOIC | F3: % of Fund Returned
B4: $200 M | C4: $7 M | D4: 3.33 | E4: 0.05 | F4: 0.05 | G4: =D4*1.43% -> 0.047619
B5: $500 M | C5: $17 M | D5: 8.33 | E5: 0.12 | F5: 0.12 | G5: =D5*1.43% -> 0.119119
B6: $1,000 M | C6: $33 M | D6: 16.65 | E6: 0.24 | F6: 0.23
B7: $4,300 M | C7: $143 M | D7: 71.6 | E7: 1.02 | F7: 1
C9: 2000000

Sheet Statement of Investments
A1: 46022 | B1: As of | C1: =IF(TODAY()<$A$1,TODAY(),A1) -> 46022
C2: Investment | D2: Liquidity | K2: Original Cost | N2: Current Value | Q2: Gross
C3: Date | D3: Date | F3: Security | G3: Stock Certificates | I3: Shares | K3: Per Share | L3: Total Dollars | N3: Per Share | O3: Total Dollars | Q3: MOIC | R3: IRR
S4: 43101 | T4: -0.1
A5: REALIZED
B77: Total Realized Portfolio | L77: =SUM(L5:L76) -> 0 | O77: =SUM(O5:O76) -> 0 | Q77: =IFERROR(O77/L77,0) -> 0 | R77: 0
A79: UNREALIZED
S80: 43101 | T80: -0.1
B81: Laguna Health | C81: 45021 | F81: Series A Preferred Stock | I81: 2487562 | K81: =L81/I81 -> 1.608 | L81: 3999999.7 | N81: =K81 -> 1.608 | O81: =I81*N81 -> 3999999.7 | S81: =IFERROR(C81,0) -> 45021 | T81: =-L81 -> -3999999.7
C82: 45723 | F82: SAFE | L82: 1000000 | O82: =+L82 -> 1000000 | S82: =IFERROR(C82,0) -> 45723 | T82: =-L82 -> -1000000
E84: =B81 -> Laguna Health | F84: Total | L84: =SUM(L81:L83) -> 4999999.7 | O84: =SUM(O81:O83) -> 4999999.7 | Q84: =O84/L84 -> 1 | R84: =XIRR(T81:T84,S81:S84,) -> 2.9802322e-09 | S84: =$C$1 -> 46022 | T84: =O84 -> 4999999.7
B86: Stepful | C86: 45183 | F86: Series A Preferred Stock | I86: 578611 | K86: =+L86/I86 -> 6.9131 | L86: 3999995.7 | N86: =K87 -> 16.818285 | O86: =I86*N86 -> 9731244.8 | S86: =IFERROR(C86,0) -> 45183 | T86: =-L86 -> -3999995.7
C87: 45590 | F87: Series B Preferred Stock | I87: 123625 | K87: =L87/I87 -> 16.818285 | L87: 2079160.5 | N87: =N86 -> 16.818285 | O87: =I87*N87 -> 2079160.5 | S87: =IFERROR(C87,0) -> 45590 | T87: =-L87 -> -2079160.5
C88: 45828 | F88: Common Stock | I88: 118816 | K88: =L88/I88 -> 15.14 | L88: 1798874.2 | N88: =K88 -> 15.14 | O88: =I88*N88 -> 1798874.2 | S88: =IFERROR(C88,0) -> 45828 | T88: =-L88 -> -1798874.2
E90: =B86 -> Stepful | F90: Total | I90: =SUM(I86:I89) -> 821052 | L90: =SUM(L86:L88) -> 7878030.5 | O90: =SUM(O86:O89) -> 13609280 | Q90: =O90/L90 -> 1.7274977 | R90: =XIRR(T86:T90,S86:S90,0) -> 0.38251794 | S90: =$C$1 -> 46022 | T90: =O90 -> 13609280
B92: Summer | C92: 45209 | F92: Series A - II Preferred | I92: 2471857 | K92: =L92/I92 -> 1.314801 | L92: =2250000+1000000 -> 3250000 | N92: 0 | O92: =L92 -> 3250000 | S92: =IFERROR(C92,0) -> 45209 | T92: =-L92 -> -3250000
C93: 45756 | F93: Common Stock Warrants | I93: 1235928 | O93: =N93*I93 -> 0 | S93: =IFERROR(C93,0) -> 45756 | T93: =-L93 -> 0
E95: =B92 -> Summer | F95: Total | L95: =SUM(L92:L94) -> 3250000 | O95: =SUM(O92:O94) -> 3250000 | Q95: =O95/L95 -> 1 | R95: =XIRR(T92:T95,S92:S95,0) -> 4.8828125e-09 | S95: =$C$1 -> 46022 | T95: =O95 -> 3250000
B97: Wagmo | C97: 45209 | F97: Series A-1 Preferred Stock | I97: 499599.67 | K97: 3.0024 | L97: 1499998 | N97: 3.0024 | O97: =+L97 -> 1499998 | S97: =IFERROR(C97,0) -> 45209 | T97: =-L97 -> -1499998
F98: Series A-1 Warrants | I98: 99920 | N98: =N97-K97 -> 0 | O98: =+L98 -> 0
E100: =B97 -> Wagmo | F100: Total | L100: =SUM(L97:L99) -> 1499998 | O100: =SUM(O97:O99) -> 1499998 | Q100: =O100/L100 -> 1 | R100: =XIRR(T97:T100,S97:S100,0) -> 4.8828125e-09 | S100: =$C$1 -> 46022 | T100: =O100 -> 1499998
B102: Kubera | C102: 45274 | F102: Series Seed Preferred Stock | I102: 447777 | K102: =+L102/I102 -> 0.89330001 | L102: 399999.2 | N102: =N103 -> 1.9727001 | O102: =+I102*N102 -> 883329.72 | S102: =IFERROR(C102,0) -> 45274 | T102: =-L102 -> -399999.2
C103: 45924 | F103: Series Seed-1 Preferred Stock | I103: 64928 | K103: =+L103/I103 -> 1.9727001 | L103: 128083.47 | N103: =K103 -> 1.9727001 | O103: =+I103*N103 -> 128083.47 | S103: =IFERROR(C103,0) -> 45924 | T103: =-L103 -> -128083.47
E104: =B102 -> Kubera | F104: Total | L104: =SUM(L102:L103) -> 528082.67 | O104: =SUM(O102:O103) -> 1011413.2 | Q104: =O104/L104 -> 1.9152554 | R104: =XIRR(T102:T104,S102:S104,0) -> 0.46074747 | S104: =$C$1 -> 46022 | T104: =O104 -> 1011413.2
B106: Salsa | C106: 45329 | F106: Series A-1 Preferred Stock | I106: =832084+11634 -> 843718 | K106: =L106/I106 -> 2.9630753 | L106: =2.5*10^6 -> 2500000 | N106: =K107 -> 3.4524997 | O106: =I106*N106 -> 2912936.2 | S106: =IFERROR(C106,0) -> 45329 | T106: =-L106 -> -2500000
C107: 45747 | F107: Series A Preferred Stock | I107: =856953+11982 -> 868935 | K107: =L107/I107 -> 3.4524997 | L107: =2958599.41+41398.45 -> 2999997.9 | N107: =K107 -> 3.4524997 | O107: =I107*N107 -> 2999997.9 | S107: =IFERROR(C107,0) -> 45747 | T107: =-L107 -> -2999997.9
E109: =B106 -> Salsa | F109: Total | L109: =SUM(L106:L108) -> 5499997.9 | O109: =SUM(O106:O108) -> 5912934 | Q109: =O109/L109 -> 1.0750793 | R109: =XIRR(T106:T109,S106:S109,0) -> 0.058040698 | S109: =$C$1 -> 46022 | T109: =O109 -> 5912934
B111: Solara | C111: 45329 | F111: Series Seed Preferred Stock | I111: 2041441 | K111: =L111/I111 -> 0.9797 | L111: 1999999.8 | N111: 1.3442 | O111: =+I111*N111 -> 2744105 | S111: =IFERROR(C111,0) -> 45329 | T111: =-L111 -> -1999999.8
C112: 46008 | F112: Series A Preferred Stock | I112: 1898606 | K112: =L112/I112 -> 1.3442489 | L112: =2552199 -> 2552199 | N112: 1.3442 | O112: =N112*I112 -> 2552106.2 | S112: =IFERROR(C112,0) -> 46008 | T112: =-L112 -> -2552199
E114: =B111 -> Solara | F114: Total | L114: =SUM(L111:L113) -> 4552198.8 | O114: =SUM(O111:O113) -> 5296211.2 | Q114: =O114/L114 -> 1.1634402 | R114: =XIRR(T111:T114,S111:S114,0) -> 0.17761299 | S114: =$C$1 -> 46022 | T114: =O114 -> 5296211.2
B116: Hireguide | C116: 45351 | F116: SAFE Note | I116: 0 | K116: 0 | L116: =3*10^6 -> 3000000 | N116: 0 | O116: =500000 -> 500000 | S116: =IFERROR(C116,0) -> 45351 | T116: =-L116 -> -3000000
E118: =B116 -> Hireguide | F118: Total | L118: =SUM(L116:L117) -> 3000000 | O118: =SUM(O116:O117) -> 500000 | Q118: =O118/L118 -> 0.16666667 | R118: =XIRR(T116:T118,S116:S118,0) -> -0.62267676 | S118: =$C$1 -> 46022 | T118: =O118 -> 500000
B120: Take2 AI | C120: 45376 | F120: SAFE Note | I120: 0 | K120: 0 | L120: =700000 -> 700000 | N120: 0 | O120: =L120 -> 700000 | S120: =IFERROR(C120,0) -> 45376 | T120: =-L120 -> -700000
E122: =B120 -> Take2 AI | F122: Total | L122: =SUM(L120:L121) -> 700000 | O122: =SUM(O120:O121) -> 700000 | Q122: =O122/L122 -> 1 | R122: =XIRR(T120:T122,S120:S122,0) -> 4.8828125e-09 | S122: =$C$1 -> 46022 | T122: =O122 -> 700000
B124: Techwolf | C124: 45467 | F124: Series B Preferred Stock | I124: 112815 | L124: 5037377 | O124: =+L124 -> 5037377 | S124: =IFERROR(C124,0) -> 45467 | T124: =-L124 -> -5037377
E126: =B124 -> Techwolf | F126: Total | L126: =SUM(L124:L125) -> 5037377 | O126: =SUM(O124:O125) -> 5037377 | Q126: =O126/L126 -> 1 | R126: =XIRR(T124:T126,S124:S126,0) -> 4.8828125e-09 | S126: =$C$1 -> 46022 | T126: =O126 -> 5037377
B128: Thatch | C128: 45513 | F128: Series A Preferred Stock | I128: 309845 | K128: 4.8734 | L128: 1509998.6 | N128: =+K131 -> 12.3072 | O128: =I128*N128 -> 3813324.4 | S128: =IFERROR(C128,0) -> 45513 | T128: =-L128 -> -1509998.6
C129: 45525 | F129: Series Seed Preferred Stock - Secondary Purchase | I129: =L129/K129 -> 26806.002 | K129: 4.8734 | L129: =129067.13+1569.24 -> 130636.37 | N129: =N128 -> 12.3072 | O129: =I129*N129 -> 329906.83 | S129: =IFERROR(C129,0) -> 45525 | T129: =-L129 -> -130636.37
C130: 45508 | F130: Series A Warrants | I130: 512988.88 | K130: 0 | L130: 0 | N130: =O130/I130 -> 7.3312759 | O130: 3760863 | S130: =IFERROR(C130,0) -> 45508 | T130: =-L130 -> 0 | U130: =+I130*K129 -> 2500000
C131: 45737 | F131: Series B Preferred Stock | I131: =191302+3705 -> 195007 | K131: =+L131/I131 -> 12.3072 | L131: =2354391.98+45598.18 -> 2399990.2 | N131: =+K131 -> 12.3072 | O131: =2.4*10^6 -> 2400000 | S131: =IFERROR(C131,0) -> 45737 | T131: =-L131 -> -2399990.2
...

Sheet Investment Characteristics
Q1: =Q8*N8 -> 1499860.1 | Y1: =143*10^6 -> 143000000
B2: Core Initial Investment Characteristics | K2: Current Investment Characteristics
B3: Company | C3: Date | D3: Series | E3: Sector | F3: $ Invested | G3: VC Syndicate | H3: FD% | I3: Avg. Cost | K3: Company | L3: Series | M3: FD% Actual | N3: With warrants fully vested | O3: Initital Cost | P3: Avg. Cost | Q3: Last Valuation | R3: Holding Value | S3: $ Invested | T3: Follow -On Investment | U3: Market Value | V3: Multiple | W3: Lead | X3: Allocation | Y3: RTF | Z3: Board Seat | AB3: 45107 | AC3: 45473 | AD3: 45565 | AE3: 45657 | AF3: 45838 | AG3: 45930 | AI3: Rationale
A4: x | B4: Laguna Health | C4: =INDEX('Statement of Investments'!$C$5:$C$205,MATCH('Investment Characteristics'!$B4,'Statement of Investments'!$B$5:$B$205,0)) -> 45021 | D4: A | E4: Healthtech | F4: =INDEX('Statement of Investments'!$L$5:$L$205,MATCH('Investment Characteristics'!$B4,'Statement of Investments'!$B$5:$B$205,0)) -> 3999999.7 | G4: HC9, Pitango | H4: 0.07547 | I4: =IFERROR(ROUND(F4/H4,-5),0) -> 53000000 | K4: =B4 -> Laguna Health | L4: A | M4: 0.077934988 | N4: =M4 -> 0.077934988 | O4: =I4 -> 53000000 | P4: =IFERROR(ROUND(S4/M4,-5),0) -> 64200000 | Q4: =O4 -> 53000000 | R4: =+Q4 -> 53000000 | S4: =INDEX('Statement of Investments'!$L$5:$L$205,MATCH(B4,'Statement of Investments'!$E$5:$E$205,0)) -> 4999999.7 | T4: =S4-F4 -> 1000000 | U4: =INDEX('Statement of Investments'!$O$5:$O$205,MATCH(B4,'Statement of Investments'!$E$5:$E$205,0)) -> 4999999.7 | V4: =U4/S4 -> 1 | W4: RP | X4: GG | Y4: =+$Y$1/M4/10^6 -> 1834.8627 | AB4: 1 | AC4: 1 | AD4: 0 | AE4: 0
A5: x | B5: Stepful | C5: =INDEX('Statement of Investments'!$C$5:$C$205,MATCH('Investment Characteristics'!$B5,'Statement of Investments'!$B$5:$B$205,0)) -> 45183 | D5: A | E5: Workforce | F5: =INDEX('Statement of Investments'!$L$5:$L$205,MATCH('Investment Characteristics'!$B5,'Statement of Investments'!$B$5:$B$205,0)) -> 3999995.7 | G5: Reach, Alleycorp, YC | H5: 0.043589887 | I5: =IFERROR(ROUND(F5/H5,-5),0) -> 91800000 | K5: =B5 -> Stepful | L5: B | M5: 0.052805468 | N5: =M5 -> 0.052805468 | O5: =I5 -> 91800000 | P5: =IFERROR(ROUND(S5/M5,-5),0) -> 149200000 | Q5: 261500000 | R5: =+Q5 -> 261500000 | S5: =INDEX('Statement of Investments'!$L$5:$L$205,MATCH(B5,'Statement of Investments'!$E$5:$E$205,0)) -> 7878030.5 | T5: =S5-F5 -> 3878034.7 | U5: =INDEX('Statement of Investments'!$O$5:$O$205,MATCH(B5,'Statement of Investments'!$E$5:$E$205,0)) -> 13609280 | V5: =U5/S5 -> 1.7274977 | W5: ABG | X5: ABG | Y5: =+$Y$1/M5/10^6 -> 2708.0529 | AB5: - | AC5: 1 | AD5: 1 | AE5: 1
B6: Summer | C6: =INDEX('Statement of Investments'!$C$5:$C$205,MATCH('Investment Characteristics'!$B6,'Statement of Investments'!$B$5:$B$205,0)) -> 45209 | D6: Seed | E6: Financial | F6: =INDEX('Statement of Investments'!$L$5:$L$205,MATCH('Investment Characteristics'!$B6,'Statement of Investments'!$B$5:$B$205,0)) -> 3250000 | G6: GC, QED, Flourish, Rebalance | H6: =+F6/I6 -> 0.092857143 | I6: =35*10^6 -> 35000000 | K6: =B6 -> Summer | L6: A | M6: 0.11734531 | N6: =M6 -> 0.11734531 | O6: =I6 -> 35000000 | P6: =IFERROR(ROUND(S6/M6,-5),0) -> 27700000 | Q6: 41544018 | R6: 41544018 | S6: =INDEX('Statement of Investments'!$L$5:$L$205,MATCH(B6,'Statement of Investments'!$E$5:$E$205,0)) -> 3250000 | T6: =S6-F6 -> 0 | U6: =INDEX('Statement of Investments'!$O$5:$O$205,MATCH(B6,'Statement of Investments'!$E$5:$E$205,0)) -> 3250000 | V6: =U6/S6 -> 1 | W6: RP | X6: RP | Y6: =+$Y$1/M6/10^6 -> 1218.6256 | AB6: - | AC6: 1 | AD6: 0 | AE6: -1
B7: Kubera | C7: =INDEX('Statement of Investments'!$C$5:$C$205,MATCH('Investment Characteristics'!$B7,'Statement of Investments'!$B$5:$B$205,0)) -> 45274 | D7: Seed | E7: Healthtech | F7: =INDEX('Statement of Investments'!$L$5:$L$205,MATCH('Investment Characteristics'!$B7,'Statement of Investments'!$B$5:$B$205,0)) -> 399999.2 | G7: Upfront Ventures | H7: =+F7/I7 -> 0.033333267 | I7: =12*10^6 -> 12000000 | K7: =B7 -> Kubera | L7: Seed | M7: 0.033713855 | N7: =M7 -> 0.033713855 | O7: =I7 -> 12000000 | P7: =IFERROR(ROUND(S7/M7,-5),0) -> 15700000 | Q7: 30000000 | R7: =+Q7 -> 30000000 | S7: =INDEX('Statement of Investments'!$L$5:$L$205,MATCH(B7,'Statement of Investments'!$E$5:$E$205,0)) -> 528082.67 | T7: =S7-F7 -> 128083.47 | U7: =INDEX('Statement of Investments'!$O$5:$O$205,MATCH(B7,'Statement of Investments'!$E$5:$E$205,0)) -> 1011413.2 | V7: =U7/S7 -> 1.9152554 | W7: RP | X7: RP | Y7: =+$Y$1/M7/10^6 -> 4241.5796 | AB7: - | AC7: 1 | AD7: 1 | AE7: 0
B8: Wagmo | C8: =INDEX('Statement of Investments'!$C$5:$C$205,MATCH('Investment Characteristics'!$B8,'Statement of Investments'!$B$5:$B$205,0)) -> 45209 | D8: A | E8: Financial | F8: =INDEX('Statement of Investments'!$L$5:$L$205,MATCH('Investment Characteristics'!$B8,'Statement of Investments'!$B$5:$B$205,0)) -> 1499998 | G8: Revolution, MS&AD | H8: 0.03180843 | I8: =IFERROR(ROUND(F8/H8,-5),0) -> 47200000 | K8: =B8 -> Wagmo | L8: A | M8: =(133226+499600+0.75*199840)/26203667 -> 0.029870094 | N8: =(133226+499600+199840)/26203667 -> 0.031776698 | O8: =I8 -> 47200000 | P8: =IFERROR(ROUND(S8/M8,-5),0) -> 50200000 | Q8: =O8 -> 47200000 | R8: =+Q8 -> 47200000 | S8: =INDEX('Statement of Investments'!$L$5:$L$205,MATCH(B8,'Statement of Investments'!$E$5:$E$205,0)) -> 1499998 | T8: =S8-F8 -> 0 | U8: =INDEX('Statement of Investments'!$O$5:$O$205,MATCH(B8,'Statement of Investments'!$E$5:$E$205,0)) -> 1499998 | V8: =U8/S8 -> 1 | W8: RP | X8: CH | Y8: =+$Y$1/M8/10^6 -> 4787.397 | AB8: - | AC8: 1 | AD8: 0 | AE8: 1
B9: Salsa | C9: =INDEX('Statement of Investments'!$C$5:$C$205,MATCH('Investment Characteristics'!$B9,'Statement of Investments'!$B$5:$B$205,0)) -> 45329 | D9: Seed | E9: Financial | F9: =INDEX('Statement of Investments'!$L$5:$L$205,MATCH('Investment Characteristics'!$B9,'Statement of Investments'!$B$5:$B$205,0)) -> 2500000 | G9: BTV, Greycroft | H9: =+F9/I9 -> 0.056818182 | I9: =44*10^6 -> 44000000 | K9: =B9 -> Salsa | L9: A | M9: 0.084687403 | N9: =M9 -> 0.084687403 | O9: =I9 -> 44000000 | P9: =IFERROR(ROUND(S9/M9,-5),0) -> 64900000 | Q9: =70*10^6 -> 70000000 | R9: =+Q9 -> 70000000 | S9: =INDEX('Statement of Investments'!$L$5:$L$205,MATCH(B9,'Statement of Investments'!$E$5:$E$205,0)) -> 5499997.9 | T9: =S9-F9 -> 2999997.9 | U9: =INDEX('Statement of Investments'!$O$5:$O$205,MATCH(B9,'Statement of Investments'!$E$5:$E$205,0)) -> 5912934 | V9: =U9/S9 -> 1.0750793 | W9: RP | X9: CH | Y9: =+$Y$1/M9/10^6 -> 1688.5628 | AB9: - | AC9: 1 | AD9: 1 | AE9: 1
A10: x | B10: Solara | C10: =INDEX('Statement of Investments'!$C$5:$C$205,MATCH('Investment Characteristics'!$B10,'Statement of Investments'!$B$5:$B$205,0)) -> 45329 | D10: Seed | E10: Healthtech | F10: =INDEX('Statement of Investments'!$L$5:$L$205,MATCH('Investment Characteristics'!$B10,'Statement of Investments'!$B$5:$B$205,0)) -> 1999999.8 | G10: Define Ventures, USVP | H10: =+F10/I10 -> 0.13793102 | I10: 14500000 | K10: =B10 -> Solara | L10: Seed | M10: 0.1309 | N10: =M10 -> 0.1309 | O10: =I10 -> 14500000 | P10: =IFERROR(ROUND(S10/M10,-5),0) -> 34800000 | Q10: =40000000 -> 40000000 | R10: =+Q10 -> 40000000 | S10: =INDEX('Statement of Investments'!$L$5:$L$205,MATCH(B10,'Statement of Investments'!$E$5:$E$205,0)) -> 4552198.8 | T10: =S10-F10 -> 2552199 | U10: =INDEX('Statement of Investments'!$O$5:$O$205,MATCH(B10,'Statement of Investments'!$E$5:$E$205,0)) -> 5296211.2 | V10: =U10/S10 -> 1.1634402 | W10: RP | X10: GG | Y10: =+$Y$1/M10/10^6 -> 1092.437 | AB10: - | AC10: 1 | AD10: 1 | AE10: 1
A11: x | B11: Hireguide | C11: =INDEX('Statement of Investments'!$C$5:$C$205,MATCH('Investment Characteristics'!$B11,'Statement of Investments'!$B$5:$B$205,0)) -> 45351 | D11: Seed | E11: Workforce | F11: =INDEX('Statement of Investments'!$L$5:$L$205,MATCH('Investment Characteristics'!$B11,'Statement of Investments'!$B$5:$B$205,0)) -> 3000000 | G11: Wing, NEA, GGV | H11: =+F11/I11 -> 0.09375 | I11: =32*10^6 -> 32000000 | K11: =B11 -> Hireguide | L11: Seed | M11: 0.09375 | N11: =M11 -> 0.09375 | O11: =I11 -> 32000000 | P11: =IFERROR(ROUND(S11/M11,-5),0) -> 32000000 | Q11: =O11 -> 32000000 | R11: =+Q11 -> 32000000 | S11: =INDEX('Statement of Investments'!$L$5:$L$205,MATCH(B11,'Statement of Investments'!$E$5:$E$205,0)) -> 3000000 | T11: =S11-F11 -> 0 | U11: =INDEX('Statement of Investments'!$O$5:$O$205,MATCH(B11,'Statement of Investments'!$E$5:$E$205,0)) -> 500000 | V11: =U11/S11 -> 0.16666667 | W11: CT | X11: RP | Y11: =+$Y$1/M11/10^6 -> 1525.3333 | AB11: - | AD11: 1 | AE11: 0
B12: Take2 AI | C12: =INDEX('Statement of Investments'!$C$5:$C$205,MATCH('Investment Characteristics'!$B12,'Statement of Investments'!$B$5:$B$205,0)) -> 45376 | D12: Seed | E12: Workforce | F12: =INDEX('Statement of Investments'!$L$5:$L$205,MATCH('Investment Characteristics'!$B12,'Statement of Investments'!$B$5:$B$205,0)) -> 700000 | G12: Reach Capital | H12: =+F12/I12 -> 0.07 | I12: 10000000 | K12: =B12 -> Take2 AI | L12: Seed | M12: 0.07 | N12: =M12 -> 0.07 | O12: =I12 -> 10000000 | P12: =IFERROR(ROUND(S12/M12,-5),0) -> 10000000 | Q12: =O12 -> 10000000 | R12: =+Q12 -> 10000000 | S12: =INDEX('Statement of Investments'!$L$5:$L$205,MATCH(B12,'Statement of Investments'!$E$5:$E$205,0)) -> 700000 | T12: =S12-F12 -> 0 | U12: =INDEX('Statement of Investments'!$O$5:$O$205,MATCH(B12,'Statement of Investments'!$E$5:$E$205,0)) -> 700000 | V12: =U12/S12 -> 1 | W12: ABG | X12: ABG | Y12: =+$Y$1/M12/10^6 -> 2042.8571 | AB12: - | AD12: 1 | AE12: 0
B13: Techwolf | C13: =INDEX('Statement of Investments'!$C$5:$C$205,MATCH('Investment Characteristics'!$B13,'Statement of Investments'!$B$5:$B$205,0)) -> 45467 | D13: B | E13: Workforce | F13: =INDEX('Statement of Investments'!$L$5:$L$205,MATCH('Investment Characteristics'!$B13,'Statement of Investments'!$B$5:$B$205,0)) -> 5037377 | G13: Felix Capital, Stride VC | H13: =+F13/I13 -> 0.035726078 | I13: =141*10^6 -> 141000000 | K13: =B13 -> Techwolf | L13: B | M13: 0.035210817 | N13: =M13 -> 0.035210817 | O13: =I13 -> 141000000 | P13: =IFERROR(ROUND(S13/M13,-5),0) -> 143100000 | Q13: =O13 -> 141000000 | R13: =+Q13 -> 141000000 | S13: =INDEX('Statement of Investments'!$L$5:$L$205,MATCH(B13,'Statement of Investments'!$E$5:$E$205,0)) -> 5037377 | T13: =S13-F13 -> 0 | U13: =INDEX('Statement of Investments'!$O$5:$O$205,MATCH(B13,'Statement of Investments'!$E$5:$E$205,0)) -> 5037377 | V13: =U13/S13 -> 1 | W13: ABG | X13: ABG | Y13: =+$Y$1/M13/10^6 -> 4061.252 | AE13: 1
B14: Thatch | C14: =INDEX('Statement of Investments'!$C$5:$C$205,MATCH('Investment Characteristics'!$B14,'Statement of Investments'!$B$5:$B$205,0)) -> 45513 | D14: A | E14: Healthtech | F14: =INDEX('Statement of Investments'!$L$5:$L$205,MATCH('Investment Characteristics'!$B14,'Statement of Investments'!$B$5:$B$205,0)) -> 1509998.6 | G14: Index, GV, GC, a16z | H14: 0.029703718 | I14: =F14/H14 -> 50835341 | K14: =B14 -> Thatch | L14: B | M14: 0.032141794 | N14: =M14 -> 0.032141794 | O14: =I14 -> 50835341 | P14: =IFERROR(ROUND(S14/M14,-5),0) -> 125700000 | Q14: =450*10^6 -> 450000000 | R14: =450*10^6 -> 450000000 | S14: =INDEX('Statement of Investments'!$L$5:$L$205,MATCH(B14,'Statement of Investments'!$E$5:$E$205,0)) -> 4040625.2 | T14: =S14-F14 -> 2530626.5 | U14: =INDEX('Statement of Investments'!$O$5:$O$205,MATCH(B14,'Statement of Investments'!$E$5:$E$205,0)) -> 10304094 | V14: =U14/S14 -> 2.5501238 | W14: RP | X14: GG | Y14: =+$Y$1/M14/10^6 -> 4449.0361 | AE14: 1
A15: x | B15: Multimodal | C15: =INDEX('Statement of Investments'!$C$5:$C$205,MATCH('Investment Characteristics'!$B15,'Statement of Investments'!$B$5:$B$205,0)) -> 45614 | D15: Seed | E15: Financial | F15: =INDEX('Statement of Investments'!$L$5:$L$205,MATCH('Investment Characteristics'!$B15,'Statement of Investments'!$B$5:$B$205,0)) -> 2000000 | H15: =+F15/I15 -> 0.066666667 | I15: =30*10^6 -> 30000000 | K15: =B15 -> Multimodal | L15: Seed | M15: 0.066666667 | N15: =M15 -> 0.066666667 | O15: =I15 -> 30000000 | P15: =IFERROR(ROUND(S15/M15,-5),0) -> 30000000 | Q15: =O15 -> 30000000 | R15: =+Q15 -> 30000000 | S15: =INDEX('Statement of Investments'!$L$5:$L$205,MATCH(B15,'Statement of Investments'!$E$5:$E$205,0)) -> 2000000 | T15: =S15-F15 -> 0 | U15: =INDEX('Statement of Investments'!$O$5:$O$205,MATCH(B15,'Statement of Investments'!$E$5:$E$205,0)) -> 2000000 | V15: =U15/S15 -> 1 | W15: CH | X15: CH | Y15: =+$Y$1/M15/10^6 -> 2145 | AE15: 1
A16: x | B16: OneImaging | C16: =INDEX('Statement of Investments'!$C$5:$C$205,MATCH('Investment Characteristics'!$B16,'Statement of Investments'!$B$5:$B$205,0)) -> 45665 | D16: Seed | E16: Healthtech | F16: =INDEX('Statement of Investments'!$L$5:$L$205,MATCH('Investment Characteristics'!$B16,'Statement of Investments'!$B$5:$B$205,0)) -> 1000000 | G16: Aquiline, Six Thirty, Vy Capital | H16: =+F16/I16 -> 0.055555556 | I16: =18*10^6 -> 18000000 | K16: =B16 -> OneImaging | L16: A | M16: 0.05994 | N16: =M16 -> 0.05994 | O16: =I16 -> 18000000 | P16: =IFERROR(ROUND(S16/M16,-5),0) -> 66700000 | Q16: 250000000 | R16: =+Q16 -> 250000000 | S16: =INDEX('Statement of Investments'!$L$5:$L$205,MATCH(B16,'Statement of Investments'!$E$5:$E$205,0)) -> 4000000 | T16: =S16-F16 -> 3000000 | U16: =INDEX('Statement of Investments'!$O$5:$O$205,MATCH(B16,'Statement of Investments'!$E$5:$E$205,0)) -> 14640928 | V16: =U16/S16 -> 3.660232 | W16: CT | X16: RP | Y16: =+$Y$1/M16/10^6 -> 2385.7191 | AE16: 1
B17: ExceedsAI | C17: =INDEX('Statement of Investments'!$C$5:$C$205,MATCH('Investment Characteristics'!$B17,'Statement of Investments'!$B$5:$B$205,0)) -> 45666 | D17: Seed | E17: Workforce | F17: =INDEX('Statement of Investments'!$L$5:$L$205,MATCH('Investment Characteristics'!$B17,'Statement of Investments'!$B$5:$B$205,0)) -> 1187499.8 | G17: Venrock | H17: =+F17/I17 -> 0.079166656 | I17: =15*10^6 -> 15000000 | K17: =B17 -> ExceedsAI | L17: Seed | M17: 0.079166656 | N17: =M17 -> 0.079166656 | O17: =I17 -> 15000000 | P17: =IFERROR(ROUND(S17/M17,-5),0) -> 15000000 | Q17: =O17 -> 15000000 | R17: =+Q17 -> 15000000 | S17: =INDEX('Statement of Investments'!$L$5:$L$205,MATCH(B17,'Statement of Investments'!$E$5:$E$205,0)) -> 1187499.8 | T17: =S17-F17 -> 0 | U17: =INDEX('Statement of Investments'!$O$5:$O$205,MATCH(B17,'Statement of Investments'!$E$5:$E$205,0)) -> 1187499.8 | V17: =U17/S17 -> 1 | W17: ABG | X17: ABG | Y17: =+$Y$1/M17/10^6 -> 1806.316 | AE17: 1
B18: Sully.AI | C18: =INDEX('Statement of Investments'!$C$5:$C$205,MATCH('Investment Characteristics'!$B18,'Statement of Investments'!$B$5:$B$205,0)) -> 45666 | D18: A | E18: Healthtech | F18: =INDEX('Statement of Investments'!$L$5:$L$205,MATCH('Investment Characteristics'!$B18,'Statement of Investments'!$B$5:$B$205,0)) -> 3999999.5 | G18: Amity Ventures | H18: =+F18/I18 -> 0.053333327 | I18: =75*10^6 -> 75000000 | K18: =B18 -> Sully.AI | L18: A | M18: 0.053333327 | N18: =M18 -> 0.053333327 | O18: =I18 -> 75000000 | P18: =IFERROR(ROUND(S18/M18,-5),0) -> 75000000 | Q18: =O18 -> 75000000 | R18: =+Q18 -> 75000000 | S18: =INDEX('Statement of Investments'!$L$5:$L$205,MATCH(B18,'Statement of Investments'!$E$5:$E$205,0)) -> 3999999.5 | T18: =S18-F18 -> 0 | U18: =INDEX('Statement of Investments'!$O$5:$O$205,MATCH(B18,'Statement of Investments'!$E$5:$E$205,0)) -> 3999999.5 | V18: =U18/S18 -> 1 | W18: ABG | X18: ABG | Y18: =+$Y$1/M18/10^6 -> 2681.2503 | AE18: 1
A19: x | B19: Athena.AI | C19: =INDEX('Statement of Investments'!$C$5:$C$205,MATCH('Investment Characteristics'!$B19,'Statement of Investments'!$B$5:$B$205,0)) -> 45778 | D19: Seed | E19: Workforce | F19: =INDEX('Statement of Investments'!$L$5:$L$205,MATCH('Investment Characteristics'!$B19,'Statement of Investments'!$B$5:$B$205,0)) -> 3150000 | G19: Village Global | H19: =+F19/I19 -> 0.09 | I19: =35*10^6 -> 35000000 | K19: =B19 -> Athena.AI | L19: Seed | M19: 0.09 | N19: =M19 -> 0.09 | O19: =I19 -> 35000000 | P19: =IFERROR(ROUND(S19/M19,-5),0) -> 35000000 | Q19: =O19 -> 35000000 | R19: =+Q19 -> 35000000 | S19: =INDEX('Statement of Investments'!$L$5:$L$205,MATCH(B19,'Statement of Investments'!$E$5:$E$205,0)) -> 3150000 | T19: =S19-F19 -> 0 | U19: =INDEX('Statement of Investments'!$O$5:$O$205,MATCH(B19,'Statement of Investments'!$E$5:$E$205,0)) -> 3150000 | V19: =U19/S19 -> 1 | W19: RP | X19: RP | Y19: =+$Y$1/M19/10^6 -> 1588.8889
A20: x | B20: Onboarded | C20: =INDEX('Statement of Investments'!$C$5:$C$205,MATCH('Investment Characteristics'!$B20,'Statement of Investments'!$B$5:$B$205,0)) -> 45824 | D20: A | E20: Workforce | F20: =INDEX('Statement of Investments'!$L$5:$L$205,MATCH('Investment Characteristics'!$B20,'Statement of Investments'!$B$5:$B$205,0)) -> 5000000 | G20: SV, Resolute | H20: =+F20/I20 -> 0.086956522 | I20: =57.5*10^6 -> 57500000 | K20: =B20 -> Onboarded | L20: A | M20: 0.086956522 | N20: =M20 -> 0.086956522 | O20: =I20 -> 57500000 | P20: =IFERROR(ROUND(S20/M20,-5),0) -> 57500000 | Q20: =O20 -> 57500000 | R20: =+Q20 -> 57500000 | S20: =INDEX('Statement of Investments'!$L$5:$L$205,MATCH(B20,'Statement of Investments'!$E$5:$E$205,0)) -> 5000000 | T20: =S20-F20 -> 0 | U20: =INDEX('Statement of Investments'!$O$5:$O$205,MATCH(B20,'Statement of Investments'!$E$5:$E$205,0)) -> 5000000 | V20: =U20/S20 -> 1 | W20: CT | X20: GG | Y20: =+$Y$1/M20/10^6 -> 1644.5
B21: PenguinAI | C21: =INDEX('Statement of Investments'!$C$5:$C$205,MATCH('Investment Characteristics'!$B21,'Statement of Investments'!$B$5:$B$205,0)) -> 45821 | D21: A | E21: Healthtech | F21: =INDEX('Statement of Investments'!$L$5:$L$205,MATCH('Investment Characteristics'!$B21,'Statement of Investments'!$B$5:$B$205,0)) -> 4000000 | G21: GreyCroft, UPMC | H21: =+F21/I21 -> 0.024242424 | I21: =165*10^6 -> 165000000 | K21: =B21 -> PenguinAI | L21: A | M21: 0.02527 | N21: =M21 -> 0.02527 | O21: =I21 -> 165000000 | P21: =IFERROR(ROUND(S21/M21,-5),0) -> 158300000 | Q21: =O21 -> 165000000 | R21: =+Q21 -> 165000000 | S21: =INDEX('Statement of Investments'!$L$5:$L$205,MATCH(B21,'Statement of Investments'!$E$5:$E$205,0)) -> 4000000 | T21: =S21-F21 -> 0 | U21: =INDEX('Statement of Investments'!$O$5:$O$205,MATCH(B21,'Statement of Investments'!$E$5:$E$205,0)) -> 4000000 | V21: =U21/S21 -> 1 | W21: GG | X21: GG | Y21: =+$Y$1/M21/10^6 -> 5658.8841
B22: Tezi | C22: =INDEX('Statement of Investments'!$C$5:$C$205,MATCH('Investment Characteristics'!$B22,'Statement of Investments'!$B$5:$B$205,0)) -> 45869 | D22: Seed | E22: Workforce | F22: =INDEX('Statement of Investments'!$L$5:$L$205,MATCH('Investment Characteristics'!$B22,'Statement of Investments'!$B$5:$B$205,0)) -> 1999997 | G22: 8VC, Audacious | H22: =F22/I22 -> 0.033333283 | I22: 60000000 | K22: =B22 -> Tezi | L22: Seed | M22: 0.033333283 | N22: =M22+((389350+(500000/(0.8*3.34)))/17969903) -> 0.065413353 | O22: =I22 -> 60000000 | P22: =IFERROR(ROUND(S22/M22,-5),0) -> 60000000 | Q22: =O22 -> 60000000 | R22: =+Q22 -> 60000000 | S22: =INDEX('Statement of Investments'!$L$5:$L$205,MATCH(B22,'Statement of Investments'!$E$5:$E$205,0)) -> 1999997 | T22: =S22-F22 -> 0 | U22: =INDEX('Statement of Investments'!$O$5:$O$205,MATCH(B22,'Statement of Investments'!$E$5:$E$205,0)) -> 1999997 | V22: =U22/S22 -> 1 | W22: RP | X22: RP | Y22: =+$Y$1/M22/10^6 -> 4290.0064
A23: x | B23: Trial Library | C23: =INDEX('Statement of Investments'!$C$5:$C$205,MATCH('Investment Characteristics'!$B23,'Statement of Investments'!$B$5:$B$205,0)) -> 45877 | D23: A | E23: Healthtech | F23: =INDEX('Statement of Investments'!$L$5:$L$205,MATCH('Investment Characteristics'!$B23,'Statement of Investments'!$B$5:$B$205,0)) -> 2999998 | G23: Lux, Next Ventures | H23: =F23/I23 -> 0.05999996 | I23: =50*10^6 -> 50000000 | K23: =B23 -> Trial Library | L23: A | M23: 0.060720105 | N23: =M23 -> 0.060720105 | O23: =I23 -> 50000000 | P23: =IFERROR(ROUND(S23/M23,-5),0) -> 49400000 | Q23: =O23 -> 50000000 | R23: =+Q23 -> 50000000 | S23: =INDEX('Statement of Investments'!$L$5:$L$205,MATCH(B23,'Statement of Investments'!$E$5:$E$205,0)) -> 2999998 | T23: =S23-F23 -> 0 | U23: =INDEX('Statement of Investments'!$O$5:$O$205,MATCH(B23,'Statement of Investments'!$E$5:$E$205,0)) -> 2999998 | V23: =U23/S23 -> 1 | W23: ABG | X23: GG
B24: Carefam | C24: 45949 | D24: A | E24: Workforce | F24: =2.64*10^6 -> 2640000 | G24: Pitango Ventures | H24: 0.0702 | I24: =37*10^6 -> 37000000 | K24: Carefam | L24: A | M24: 0.0702 | N24: =M24 -> 0.0702 | O24: =I24 -> 37000000 | P24: =IFERROR(ROUND(S24/M24,-5),0) -> 37600000 | Q24: =P24 -> 37600000 | R24: =Q24 -> 37600000 | S24: =F24 -> 2640000 | T24: 0 | U24: =S24 -> 2640000 | V24: =U24/S24 -> 1 | W24: ABG | X24: ABG
A25: x | B25: Helm | C25: 45958 | D25: A | E25: Financial | F25: 3000000 | G25: .406 Ventures, Springtide | H25: =6.66666666666667%+(0.5/45) -> 0.077777778 | I25: =F25/H25 -> 38571429 | K25: =+B25 -> Helm | L25: A | M25: =H25 -> 0.077777778 | N25: 0.1 | O25: =I25 -> 38571429 | P25: =IFERROR(ROUND(S25/M25,-5),0) -> 38600000 | Q25: =45*10^6 -> 45000000 | R25: =45*10^6 -> 45000000 | S25: =F25 -> 3000000 | T25: =S25-F25 -> 0 | U25: =S25 -> 3000000 | V25: =U25/S25 -> 1 | W25: CT | X25: GG
B26: Multiply | D26: A | E26: Financial | F26: 4000000 | G26: SV | H26: =4/120 -> 0.033333333 | I26: =+F26/H26 -> 120000000 | K26: Multiply | L26: A | M26: =H26 -> 0.033333333 | N26: =M26+(4/120) -> 0.066666667 | O26: =I26 -> 120000000 | P26: =IFERROR(ROUND(S26/M26,-5),0) -> 120000000 | Q26: 120000000 | R26: =Q26 -> 120000000 | S26: 4000000 | T26: 0 | U26: =S26 -> 4000000 | V26: =U26/S26 -> 1
B32: Average | F32: =AVERAGE(F4:F31) -> 2733689.7 | H32: =AVERAGE(H4:H31) -> 0.062241445 | I32: =AVERAGE(I4:I31) -> 53582903 | K32: Average | M32: =AVERAGE(M4:M31) -> 0.065002496 | N32: =AVERAGE(N4:N31) -> 0.068895636 | O32: =AVERAGE(O4:O31) -> 53582903 | P32: =AVERAGE(P4:P31) -> 63504348 | Q32: =AVERAGE(Q4:Q31) -> 92014957 | S32: =AVERAGE(S4:S31) -> 3433208.9 | U32: =AVERAGE(U4:U31) -> 4379988.2
B33: Median | F33: =MEDIAN(F4:F31) -> 2999998 | H33: =MEDIAN(H4:H31) -> 0.05999996 | I33: =MEDIAN(I4:I31) -> 44000000 | K33: Median | M33: =MEDIAN(M4:M31) -> 0.066666667 | N33: =MEDIAN(N4:N31) -> 0.066666667 | O33: =MEDIAN(O4:O31) -> 44000000 | P33: =MEDIAN(P4:P31) -> 50200000 | Q33: =MEDIAN(Q4:Q31) -> 50000000 | S33: =MEDIAN(S4:S31) -> 3250000 | U33: =MEDIAN(U4:U31) -> 3250000
B34: Dollar Weighted | H34: =SUMPRODUCT(H$4:H$31,$F$4:$F$31)/SUM($F$4:$F$31) -> 0.062380931 | I34: =SUMPRODUCT(I$4:I$31,$F$4:$F$31)/SUM($F$4:$F$31) -> 67030563 | K34: Dollar Weighted | M34: =SUMPRODUCT(M$4:M$31,$S$4:$S$31)/SUM($S$4:$S$31) -> 0.066479022 | N34: =SUMPRODUCT(N$4:N$31,$S$4:$S$31)/SUM($S$4:$S$31) -> 0.06986057 | O34: =SUMPRODUCT(O$4:O$31,$S$4:$S$31)/SUM($S$4:$S$31) -> 63025460 | P34: =SUMPRODUCT(P$4:P$31,$S$4:$S$31)/SUM($S$4:$S$31) -> 77959336 | Q34: =SUMPRODUCT(Q$4:Q$31,$S$4:$S$31)/SUM($S$4:$S$31) -> 1.1606876e+08
B38: SVA Initial Investment Characteristics | K38: Current Investment Characteristics
B39: Company | C39: Date | D39: Series | E39: Sector | F39: $ Invested | G39: VC Syndicate | H39: FD% | I39: Avg. Cost | K39: Company | L39: Series | M39: FD% | O39: Initital Cost | P39: Avg. Cost | Q39: Last Valuation | R39: Holding Value | S39: $ Invested | T39: Follow -On Investment | U39: Market Value | V39: Multiple | W39: Lead | X39: Allocation | Y39: RTF
B40: Clasp | C40: =INDEX('Statement of Investments'!$C$5:$C$205,MATCH('Investment Characteristics'!$B40,'Statement of Investments'!$B$5:$B$205,0)) -> 45807 | D40: Seed - SVA | E40: Workforce | F40: =INDEX('Statement of Investments'!$L$5:$L$205,MATCH('Investment Characteristics'!$B40,'Statement of Investments'!$B$5:$B$205,0)) -> 250000 | G40: SV | H40: =F40/I40 -> 0.0071428571 | I40: 35000000 | K40: =B40 -> Clasp | L40: Seed | M40: 0.0071428571 | O40: =I40 -> 35000000 | P40: =IFERROR(ROUND(S40/M40,-5),0) -> 35000000 | Q40: =O40 -> 35000000 | R40: =+Q40 -> 35000000 | S40: =INDEX('Statement of Investments'!$L$5:$L$205,MATCH(B40,'Statement of Investments'!$E$5:$E$205,0)) -> 250000 | U40: =INDEX('Statement of Investments'!$O$5:$O$205,MATCH(B40,'Statement of Investments'!$E$5:$E$205,0)) -> 250000 | V40: =U40/S40 -> 1 | X40: CH | Y40: =+$Y$1/M40/10^6 -> 20020
B41: Sunny Health | C41: =INDEX('Statement of Investments'!$C$5:$C$205,MATCH('Investment Characteristics'!$B41,'Statement of Investments'!$B$5:$B$205,0)) -> 45806 | D41: Seed - SVA | E41: Healthtech | F41: =INDEX('Statement of Investments'!$L$5:$L$205,MATCH('Investment Characteristics'!$B41,'Statement of Investments'!$B$5:$B$205,0)) -> 50000 | G41: SV | H41: =F41/I41 -> 0.003125 | I41: 16000000 | K41: =B41 -> Sunny Health | L41: Seed | M41: 0.003125 | O41: =I41 -> 16000000 | P41: =IFERROR(ROUND(S41/M41,-5),0) -> 16000000 | Q41: =O41 -> 16000000 | R41: =+Q41 -> 16000000 | S41: =INDEX('Statement of Investments'!$L$5:$L$205,MATCH(B41,'Statement of Investments'!$E$5:$E$205,0)) -> 50000 | U41: =INDEX('Statement of Investments'!$O$5:$O$205,MATCH(B41,'Statement of Investments'!$E$5:$E$205,0)) -> 50000 | V41: =U41/S41 -> 1 | X41: RP | Y41: =+$Y$1/M41/10^6 -> 45760
B42: Outro Health | C42: =INDEX('Statement of Investments'!$C$5:$C$205,MATCH('Investment Characteristics'!$B42,'Statement of Investments'!$B$5:$B$205,0)) -> 45806 | D42: Seed - SVA | E42: Healthtech | F42: =INDEX('Statement of Investments'!$L$5:$L$205,MATCH('Investment Characteristics'!$B42,'Statement of Investments'!$B$5:$B$205,0)) -> 250000 | G42: SV | H42: =F42/I42 -> 0.025 | I42: 10000000 | K42: =B42 -> Outro Health | L42: Seed | M42: 0.025 | O42: =I42 -> 10000000 | P42: =IFERROR(ROUND(S42/M42,-5),0) -> 10000000 | Q42: =O42 -> 10000000 | R42: =+Q42 -> 10000000 | S42: =INDEX('Statement of Investments'!$L$5:$L$205,MATCH(B42,'Statement of Investments'!$E$5:$E$205,0)) -> 250000 | U42: =INDEX('Statement of Investments'!$O$5:$O$205,MATCH(B42,'Statement of Investments'!$E$5:$E$205,0)) -> 250000 | V42: =U42/S42 -> 1 | X42: ABG | Y42: =+$Y$1/M42/10^6 -> 5720
B43: TrueClaim | C43: =INDEX('Statement of Investments'!$C$5:$C$205,MATCH('Investment Characteristics'!$B43,'Statement of Investments'!$B$5:$B$205,0)) -> 45924 | D43: Seed - SVA | E43: Healthtech | F43: =INDEX('Statement of Investments'!$L$5:$L$205,MATCH('Investment Characteristics'!$B43,'Statement of Investments'!$B$5:$B$205,0)) -> 250000 | G43: SV | H43: =F43/I43 -> 0.010416667 | I43: 24000000 | K43: TrueClaim | L43: Seed | M43: 0.010416667 | O43: =I43 -> 24000000 | P43: =IFERROR(ROUND(S43/M43,-5),0) -> 24000000 | Q43: =O43 -> 24000000 | R43: =+Q43 -> 24000000 | S43: =INDEX('Statement of Investments'!$L$5:$L$205,MATCH(B43,'Statement of Investments'!$E$5:$E$205,0)) -> 250000 | U43: =INDEX('Statement of Investments'!$O$5:$O$205,MATCH(B43,'Statement of Investments'!$E$5:$E$205,0)) -> 250000 | V43: =U43/S43 -> 1 | Y43: =+$Y$1/M43/10^6 -> 13728
B44: Andel | C44: =INDEX('Statement of Investments'!$C$5:$C$205,MATCH('Investment Characteristics'!$B44,'Statement of Investments'!$B$5:$B$205,0)) -> 45924 | D44: Seed - SVA | E44: Healthtech | F44: =INDEX('Statement of Investments'!$L$5:$L$205,MATCH('Investment Characteristics'!$B44,'Statement of Investments'!$B$5:$B$205,0)) -> 250000 | G44: SV | H44: =F44/I44 -> 0.011111111 | I44: 22500000 | K44: Andel | L44: Seed | M44: 0.011111111 | O44: =I44 -> 22500000 | P44: =IFERROR(ROUND(S44/M44,-5),0) -> 22500000 | Q44: =O44 -> 22500000 | R44: =+Q44 -> 22500000 | S44: =INDEX('Statement of Investments'!$L$5:$L$205,MATCH(B44,'Statement of Investments'!$E$5:$E$205,0)) -> 250000 | U44: =INDEX('Statement of Investments'!$O$5:$O$205,MATCH(B44,'Statement of Investments'!$E$5:$E$205,0)) -> 250000 | V44: =U44/S44 -> 1 | Y44: =+$Y$1/M44/10^6 -> 12870
B45: Second Door | C45: =INDEX('Statement of Investments'!$C$5:$C$205,MATCH('Investment Characteristics'!$B45,'Statement of Investments'!$B$5:$B$205,0)) -> 45924 | D45: Seed - SVA | E45: Healthtech | F45: =INDEX('Statement of Investments'!$L$5:$L$205,MATCH('Investment Characteristics'!$B45,'Statement of Investments'!$B$5:$B$205,0)) -> 250000 | G45: SV | H45: =F45/I45 -> 0.017857143 | I45: 14000000 | K45: Second Door | L45: Seed | M45: 0.017857143 | O45: =I45 -> 14000000 | P45: =IFERROR(ROUND(S45/M45,-5),0) -> 14000000 | Q45: =O45 -> 14000000 | R45: =+Q45 -> 14000000 | S45: =INDEX('Statement of Investments'!$L$5:$L$205,MATCH(B45,'Statement of Investments'!$E$5:$E$205,0)) -> 250000 | U45: =INDEX('Statement of Investments'!$O$5:$O$205,MATCH(B45,'Statement of Investments'!$E$5:$E$205,0)) -> 250000 | V45: =U45/S45 -> 1 | Y45: =+$Y$1/M45/10^6 -> 8008
P51: =5/80 -> 0.0625
P52: =1780000/3 -> 593333.33
P53: =4000000/P52 -> 6.741573
...

Sheet Portfolio Construction
D1: =20600000 -> 20600000 | F1: 73000000
D2: Fund I | F2: Fund II | G2: % change
B3: Seed | C3: # of Deals | D3: 14 | F3: ='Investment Characteristics'!C85 -> 11 | G3: =F3/D3-1 -> -0.21428571
C4: % of Portfolio | D4: =D3/$D$30 -> 0.5 | F4: =F3/$F$30 -> 0.47826087 | G4: =F4/D4-1 -> -0.043478261
C5: Avg. Initital Inv. | D5: 258412.48 | F5: ='Investment Characteristics'!C82 -> 1926136 | G5: =F5/D5-1 -> 6.4537266
C6: Inv. % of Fund Size | D6: =D5/$D$1 -> 0.012544295 | F6: =F5/$F$1 -> 0.026385424 | G6: =F6/D6-1 -> 1.1033804
C7: Median FD% | D7: 0.0104 | F7: ='Investment Characteristics'!C94 -> 0.07 | G7: =F7/D7-1 -> 5.7307692
C8: Avg. FD% | D8: 0.014 | F8: ='Investment Characteristics'!C93 -> 0.073582888 | G8: =F8/D8-1 -> 4.2559206
C9: Median Valuation | D9: 16000000 | F9: ='Investment Characteristics'!C91 -> 30000000 | G9: =F9/D9-1 -> 0.875
C10: Avg. Valuation | D10: 16642857 | F10: ='Investment Characteristics'!C90 -> 27772727 | G10: =F10/D10-1 -> 0.66874756
B12: A | C12: # of Deals | D12: 7 | F12: ='Investment Characteristics'!D85 -> 11 | G12: =F12/D12-1 -> 0.57142857
C13: % of Portfolio | D13: =D12/$D$30 -> 0.25 | F13: =F12/$F$30 -> 0.47826087 | G13: =F13/D13-1 -> 0.91304348
C14: Avg. Initital Inv. | D14: 492857.33 | F14: ='Investment Characteristics'!D82 -> 3331817.2 | G14: =F14/D14-1 -> 5.7602064
C15: Inv. % of Fund Size | D15: =D14/D1 -> 0.023925113 | F15: =F14/F1 -> 0.045641332 | G15: =F15/D15-1 -> 0.90767467
C16: Median FD% | D16: 0.0079999296 | F16: ='Investment Characteristics'!D94 -> 0.053333327 | G16: =F16/D16-1 -> 5.6667245
C17: Avg. FD% | D17: 0.0084 | F17: ='Investment Characteristics'!D93 -> 0.053310489 | G17: =F17/D17-1 -> 5.3464868
C18: Median Valuation | D18: 39000000 | F18: ='Investment Characteristics'!D91 -> 53000000 | G18: =F18/D18-1 -> 0.35897436
C19: Avg. Valuation | D19: 62571429 | F19: ='Investment Characteristics'!D90 -> 71446070 | G19: =F19/D19-1 -> 0.14183217
B21: B+ | C21: # of Deals | D21: 7 | F21: ='Investment Characteristics'!E85 -> 1 | G21: =F21/D21-1 -> -0.85714286
C22: % of Portfolio | D22: =D21/$D$30 -> 0.25 | F22: =F21/$F$30 -> 0.043478261 | G22: =F22/D22-1 -> -0.82608696
C23: Avg. Initital Inv. | D23: 611474.83 | F23: ='Investment Characteristics'!E82 -> 5037377 | G23: =F23/D23-1 -> 7.2380775
C24: Inv. % of Fund Size | D24: =D23/D1 -> 0.029683244 | F24: =F23/F1 -> 0.069005164 | G24: =F24/D24-1 -> 1.3247178
C25: Median FD% | D25: 0.004370656 | F25: ='Investment Characteristics'!E94 -> 0.035726078 | G25: =F25/D25-1 -> 7.1740768
C26: Avg. FD% | D26: 0.005 | F26: ='Investment Characteristics'!E93 -> 0.035726078 | G26: =F26/D26-1 -> 6.1452156
C27: Median Valuation | D27: 137000000 | F27: ='Investment Characteristics'!E91 -> 141000000 | G27: =F27/D27-1 -> 0.02919708
C28: Avg. Valuation | D28: 1.4014286e+08 | F28: ='Investment Characteristics'!E90 -> 141000000 | G28: =F28/D28-1 -> 0.006116208
B30: Total | C30: # of Deals | D30: 28 | F30: ='Investment Characteristics'!F85 -> 23 | G30: =F30/D30-1 -> -0.17857143
C31: Avg. Initital Inv. | D31: 405289.28 | F31: ='Investment Characteristics'!F82 -> 2733689.7 | G31: =F31/D31-1 -> 5.7450333
C32: Inv. % of Fund Size | D32: =D31/D1 -> 0.019674237 | F32: =F31/F1 -> 0.037447804 | G32: =F32/D32-1 -> 0.90339295
C33: Median FD% | D33: 0.0071 | F33: ='Investment Characteristics'!H33 -> 0.05999996 | G33: =F33/D33-1 -> 7.4506986
C34: Avg. FD% | D34: 0.0091946146 | F34: ='Investment Characteristics'!H32 -> 0.062241445 | G34: =F34/D34-1 -> 5.769337
C35: Median Valuation | D35: 25500000 | F35: ='Investment Characteristics'!I33 -> 44000000 | G35: =F35/D35-1 -> 0.7254902
C36: Avg. Valuation | D36: 59000000 | F36: ='Investment Characteristics'!I32 -> 53582903 | G36: =F36/D36-1 -> -0.091815203

Sheet Investment Rollover
B2: Cost | H2: Carrying Value
B3: Company | C3: 6/30/2025 | D3: Additions | E3: Dispositions | F3: 9/30/2025 | H3: Company | I3: =C3 -> 6/30/2025 | J3: Additions | K3: Dispositions | L3: Net Writeup | M3: =F3 -> 9/30/2025 | N3: MOIC
B4: Laguna Health | C4: 4999999.7 | D4: =IF(F4>C4,F4-C4,0) -> 0 | E4: =IF(F4<C4,F4-C4,0) -> 0 | F4: =INDEX('Statement of Investments'!$L$5:$L$205,MATCH('Investment Rollover'!$B4,'Statement of Investments'!$E$5:$E$205,0)) -> 4999999.7 | H4: =B4 -> Laguna Health | I4: 4999999.7 | J4: =D4 -> 0 | K4: =E4 -> 0 | L4: =M4-SUM(I4:K4) -> 0 | M4: =INDEX('Statement of Investments'!$O$5:$O$205,MATCH('Investment Rollover'!$H4,'Statement of Investments'!$E$5:$E$205,0)) -> 4999999.7 | N4: =M4/F4 -> 1
B5: Stepful | C5: 7878030.5 | D5: =IF(F5>C5,F5-C5,0) -> 0 | E5: =IF(F5<C5,F5-C5,0) -> 0 | F5: =INDEX('Statement of Investments'!$L$5:$L$205,MATCH('Investment Rollover'!$B5,'Statement of Investments'!$E$5:$E$205,0)) -> 7878030.5 | H5: =B5 -> Stepful | I5: 13609280 | J5: =D5 -> 0 | K5: =E5 -> 0 | L5: =M5-SUM(I5:K5) -> 0 | M5: =INDEX('Statement of Investments'!$O$5:$O$205,MATCH('Investment Rollover'!$H5,'Statement of Investments'!$E$5:$E$205,0)) -> 13609280 | N5: =M5/F5 -> 1.7274977
B6: Summer | C6: 3250000 | D6: =IF(F6>C6,F6-C6,0) -> 0 | E6: =IF(F6<C6,F6-C6,0) -> 0 | F6: =INDEX('Statement of Investments'!$L$5:$L$205,MATCH('Investment Rollover'!$B6,'Statement of Investments'!$E$5:$E$205,0)) -> 3250000 | H6: =B6 -> Summer | I6: 3250000 | J6: =D6 -> 0 | K6: =E6 -> 0 | L6: =M6-SUM(I6:K6) -> 0 | M6: =INDEX('Statement of Investments'!$O$5:$O$205,MATCH('Investment Rollover'!$H6,'Statement of Investments'!$E$5:$E$205,0)) -> 3250000 | N6: =M6/F6 -> 1
B7: Wagmo | C7: 1499998 | D7: =IF(F7>C7,F7-C7,0) -> 0 | E7: =IF(F7<C7,F7-C7,0) -> 0 | F7: =INDEX('Statement of Investments'!$L$5:$L$205,MATCH('Investment Rollover'!$B7,'Statement of Investments'!$E$5:$E$205,0)) -> 1499998 | H7: =B7 -> Wagmo | I7: 1499998 | J7: =D7 -> 0 | K7: =E7 -> 0 | L7: =M7-SUM(I7:K7) -> 0 | M7: =INDEX('Statement of Investments'!$O$5:$O$205,MATCH('Investment Rollover'!$H7,'Statement of Investments'!$E$5:$E$205,0)) -> 1499998 | N7: =M7/F7 -> 1
B8: Kubera | C8: 399999.2 | D8: =IF(F8>C8,F8-C8,0) -> 128083.47 | E8: =IF(F8<C8,F8-C8,0) -> 0 | F8: =INDEX('Statement of Investments'!$L$5:$L$205,MATCH('Investment Rollover'!$B8,'Statement of Investments'!$E$5:$E$205,0)) -> 528082.67 | H8: =B8 -> Kubera | I8: 399999.2 | J8: =D8 -> 128083.47 | K8: =E8 -> 0 | L8: =M8-SUM(I8:K8) -> 483330.52 | M8: =INDEX('Statement of Investments'!$O$5:$O$205,MATCH('Investment Rollover'!$H8,'Statement of Investments'!$E$5:$E$205,0)) -> 1011413.2 | N8: =M8/F8 -> 1.9152554
B9: Salsa | C9: 5499997.9 | D9: =IF(F9>C9,F9-C9,0) -> 0 | E9: =IF(F9<C9,F9-C9,0) -> 0 | F9: =INDEX('Statement of Investments'!$L$5:$L$205,MATCH('Investment Rollover'!$B9,'Statement of Investments'!$E$5:$E$205,0)) -> 5499997.9 | H9: =B9 -> Salsa | I9: 5499997.9 | J9: =D9 -> 0 | K9: =E9 -> 0 | L9: =M9-SUM(I9:K9) -> 412936.17 | M9: =INDEX('Statement of Investments'!$O$5:$O$205,MATCH('Investment Rollover'!$H9,'Statement of Investments'!$E$5:$E$205,0)) -> 5912934 | N9: =M9/F9 -> 1.0750793
