Workbook

Sheet Summary

Sheet Fund Dashboard
B2: SemperVirens Fund I Summary
C3: ="As of "&TEXT('Statement of Investments'!$C$1,"mm/dd/yyyy") -> As of 09/30/2025 | F3: ="As of "&TEXT('Statement of Investments'!$C$1,"mm/dd/yyyy") -> As of 09/30/2025
B5: Fund Capital: | E5: Quarterly Invested Capital:
B6: Committed Capital | C6: 20730000 | E6: New Investments | F6: =SUMIF('Investment Rollover'!$C$4:$C$26,"=0",'Investment Rollover'!$D$4:$D$26) -> 0
B7: Capital Called | C7: =-SUM('Net IRR'!C8:C13) -> 13681800 | E7: Follow-Ons | F7: =SUMIF('Investment Rollover'!$C$4:$C$26,">0",'Investment Rollover'!$D$4:$D$26) -> 252260.58
B8: Percent Called | C8: =C7/C6 -> 0.66 | E8: Total New Investments | F8: =SUM(F6:F7) -> 252260.58
B10: Investment Summary: | E10: Pro-Forma Net Peformance:
B11: Invested Capital | C11: ='Investment Performance Summary'!E47 -> 19553337 | E11: Contributions | F11: =-'Net IRR'!C39 -> 13681800
B12: Total Value | C12: ='Investment Performance Summary'!H47 -> 1.0394943e+08 | E12: Distributions | F12: ='Net IRR'!D39 -> 0
B13: MOIC | C13: =C12/C11 -> 5.3161987 | E13: NAV | F13: ='Net IRR'!F38 -> 90671203
B14: Gross IRR | C14: ='Investment Performance Summary'!J47 -> 0.35434995 | E14: TVPI | F14: =(F13+F12)/F11 -> 6.62714
E15: DPI | F15: =F12/F11 -> 0
E16: Net IRR | F16: ='Net IRR'!F39 -> 0.35763722

Sheet Investment Performance Summary
B2: SemperVirens Fund I Investment Summary
B4: ="As of "&TEXT('Statement of Investments'!$C$1,"mm/dd/yyyy") -> As of 09/30/2025 | C4: Initial Inv. | D4: Initial Exit | E4: Dollars | F4: Unrealized | G4: Realized | H4: Total | I4: Gross | J4: Gross
B5: Company | C5: Date | D5: Date | E5: Invested | F5: Value | G5: Value | H5: Value | I5: Multiple | J5: IRR
B6: Realized Portfolio
B8: Physera | C8: =INDEX('Statement of Investments'!$C$5:$C$204,MATCH('Investment Performance Summary'!$B8,'Statement of Investments'!$B$5:$B$204,0)) -> 43440 | D8: =INDEX('Statement of Investments'!$D$5:$D$204,MATCH('Investment Performance Summary'!$B8,'Statement of Investments'!$B$5:$B$204,0)) -> 43969 | E8: =INDEX('Statement of Investments'!$L$5:$L$204,MATCH($B8,'Statement of Investments'!$E$5:$E$204,0)) -> 208014.11 | F8: 0 | G8: =INDEX('Statement of Investments'!$O$5:$O$204,MATCH($B8,'Statement of Investments'!$E$5:$E$204,0)) -> 366088.28 | H8: =F8+G8 -> 366088.28 | I8: =H8/E8 -> 1.7599205 | J8: =INDEX('Statement of Investments'!$R$5:$R$204,MATCH($B8,'Statement of Investments'!$E$5:$E$204,0)) -> 0.47701722
B9: Fountain - Realized | C9: =INDEX('Statement of Investments'!$C$5:$C$204,MATCH('Investment Performance Summary'!$B9,'Statement of Investments'!$B$5:$B$204,0)) -> 43789 | D9: =INDEX('Statement of Investments'!$D$5:$D$204,MATCH('Investment Performance Summary'!$B9,'Statement of Investments'!$B$5:$B$204,0)) -> 44054 | E9: =INDEX('Statement of Investments'!$L$5:$L$204,MATCH($B9,'Statement of Investments'!$E$5:$E$204,0)) -> 94663.1 | F9: 0 | G9: =INDEX('Statement of Investments'!$O$5:$O$204,MATCH($B9,'Statement of Investments'!$E$5:$E$204,0)) -> 94663.1 | H9: =F9+G9 -> 94663.1 | I9: =H9/E9 -> 1 | J9: =INDEX('Statement of Investments'!$R$5:$R$204,MATCH($B9,'Statement of Investments'!$E$5:$E$204,0)) -> 4.8828125e-09
B10: Sapling | C10: =INDEX('Statement of Investments'!$C$5:$C$204,MATCH('Investment Performance Summary'!$B10,'Statement of Investments'!$B$5:$B$204,0)) -> 43728 | D10: =INDEX('Statement of Investments'!$D$5:$D$204,MATCH('Investment Performance Summary'!$B10,'Statement of Investments'!$B$5:$B$204,0)) -> 44188 | E10: =INDEX('Statement of Investments'!$L$5:$L$204,MATCH($B10,'Statement of Investments'!$E$5:$E$204,0)) -> 129007.89 | F10: 0 | G10: =INDEX('Statement of Investments'!$O$5:$O$204,MATCH($B10,'Statement of Investments'!$E$5:$E$204,0)) -> 203127.39 | H10: =F10+G10 -> 203127.39 | I10: =H10/E10 -> 1.5745346 | J10: =INDEX('Statement of Investments'!$R$5:$R$204,MATCH($B10,'Statement of Investments'!$E$5:$E$204,0)) -> 0.43362643
B11: Alice | C11: =INDEX('Statement of Investments'!$C$5:$C$204,MATCH('Investment Performance Summary'!$B11,'Statement of Investments'!$B$5:$B$204,0)) -> 43705 | D11: =INDEX('Statement of Investments'!$D$5:$D$204,MATCH('Investment Performance Summary'!$B11,'Statement of Investments'!$B$5:$B$204,0)) -> 45008 | E11: =INDEX('Statement of Investments'!$L$5:$L$204,MATCH($B11,'Statement of Investments'!$E$5:$E$204,0)) -> 600000.08 | F11: 0 | G11: =INDEX('Statement of Investments'!$O$5:$O$204,MATCH($B11,'Statement of Investments'!$E$5:$E$204,0)) -> 0 | H11: =F11+G11 -> 0 | I11: =H11/E11 -> 0 | J11: =INDEX('Statement of Investments'!$R$5:$R$204,MATCH($B11,'Statement of Investments'!$E$5:$E$204,0)) -> -1
B12: Pill Club | C12: =INDEX('Statement of Investments'!$C$5:$C$204,MATCH('Investment Performance Summary'!$B12,'Statement of Investments'!$B$5:$B$204,0)) -> 43473 | D12: =INDEX('Statement of Investments'!$D$5:$D$204,MATCH('Investment Performance Summary'!$B12,'Statement of Investments'!$B$5:$B$204,0)) -> 45381 | E12: =INDEX('Statement of Investments'!$L$5:$L$204,MATCH($B12,'Statement of Investments'!$E$5:$E$204,0)) -> 999998.53 | F12: 0 | G12: =INDEX('Statement of Investments'!$O$5:$O$204,MATCH($B12,'Statement of Investments'!$E$5:$E$204,0)) -> 0 | H12: =F12+G12 -> 0 | I12: =H12/E12 -> 0 | J12: =INDEX('Statement of Investments'!$R$5:$R$204,MATCH($B12,'Statement of Investments'!$E$5:$E$204,0)) -> -1
B13: Forage | C13: =INDEX('Statement of Investments'!$C$5:$C$204,MATCH('Investment Performance Summary'!$B13,'Statement of Investments'!$B$5:$B$204,0)) -> 44014 | D13: =INDEX('Statement of Investments'!$D$5:$D$204,MATCH('Investment Performance Summary'!$B13,'Statement of Investments'!$B$5:$B$204,0)) -> 45425 | E13: =INDEX('Statement of Investments'!$L$5:$L$204,MATCH($B13,'Statement of Investments'!$E$5:$E$204,0)) -> 249999.58 | F13: 0 | G13: =INDEX('Statement of Investments'!$O$5:$O$204,MATCH($B13,'Statement of Investments'!$E$5:$E$204,0)) -> 222162.45 | H13: =F13+G13 -> 222162.45 | I13: =H13/E13 -> 0.88865129 | J13: =INDEX('Statement of Investments'!$R$5:$R$204,MATCH($B13,'Statement of Investments'!$E$5:$E$204,0)) -> -0.030075918
B14: Shift | C14: =INDEX('Statement of Investments'!$C$5:$C$204,MATCH('Investment Performance Summary'!$B14,'Statement of Investments'!$B$5:$B$204,0)) -> 43390 | D14: ='Statement of Investments'!D37 -> 45631 | E14: =INDEX('Statement of Investments'!$L$5:$L$204,MATCH($B14,'Statement of Investments'!$E$5:$E$204,0)) -> 223873.41 | F14: 0 | G14: =INDEX('Statement of Investments'!$O$5:$O$204,MATCH($B14,'Statement of Investments'!$E$5:$E$204,0)) -> 8128.52 | H14: =F14+G14 -> 8128.52 | I14: =H14/E14 -> 0.036308555 | J14: =INDEX('Statement of Investments'!$R$5:$R$204,MATCH($B14,'Statement of Investments'!$E$5:$E$204,0)) -> -1
B15: Rula - Realized | C15: =INDEX('Statement of Investments'!$C$5:$C$204,MATCH('Investment Performance Summary'!$B15,'Statement of Investments'!$B$5:$B$204,0)) -> 43719 | D15: =INDEX('Statement of Investments'!$D$5:$D$204,MATCH('Investment Performance Summary'!$B15,'Statement of Investments'!$B$5:$B$204,0)) -> 45611 | E15: =INDEX('Statement of Investments'!$L$5:$L$204,MATCH($B15,'Statement of Investments'!$E$5:$E$204,0)) -> 259445.38 | F15: 0 | G15: =INDEX('Statement of Investments'!$O$5:$O$204,MATCH($B15,'Statement of Investments'!$E$5:$E$204,0)) -> 10236410 | H15: =F15+G15 -> 10236410 | I15: =H15/E15 -> 39.454972 | J15: =INDEX('Statement of Investments'!$R$5:$R$204,MATCH($B15,'Statement of Investments'!$E$5:$E$204,0)) -> 0.96135892
B16: Level | C16: =INDEX('Statement of Investments'!$C$5:$C$204,MATCH('Investment Performance Summary'!$B16,'Statement of Investments'!$B$5:$B$204,0)) -> 04/17/2020 | D16: - | E16: =INDEX('Statement of Investments'!$L$5:$L$204,MATCH($B16,'Statement of Investments'!$E$5:$E$204,0)) -> 1000002.7 | F16: =INDEX('Statement of Investments'!$O$5:$O$204,MATCH($B16,'Statement of Investments'!$E$5:$E$204,0)) -> 0 | G16: 0 | H16: =F16+G16 -> 0 | I16: =H16/E16 -> 0 | J16: =INDEX('Statement of Investments'!$R$5:$R$204,MATCH($B16,'Statement of Investments'!$E$5:$E$204,0)) -> -1
B17: Valence | C17: =INDEX('Statement of Investments'!$C$5:$C$204,MATCH('Investment Performance Summary'!$B17,'Statement of Investments'!$B$5:$B$204,0)) -> 43721 | E17: =INDEX('Statement of Investments'!$L$5:$L$204,MATCH($B17,'Statement of Investments'!$E$5:$E$204,0)) -> 249999.49 | F17: 0 | G17: =INDEX('Statement of Investments'!$O$5:$O$204,MATCH($B17,'Statement of Investments'!$E$5:$E$204,0)) -> 1997507.1 | H17: =F17+G17 -> 1997507.1 | I17: =H17/E17 -> 7.9900445 | J17: =INDEX('Statement of Investments'!$R$5:$R$204,MATCH($B17,'Statement of Investments'!$E$5:$E$204,0)) -> 0.41844098
B18: Total Realized Portfolio | E18: =SUM(E8:E17) -> 4015004.2 | F18: =SUM(F8:F17) -> 0 | G18: =SUM(G8:G17) -> 13128087 | H18: =SUM(H8:H17) -> 13128087 | I18: =H18/E18 -> 3.2697567 | J18: ='Statement of Investments'!R78 -> 0.25423873
B20: Unrealized Portfolio
B22: Spring | C22: =INDEX('Statement of Investments'!$C$5:$C$204,MATCH('Investment Performance Summary'!$B22,'Statement of Investments'!$B$5:$B$204,0)) -> 43244 | D22: - | E22: =INDEX('Statement of Investments'!$L$5:$L$204,MATCH($B22,'Statement of Investments'!$E$5:$E$204,0)) -> 1449990.3 | F22: =INDEX('Statement of Investments'!$O$5:$O$204,MATCH($B22,'Statement of Investments'!$E$5:$E$204,0)) -> 28841289 | G22: 0 | H22: =F22+G22 -> 28841289 | I22: =H22/E22 -> 19.890677 | J22: =INDEX('Statement of Investments'!$R$5:$R$204,MATCH($B22,'Statement of Investments'!$E$5:$E$204,0)) -> 0.68471499
B23: Hone | C23: =INDEX('Statement of Investments'!$C$5:$C$204,MATCH('Investment Performance Summary'!$B23,'Statement of Investments'!$B$5:$B$204,0)) -> 43262 | D23: - | E23: =INDEX('Statement of Investments'!$L$5:$L$204,MATCH($B23,'Statement of Investments'!$E$5:$E$204,0)) -> 682666.27 | F23: =INDEX('Statement of Investments'!$O$5:$O$204,MATCH($B23,'Statement of Investments'!$E$5:$E$204,0)) -> 1756737.3 | G23: 0 | H23: =F23+G23 -> 1756737.3 | I23: =H23/E23 -> 2.5733472 | J23: =INDEX('Statement of Investments'!$R$5:$R$204,MATCH($B23,'Statement of Investments'!$E$5:$E$204,0)) -> 0.19311117
B24: Cleo | C24: =INDEX('Statement of Investments'!$C$5:$C$204,MATCH('Investment Performance Summary'!$B24,'Statement of Investments'!$B$5:$B$204,0)) -> 43328 | D24: - | E24: =INDEX('Statement of Investments'!$L$5:$L$204,MATCH($B24,'Statement of Investments'!$E$5:$E$204,0)) -> 100000 | F24: =INDEX('Statement of Investments'!$O$5:$O$204,MATCH($B24,'Statement of Investments'!$E$5:$E$204,0)) -> 0 | G24: 0 | H24: =F24+G24 -> 0 | I24: =H24/E24 -> 0 | J24: =INDEX('Statement of Investments'!$R$5:$R$204,MATCH($B24,'Statement of Investments'!$E$5:$E$204,0)) -> -1
B25: Carrot | C25: =INDEX('Statement of Investments'!$C$5:$C$204,MATCH('Investment Performance Summary'!$B25,'Statement of Investments'!$B$5:$B$204,0)) -> 43333 | D25: - | E25: =INDEX('Statement of Investments'!$L$5:$L$204,MATCH($B25,'Statement of Investments'!$E$5:$E$204,0)) -> 999996.37 | F25: =INDEX('Statement of Investments'!$O$5:$O$204,MATCH($B25,'Statement of Investments'!$E$5:$E$204,0)) -> 5663568.2 | G25: 0 | H25: =F25+G25 -> 5663568.2 | I25: =H25/E25 -> 5.6635888 | J25: =INDEX('Statement of Investments'!$R$5:$R$204,MATCH($B25,'Statement of Investments'!$E$5:$E$204,0)) -> 0.35356258
B26: Multiverse | C26: =INDEX('Statement of Investments'!$C$5:$C$204,MATCH('Investment Performance Summary'!$B26,'Statement of Investments'!$B$5:$B$204,0)) -> 43395 | D26: - | E26: =INDEX('Statement of Investments'!$L$5:$L$204,MATCH($B26,'Statement of Investments'!$E$5:$E$204,0)) -> 834995.61 | F26: =INDEX('Statement of Investments'!$O$5:$O$204,MATCH($B26,'Statement of Investments'!$E$5:$E$204,0)) -> 9377802.2 | G26: 0 | H26: =F26+G26 -> 9377802.2 | I26: =H26/E26 -> 11.23096 | J26: =INDEX('Statement of Investments'!$R$5:$R$204,MATCH($B26,'Statement of Investments'!$E$5:$E$204,0)) -> 0.54692257
B27: Pelago | C27: =INDEX('Statement of Investments'!$C$5:$C$204,MATCH('Investment Performance Summary'!$B27,'Statement of Investments'!$B$5:$B$204,0)) -> 43558 | D27: - | E27: =INDEX('Statement of Investments'!$L$5:$L$204,MATCH($B27,'Statement of Investments'!$E$5:$E$204,0)) -> 549993.11 | F27: =INDEX('Statement of Investments'!$O$5:$O$204,MATCH($B27,'Statement of Investments'!$E$5:$E$204,0)) -> 4289097.2 | G27: 0 | H27: =F27+G27 -> 4289097.2 | I27: =H27/E27 -> 7.7984561 | J27: =INDEX('Statement of Investments'!$R$5:$R$204,MATCH($B27,'Statement of Investments'!$E$5:$E$204,0)) -> 0.43548993
B28: Karat | C28: =INDEX('Statement of Investments'!$C$5:$C$204,MATCH('Investment Performance Summary'!$B28,'Statement of Investments'!$B$5:$B$204,0)) -> 43592 | D28: - | E28: =INDEX('Statement of Investments'!$L$5:$L$204,MATCH($B28,'Statement of Investments'!$E$5:$E$204,0)) -> 999994.83 | F28: =INDEX('Statement of Investments'!$O$5:$O$204,MATCH($B28,'Statement of Investments'!$E$5:$E$204,0)) -> 999994.83 | G28: 0 | H28: =F28+G28 -> 999994.83 | I28: =H28/E28 -> 1 | J28: =INDEX('Statement of Investments'!$R$5:$R$204,MATCH($B28,'Statement of Investments'!$E$5:$E$204,0)) -> 4.8828125e-09
B29: Omada Health | C29: =INDEX('Statement of Investments'!$C$5:$C$204,MATCH('Investment Performance Summary'!$B29,'Statement of Investments'!$B$5:$B$204,0)) -> 43969 | D29: - | E29: =INDEX('Statement of Investments'!$L$5:$L$204,MATCH($B29,'Statement of Investments'!$E$5:$E$204,0)) -> 291986.05 | F29: =INDEX('Statement of Investments'!$O$5:$O$204,MATCH($B29,'Statement of Investments'!$E$5:$E$204,0)) -> 475335.52 | G29: 0 | H29: =F29+G29 -> 475335.52 | I29: =H29/E29 -> 1.6279391 | J29: =INDEX('Statement of Investments'!$R$5:$R$204,MATCH($B29,'Statement of Investments'!$E$5:$E$204,0)) -> 0.094944517
B30: Hatch | C30: =INDEX('Statement of Investments'!$C$5:$C$204,MATCH('Investment Performance Summary'!$B30,'Statement of Investments'!$B$5:$B$204,0)) -> 43665 | D30: - | E30: =INDEX('Statement of Investments'!$L$5:$L$204,MATCH($B30,'Statement of Investments'!$E$5:$E$204,0)) -> 258903.8 | F30: =INDEX('Statement of Investments'!$O$5:$O$204,MATCH($B30,'Statement of Investments'!$E$5:$E$204,0)) -> 133950.81 | G30: 0 | H30: =F30+G30 -> 133950.81 | I30: =H30/E30 -> 0.51737674 | J30: =INDEX('Statement of Investments'!$R$5:$R$204,MATCH($B30,'Statement of Investments'!$E$5:$E$204,0)) -> 4.8828125e-09
B31: Human Interest | C31: =INDEX('Statement of Investments'!$C$5:$C$204,MATCH('Investment Performance Summary'!$B31,'Statement of Investments'!$B$5:$B$204,0)) -> 43670 | D31: - | E31: =INDEX('Statement of Investments'!$L$5:$L$204,MATCH($B31,'Statement of Investments'!$E$5:$E$204,0)) -> 1090002.1 | F31: =INDEX('Statement of Investments'!$O$5:$O$204,MATCH($B31,'Statement of Investments'!$E$5:$E$204,0)) -> 10743747 | G31: 0 | H31: =F31+G31 -> 10743747 | I31: =H31/E31 -> 9.8566302 | J31: =INDEX('Statement of Investments'!$R$5:$R$204,MATCH($B31,'Statement of Investments'!$E$5:$E$204,0)) -> 0.50923417
B32: Rula | C32: =INDEX('Statement of Investments'!$C$5:$C$204,MATCH('Investment Performance Summary'!$B32,'Statement of Investments'!$B$5:$B$204,0)) -> 0 | D32: - | E32: =INDEX('Statement of Investments'!$L$5:$L$204,MATCH($B32,'Statement of Investments'!$E$5:$E$204,0)) -> 496199.35 | F32: =INDEX('Statement of Investments'!$O$5:$O$204,MATCH($B32,'Statement of Investments'!$E$5:$E$204,0)) -> 6277910.6 | G32: 0 | H32: =F32+G32 -> 6277910.6 | I32: =H32/E32 -> 12.651993 | J32: =INDEX('Statement of Investments'!$R$5:$R$204,MATCH($B32,'Statement of Investments'!$E$5:$E$204,0)) -> 0.74427286
B33: Terminal | C33: =INDEX('Statement of Investments'!$C$5:$C$204,MATCH('Investment Performance Summary'!$B33,'Statement of Investments'!$B$5:$B$204,0)) -> 43727 | D33: - | E33: =INDEX('Statement of Investments'!$L$5:$L$204,MATCH($B33,'Statement of Investments'!$E$5:$E$204,0)) -> 599999.73 | F33: =INDEX('Statement of Investments'!$O$5:$O$204,MATCH($B33,'Statement of Investments'!$E$5:$E$204,0)) -> 0 | G33: 0 | H33: =F33+G33 -> 0 | I33: =H33/E33 -> 0 | J33: =INDEX('Statement of Investments'!$R$5:$R$204,MATCH($B33,'Statement of Investments'!$E$5:$E$204,0)) -> -1
... B43: Ladder | C43: =INDEX('Statement of Investments'!$C$5:$C$204,MATCH('Investment Performance Summary'!$B43,'Statement of Investments'!$B$5:$B$204,0)) -> 43866 | D43: - | E43: =INDEX('Statement of Investments'!$L$5:$L$204,MATCH($B43,'Statement of Investments'!$E$5:$E$204,0)) -> 749994.59 | F43: =INDEX('Statement of Investments'!$O$5:$O$204,MATCH($B43,'Statement of Investments'!$E$5:$E$204,0)) -> 759917.21 | G43: 0 | H43: =F43+G43 -> 759917.21 | I43: =H43/E43 -> 1.0132302 | J43: =INDEX('Statement of Investments'!$R$5:$R$204,MATCH($B43,'Statement of Investments'!$E$5:$E$204,0)) -> 0.0023270166
B45: Total Unrealized Portfolio | E45: =SUM(E22:E44) -> 15538333 | F45: =SUM(F22:F44) -> 90821339 | G45: =SUM(G22:G44) -> 0 | H45: =SUM(H22:H44) -> 90821339 | I45: =H45/E45 -> 5.844986 | J45: ='Statement of Investments'!R202 -> 0.37722788
B47: Total Portfolio | E47: =E45+E18 -> 19553337 | F47: =F45+F18 -> 90821339 | G47: =G45+G18 -> 13128087 | H47: =H45+H18 -> 1.0394943e+08 | I47: =H47/E47 -> 5.3161987 | J47: ='Statement of Investments'!R204 -> 0.35434995
H52: =2*10^6 -> 2000000
H53: =+H52*0.0125 -> 25000

Sheet Warrant Summary
C2: Shift | D2: Pill Club | E2: Digithera | F2: Alice
B3: Overall Status | C3: =INDEX('Warrant Detail'!$C$3:$Y$3,MATCH('Warrant Summary'!C$2,'Warrant Detail'!$C$2:$Y$2,0)) -> 0 | D3: =INDEX('Warrant Detail'!$C$3:$Y$3,MATCH('Warrant Summary'!D$2,'Warrant Detail'!$C$2:$Y$2,0)) -> 0 | E3: =INDEX('Warrant Detail'!$C$3:$Y$3,MATCH('Warrant Summary'!E$2,'Warrant Detail'!$C$2:$Y$2,0)) -> 0.99998984 | F3: =INDEX('Warrant Detail'!$C$3:$Y$3,MATCH('Warrant Summary'!F$2,'Warrant Detail'!$C$2:$Y$2,0)) -> 0
B4: Next Steps | C4: Continue intros, get reporting doc | D4: Set up biweekly meetings | E4: Figure out how to intro more | F4: Get reporting
B5: Owner | C5: =INDEX('Warrant Detail'!$C$4:$Y$4,MATCH('Warrant Summary'!C$2,'Warrant Detail'!$C$2:$Y$2,0)) -> Robby | D5: =INDEX('Warrant Detail'!$C$4:$Y$4,MATCH('Warrant Summary'!D$2,'Warrant Detail'!$C$2:$Y$2,0)) -> Kaleana | E5: =INDEX('Warrant Detail'!$C$4:$Y$4,MATCH('Warrant Summary'!E$2,'Warrant Detail'!$C$2:$Y$2,0)) -> Robby | F5: =INDEX('Warrant Detail'!$C$4:$Y$4,MATCH('Warrant Summary'!F$2,'Warrant Detail'!$C$2:$Y$2,0)) -> Robby/Colin
B6: Reporting | C6: =INDEX('Warrant Detail'!$C$5:$Y$5,MATCH('Warrant Summary'!C$2,'Warrant Detail'!$C$2:$Y$2,0)) -> Montly report from Shift | D6: =INDEX('Warrant Detail'!$C$5:$Y$5,MATCH('Warrant Summary'!D$2,'Warrant Detail'!$C$2:$Y$2,0)) -> Quarterly Basis | E6: =INDEX('Warrant Detail'!$C$5:$Y$5,MATCH('Warrant Summary'!E$2,'Warrant Detail'!$C$2:$Y$2,0)) -> Quarterly Report | F6: =INDEX('Warrant Detail'!$C$5:$Y$5,MATCH('Warrant Summary'!F$2,'Warrant Detail'!$C$2:$Y$2,0)) -> Monthly Report
B7: Deadline | C7: ='Warrant Detail'!C10 -> 44470 | D7: ='Warrant Detail'!G10 -> 44926 | E7: ='Warrant Detail'!K10 -> 47209 | F7: ='Warrant Detail'!O10 -> 44824
B8: Remaining Needed for Trigger | C8: 7 Employers | D8: 15 fully insured employers 20 self-insured employers 90k client employees with 30k women | F8: $1M ARR
C10: Rightway Health | D10: Vetty | E10: Level Dental | F10: InsideSherpa
B11: Overall Status | C11: =INDEX('Warrant Detail'!$C$3:$Y$3,MATCH('Warrant Summary'!C$10,'Warrant Detail'!$C$2:$Y$2,0)) -> #N/A | D11: =INDEX('Warrant Detail'!$C$3:$Y$3,MATCH('Warrant Summary'!D$10,'Warrant Detail'!$C$2:$Y$2,0)) -> 0 | E11: =INDEX('Warrant Detail'!$C$3:$Y$3,MATCH('Warrant Summary'!E$10,'Warrant Detail'!$C$2:$Y$2,0)) -> 0 | F11: =INDEX('Warrant Detail'!$C$3:$AC$3,MATCH('Warrant Summary'!F$10,'Warrant Detail'!$C$2:$AC$2,0)) -> #N/A
B12: Next Steps | C12: Get all Sequoia clients on Rightway | D12: Get reporting | E12: Get reporting, get level funding and FSA | F12: Continue introducing customers
B13: Owner | C13: =INDEX('Warrant Detail'!$C$4:$Y$4,MATCH('Warrant Summary'!C$10,'Warrant Detail'!$C$2:$Y$2,0)) -> #N/A | D13: =INDEX('Warrant Detail'!$C$4:$Y$4,MATCH('Warrant Summary'!D$10,'Warrant Detail'!$C$2:$Y$2,0)) -> Colin | E13: =INDEX('Warrant Detail'!$C$4:$Y$4,MATCH('Warrant Summary'!E$10,'Warrant Detail'!$C$2:$Y$2,0)) -> Greg | F13: =INDEX('Warrant Detail'!$C$4:$AC$4,MATCH('Warrant Summary'!F$10,'Warrant Detail'!$C$2:$AC$2,0)) -> #N/A
B14: Reporting | C14: =INDEX('Warrant Detail'!$C$5:$Y$5,MATCH('Warrant Summary'!C$10,'Warrant Detail'!$C$2:$Y$2,0)) -> #N/A | D14: =INDEX('Warrant Detail'!$C$5:$Y$5,MATCH('Warrant Summary'!D$10,'Warrant Detail'!$C$2:$Y$2,0)) -> Monthly Report | E14: =INDEX('Warrant Detail'!$C$5:$Y$5,MATCH('Warrant Summary'!E$10,'Warrant Detail'!$C$2:$Y$2,0)) -> Quarterly report within 10 business days | F14: =INDEX('Warrant Detail'!$C$5:$AC$5,MATCH('Warrant Summary'!F$10,'Warrant Detail'!$C$2:$AC$2,0)) -> #N/A
B15: Deadline | C15: ='Warrant Detail'!AE10 -> 44470 | D15: ='Warrant Detail'!S10 -> 47484 | E15: ='Warrant Detail'!W10 -> 45292 | F15: ='Warrant Detail'!AA10 -> 44805
B16: Remaining Needed for Trigger | C16: Hit 75k users | D16: $250k ARR | E16: 7,500 enrolled employees | F16: 5 customers

Sheet Supporting Worksheets -->

Sheet Statement of Investments
A1: 45930 | B1: As of | C1: =IF(TODAY()<$A$1,TODAY(),A1) -> 45930
C2: Investment | D2: Liquidity | K2: Original Cost | N2: Current Value | Q2: Gross
C3: Date | D3: Date | F3: Security | G3: Stock Certificate | I3: Shares | K3: Per Share | L3: Total Dollars | N3: Per Share | O3: Total Dollars | Q3: MOIC | R3: IRR
S4: 43101 | T4: -0.1
A5: REALIZED | U5: Commentary
B7: Physera | C7: 43440 | D7: 43969 | F7: Series A Preferred Stock | I7: 128586 | K7: 1.6177042 | L7: =I7*K7 -> 208014.11 | O7: 326186 | S7: =IFERROR(C7,0) -> 43440 | T7: =-L7 -> -208014.11
C8: 43440 | D8: 44426 | F8: Escrow release | K8: 0 | L8: 0 | O8: =39451.47+450.81 -> 39902.28 | S8: =IFERROR(C8,0) -> 43440 | T8: =-L8 -> 0
E10: =B7 -> Physera | F10: Total | I10: =SUM(I7:I9) -> 128586 | K10: =L10/I10 -> 1.6177042 | L10: =SUM(L7:L9) -> 208014.11 | N10: =O10/$I10 -> 2.8470306 | O10: =SUM(O7:O9) -> 366088.28 | Q10: =O10/L10 -> 1.7599205 | R10: =XIRR(T7:T10,S7:S10,0) -> 0.47701722 | S10: =D7 -> 43969 | T10: =O10 -> 366088.28
B12: Fountain - Realized | C12: 43789 | D12: 44054 | F12: Series B Preferred Stock | I12: 13403 | K12: =L12/I12 -> 7.0628292 | L12: 94663.1 | N12: =K12 -> 7.0628292 | O12: =$I12*N12 -> 94663.1 | S12: =IFERROR(C12,0) -> 43789 | T12: =-L12 -> -94663.1
E14: =B12 -> Fountain - Realized | F14: Total | I14: =SUM(I12:I13) -> 13403 | K14: =L14/$I14 -> 7.0628292 | L14: =SUM(L12:L13) -> 94663.1 | N14: =O14/$I14 -> 7.0628292 | O14: =SUM(O12:O13) -> 94663.1 | Q14: =O14/L14 -> 1 | R14: =XIRR(T12:T14,S12:S14,0) -> 4.8828125e-09 | S14: =D12 -> 44054 | T14: =O14 -> 94663.1
B16: Sapling | C16: 43728 | D16: 44188 | F16: Series Seed Extension Preferred Stock | I16: 144159 | K16: 0.8949 | L16: =I16*K16 -> 129007.89 | N16: =O16/I16 -> 1.2483653 | O16: 179963.1 | S16: =IFERROR(C16,0) -> 43728 | T16: =-L16 -> -129007.89
C17: 44813 | D17: 44426 | F17: Escrow release | K17: 0 | L17: 0 | O17: 23164.29 | S17: =IFERROR(C17,0) -> 44813 | T17: =-L17 -> 0
E19: =B16 -> Sapling | F19: Total | I19: =SUM(I16:I18) -> 144159 | K19: 0 | L19: =SUM(L16:L18) -> 129007.89 | N19: 0 | O19: =SUM(O16:O18) -> 203127.39 | Q19: =O19/L19 -> 1.5745346 | R19: =XIRR(T16:T19,S16:S19,0) -> 0.43362643 | S19: =D16 -> 44188 | T19: =O19 -> 203127.39
B21: Alice | C21: 43705 | D21: 45008 | F21: Series A Preferred Stock | G21: PA-8 | I21: 191902 | K21: =+L21/$I$21 -> 3.1265963 | L21: 600000.08 | N21: =+O21/$I$21 -> 0 | O21: 0 | S21: =IFERROR(C21,0) -> 43705 | T21: =-L21 -> -600000.08
F22: Series A Warrants - Expired Sep 2022
E24: =B21 -> Alice | F24: Total | I24: =SUM(I21:I23) -> 191902 | K24: =+L24/$I$24 -> 3.1265963 | L24: =SUM(L21:L23) -> 600000.08 | N24: =+O24/$I$24 -> 0 | O24: =SUM(O21:O23) -> 0 | Q24: =O24/L24 -> 0 | R24: -1 | S24: =D21 -> 45008 | T24: =O24 -> 0
B26: Pill Club | C26: 43473 | D26: 45381 | F26: Series B Preferred Stock | G26: PB-7 | I26: 579911.85 | K26: =L26/I26 -> 1.7243975 | L26: 999998.53 | N26: 2.189 | O26: 0 | S26: =IFERROR(C26,0) -> 43473 | T26: =-L26 -> -999998.53
F27: Series B Warrants
E29: =B26 -> Pill Club | F29: Total | I29: =SUM(I26:I28) -> 579911.85 | K29: =L29/$I29 -> 1.7243975 | L29: =SUM(L26:L28) -> 999998.53 | N29: =O29/$I29 -> 0 | O29: =SUM(O26:O28) -> 0 | Q29: =O29/L29 -> 0 | R29: -1 | S29: =$C$1 -> 45930 | T29: =O29 -> 0
B31: Forage | C31: 44014 | D31: 45425 | F31: Series A Preferred Stock | G31: UPA1-5 | I31: 119119 | K31: =L31/I31 -> 2.0987381 | L31: 249999.58 | N31: =+O31/I31 -> 1.8650463 | O31: 222162.45 | S31: =IFERROR(C31,0) -> 44014 | T31: =-L31 -> -249999.58
F32: Series A Warrants - Expired Sep 2022
E34: =B31 -> Forage | F34: Total | I34: =SUM(I31:I33) -> 119119 | K34: =L34/$I34 -> 2.0987381 | L34: =SUM(L31:L33) -> 249999.58 | N34: =O34/$I34 -> 1.8650463 | O34: =SUM(O31:O33) -> 222162.45 | Q34: =O34/L34 -> 0.88865129 | R34: =XIRR(T31:T34,S31:S34,0) -> -0.030075918 | S34: =D31 -> 45425 | T34: =O34 -> 222162.45
B36: Shift | C36: 43390 | F36: Series Seed Preferred Stock | G36: PS-18 | I36: 151225 | K36: =L36/I36 -> 0.4885 | L36: 73873.412 | N36: =K36 -> 0.4885 | O36: 0 | S36: =IFERROR(C36,0) -> 43390 | T36: =-L36 -> -73873.412
C37: 43450 | D37: 45631 | F37: Convertible Note | G37: CPN-11 | I37: 0 | K37: 0 | L37: 150000 | N37: 0 | O37: 8128.52 | S37: =IFERROR(C37,0) -> 43450 | T37: =-L37 -> -150000
E39: =B36 -> Shift | F39: Total | L39: =SUM(L36:L38) -> 223873.41 | O39: =SUM(O36:O38) -> 8128.52 | Q39: =O39/L39 -> 0.036308555 | R39: -1 | S39: =+D37 -> 45631 | T39: =O39 -> 8128.52
B41: Rula - Realized | C41: 43719 | D41: 45611 | F41: Series Seed Preferred Stock | G41: SS-04 | I41: 386815 | K41: 0.14065434 | L41: =+I41*K41 -> 54407.207 | N41: =+O41/I41 -> 5.7816101 | O41: =2236413.5 -> 2236413.5 | S41: =IFERROR(C41,0) -> 43719 | T41: =-L41 -> -54407.207
C42: 43719 | D42: 45723 | F42: Series Seed Preferred Stock | I42: 1390592 | K42: 0.14065434 | L42: =+I42*K42 -> 195592.79 | N42: =+O42/I42 -> 5.6660177 | O42: 7879118.8 | S42: =IFERROR(C42,0) -> 43719 | T42: =-L42 -> -195592.79 | U42: Q1'25 Secondary Sale
C43: 44265 | D43: 45723 | F43: Series A-1 Preferred Stock | I43: 21334 | K43: 0.44273843 | L43: =+I43*K43 -> 9445.3816 | N43: =+O43/I43 -> 5.6659792 | O43: 120878 | S43: =IFERROR(C43,0) -> 44265 | T43: =-L43 -> -9445.3816 | U43: Q1'25 Secondary Sale
E44: =B41 -> Rula - Realized | F44: Total | I44: =SUM(I41:I43) -> 1798741 | K44: =+L44/$I$141 -> 0.23415627 | L44: =SUM(L41:L43) -> 259445.38 | N44: =+O44/$I$141 -> 9.2386291 | O44: =SUM(O41:O43) -> 10236410 | Q44: =O44/L44 -> 39.454972 | R44: =XIRR(T41:T44,S41:S44,0) -> 0.96135892 | S44: =+D42 -> 45723 | T44: =O44 -> 10236410
B46: Level | C46: 04/17/2020 | D46: 45747 | F46: Series A Preferred Stock | G46: PA-10 | I46: 163613 | K46: =L46/I46 -> 6.112 | L46: 1000002.7 | N46: 0 | O46: =$I46*N46 -> 0 | S46: =IFERROR(C46,0) -> 04/17/2020 | T46: =-L46 -> -1000002.7 | U46: Level Q1 write off
C47: 04/17/2020 | D47: 45747 | F47: Series A Warrants | I47: 163612 | K47: 0 | L47: 0.01
E49: =B46 -> Level | F49: Total | I49: =SUM(I46:I48) -> 327225 | K49: =L49/$I49 -> 3.0560094 | L49: =SUM(L46:L48) -> 1000002.7 | N49: =O49/$I49 -> 0 | O49: =SUM(O46:O48) -> 0 | Q49: =O49/L49 -> 0 | R49: -1 | S49: =$C$1 -> 45930 | T49: =O49 -> 0
B51: Valence | C51: 43721 | F51: Series Seed-3 Preferred Stock | G51: PS3-10 | I51: 214555 | K51: =+L51/#REF! -> #REF! | L51: 249999.49 | N51: 9.31 | O51: =N51*I51 -> 1997507.1 | S51: =IFERROR(C51,0) -> 43721 | T51: =-L51 -> -249999.49 | U51: Q3'25 Secondary Sale
E53: =B51 -> Valence | F53: Total | I53: =SUM(I51:I52) -> 214555 | K53: =+L53/#REF! -> #REF! | L53: =SUM(L51:L52) -> 249999.49 | N53: =+O53/#REF! -> #REF! | O53: =SUM(O51:O52) -> 1997507.1 | Q53: =O53/L53 -> 7.9900445 | R53: =XIRR(T51:T53,S51:S53,) -> 0.41844098 | S53: 45891 | T53: =O53 -> 1997507.1
U77: =O53-L53 -> 1747507.6
B78: Total Realized Portfolio | L78: =SUMIF($F$6:$F$77,"Total",L6:L77) -> 4015004.2 | O78: =SUMIF($F$6:$F$77,"Total",O6:O77) -> 13128087 | Q78: =IFERROR(O78/L78,0) -> 3.2697567 | R78: =XIRR(T7:T77,S7:S77,) -> 0.25423873
A80: UNREALIZED
S81: 43101 | T81: -0.1
B82: Carrot | C82: 43333 | F82: Series A-3 Preferred Stock (SAFE Conversion) | G82: PA3-4 | I82: 114210 | K82: =L82/I82 -> 0.87558007 | L82: 100000 | N82: 9.7426 | O82: =$I82*N82 -> 1112702.3 | S82: =IFERROR(C82,0) -> 43333 | T82: =-L82 -> -100000
C83: 43536 | F83: Series A Preferred Stock | G83: PA-13 | I83: 184604 | K83: =L83/I83 -> 1.6251001 | L83: 299999.97 | N83: =N82 -> 9.7426 | O83: =$I83*N83 -> 1798522.9 | S83: =IFERROR(C83,0) -> 43536 | T83: =-L83 -> -299999.97
...

Sheet Investment Characteristics
V1: =21*10^6 -> 21000000
B2: Initial Investment Characteristics | L2: Current Investment Characteristics
B3: Company | C3: Date | D3: Series | E3: Sector | F3: $ Invested | G3: VC Syndicate | H3: FD% | I3: PFD% | J3: Initial Cost | L3: Company | M3: Series | N3: FD% | O3: Initital Cost | P3: Avg. Cost | Q3: Last Valuation | R3: Holding Value | S3: $ Invested | T3: Market Value | U3: Multiple | W3: 2025E Revenue | X3: Holding Value Implied Mult. | Y3: EV at 10x | Z3: 10x EV> Holding Value | AB3: 44285 | AC3: 44469 | AD3: 44742 | AE3: 44925 | AF3: 45107 | AG3: 45290 | AH3: 45473 | AI3: 45565 | AJ3: 45657 | AK3: 45838 | AL3: 45930 | AM3: Comments | AN3: Runway
B4: Shift | C4: =INDEX('Statement of Investments'!$C$5:$C$204,MATCH('Investment Characteristics'!$B4,'Statement of Investments'!$B$5:$B$204,0)) -> 43390 | D4: Seed | E4: Workforce | F4: =INDEX('Statement of Investments'!$L$5:$L$204,MATCH('Investment Characteristics'!$B4,'Statement of Investments'!$B$5:$B$204,0)) -> 73873.412 | G4: a16z, Expa Capital, Structure Capital | H4: 0.006008 | I4: 0.0113 | J4: =IFERROR(ROUND(F4/H4,-6),0) -> 12000000 | L4: =B4 -> Shift | M4: Seed | N4: 0.0060080358 | O4: =J4 -> 12000000 | P4: =IFERROR(ROUND(S4/N4,-6),0) -> 37000000 | Q4: N/A | R4: N/A | S4: =INDEX('Statement of Investments'!$L$5:$L$204,MATCH('Investment Characteristics'!$L4,'Statement of Investments'!$E$5:$E$204,0)) -> 223873.41 | T4: =INDEX('Statement of Investments'!$O$5:$O$204,MATCH($L4,'Statement of Investments'!$E$5:$E$204,0)) -> 8128.52 | U4: =T4/S4 -> 0.036308555 | V4: =+$V$1/N4/10^6 -> 3495.3187 | AB4: -1 | AC4: -1 | AD4: -1 | AE4: -1 | AF4: -1 | AG4: -1
B5: Carrot | C5: =INDEX('Statement of Investments'!$C$5:$C$204,MATCH('Investment Characteristics'!$B5,'Statement of Investments'!$B$5:$B$204,0)) -> 43333 | D5: Seed | E5: Healthtech | F5: =INDEX('Statement of Investments'!$L$5:$L$204,MATCH('Investment Characteristics'!$B5,'Statement of Investments'!$B$5:$B$204,0)) -> 100000 | G5: USVP, CRV, Precursor Ventures, Maven Ventures, SoftTech, Y Combinator | H5: N/A | I5: N/A | J5: 10000000 | L5: =B5 -> Carrot | M5: D | N5: 0.0094339757 | O5: =J5 -> 10000000 | P5: =IFERROR(ROUND(S5/N5,-6),0) -> 106000000 | Q5: 600000000 | R5: 600000000 | S5: =INDEX('Statement of Investments'!$L$5:$L$204,MATCH('Investment Characteristics'!$L5,'Statement of Investments'!$E$5:$E$204,0)) -> 999996.37 | T5: =INDEX('Statement of Investments'!$O$5:$O$204,MATCH($L5,'Statement of Investments'!$E$5:$E$204,0)) -> 5663568.2 | U5: =T5/S5 -> 5.6635888 | V5: =+$V$1/N5/10^6 -> 2225.9968 | W5: =VLOOKUP(B5,'[1]Fund I RYG'!$B$4:N$23,13,0) -> No FS | AB5: 1 | AC5: 1 | AD5: 1 | AE5: 1 | AF5: 1 | AG5: 1 | AH5: 1 | AI5: 1 | AJ5: 1 | AK5: 1 | AL5: 1 | AM5: Scaling well with significant partnerships helping cover over 17,000 providers nationwide, expanded its U.S provider network significantly: adding ~4,200 new clinics/providers across all 50 states | AN5: -
B6: Cleo | C6: =INDEX('Statement of Investments'!$C$5:$C$204,MATCH('Investment Characteristics'!$B6,'Statement of Investments'!$B$5:$B$204,0)) -> 43328 | D6: A | E6: Healthtech | F6: =INDEX('Statement of Investments'!$L$5:$L$204,MATCH('Investment Characteristics'!$B6,'Statement of Investments'!$B$5:$B$204,0)) -> 100000 | G6: Felicis, Forerunner, Greylock | H6: 0.003 | I6: 0.0062 | J6: =IFERROR(ROUND(F6/H6,-6),0) -> 33000000 | L6: =B6 -> Cleo | M6: C | N6: ='Statement of Investments'!I91/35358112 -> 0.0016734774 | O6: =J6 -> 33000000 | P6: =IFERROR(ROUND(S6/N6,-6),0) -> 60000000 | Q6: =231*10^6 -> 231000000 | R6: 0 | S6: =INDEX('Statement of Investments'!$L$5:$L$204,MATCH('Investment Characteristics'!$L6,'Statement of Investments'!$E$5:$E$204,0)) -> 100000 | T6: =INDEX('Statement of Investments'!$O$5:$O$204,MATCH($L6,'Statement of Investments'!$E$5:$E$204,0)) -> 0 | U6: =T6/S6 -> 0 | V6: =+$V$1/N6/10^6 -> 12548.721 | W6: =VLOOKUP(B6,'[1]Fund I RYG'!$B$4:N$23,13,0) -> No FS | AB6: 1 | AC6: 1 | AD6: 1 | AE6: 0 | AF6: -1 | AG6: 0 | AH6: -1 | AI6: -1 | AJ6: -1 | AK6: -1 | AL6: -1 | AM6: Written off | AN6: -
B7: Hone | C7: =INDEX('Statement of Investments'!$C$5:$C$204,MATCH('Investment Characteristics'!$B7,'Statement of Investments'!$B$5:$B$204,0)) -> 43262 | D7: Seed | E7: Workforce | F7: =('Statement of Investments'!L93+'Statement of Investments'!L94) -> 250000 | G7: F-Prime, Cowboy, Slack Fund, Day One Ventures | H7: N/A | I7: N/A | J7: =8*10^6 -> 8000000 | L7: =B7 -> Hone | M7: B | N7: 0.013943702 | O7: =J7 -> 8000000 | P7: =IFERROR(ROUND(S7/N7,-6),0) -> 49000000 | Q7: 126200000 | R7: 126200000 | S7: =INDEX('Statement of Investments'!$L$5:$L$204,MATCH('Investment Characteristics'!$L7,'Statement of Investments'!$E$5:$E$204,0)) -> 682666.27 | T7: =INDEX('Statement of Investments'!$O$5:$O$204,MATCH($L7,'Statement of Investments'!$E$5:$E$204,0)) -> 1756737.3 | U7: =T7/S7 -> 2.5733472 | V7: =+$V$1/N7/10^6 -> 1506.0563 | W7: =VLOOKUP(B7,'[1]Fund I RYG'!$B$4:N$23,13,0) -> 7921721 | X7: =Q7/W7 -> 15.930882 | Y7: =W7*10 -> 79217210 | Z7: =IF(Y7>Q7,"Yes", "No") -> No | AB7: 1 | AC7: 1 | AD7: 1 | AE7: 1 | AF7: 0 | AG7: 0 | AH7: 0 | AI7: 0 | AJ7: 0 | AK7: 0 | AL7: -1 | AM7: Revenue is flat, opportunity to reinvigorate growth via AI automation? 8 month runway left | AN7: <1 year
B8: Spring | C8: =INDEX('Statement of Investments'!$C$5:$C$204,MATCH('Investment Characteristics'!$B8,'Statement of Investments'!$B$5:$B$204,0)) -> 43244 | D8: Seed | E8: Healthtech | F8: =INDEX('Statement of Investments'!$L$5:$L$204,MATCH('Investment Characteristics'!$B8,'Statement of Investments'!$B$5:$B$204,0)) -> 200000 | G8: Tiger Global, Northzone, RRE Ventures, Saddlefire Ventures | H8: 0.0088877053 | I8: 0.021434587 | J8: =IFERROR(ROUND(F8/H8,-6),0) -> 23000000 | L8: =B8 -> Spring | M8: E | N8: ='Statement of Investments'!I103/48624741 -> 0.0087393576 | O8: =J8 -> 23000000 | P8: =IFERROR(ROUND(S8/N8,-6),0) -> 166000000 | Q8: =3.3*10^9 -> 3300000000 | R8: 3300000000 | S8: =INDEX('Statement of Investments'!$L$5:$L$204,MATCH('Investment Characteristics'!$L8,'Statement of Investments'!$E$5:$E$204,0)) -> 1449990.3 | T8: =INDEX('Statement of Investments'!$O$5:$O$204,MATCH($L8,'Statement of Investments'!$E$5:$E$204,0)) -> 28841289 | U8: =T8/S8 -> 19.890677 | V8: =+$V$1/N8/10^6 -> 2402.9226 | W8: =VLOOKUP(B8,'[1]Fund I RYG'!$B$4:N$23,13,0) -> No FS | AB8: 1 | AC8: 1 | AD8: 1 | AE8: 1 | AF8: 1 | AG8: 1 | AH8: 1 | AI8: 1 | AJ8: 1 | AK8: 1 | AL8: 1 | AM8: Continues to beat plan and is approaching profitability | AN8: Potential IPO Candidate
B9: Multiverse | C9: =INDEX('Statement of Investments'!$C$5:$C$204,MATCH('Investment Characteristics'!$B9,'Statement of Investments'!$B$5:$B$204,0)) -> 43395 | D9: Seed | E9: Workforce | F9: =INDEX('Statement of Investments'!$L$5:$L$204,MATCH('Investment Characteristics'!$B9,'Statement of Investments'!$B$5:$B$204,0)) -> 134999.64 | G9: Index, LSVP, Village Global, General Catalyst | H9: 0.0051 | I9: 0.027396302 | J9: =IFERROR(ROUND(F9/H9,-6),0) -> 26000000 | L9: =B9 -> Multiverse | M9: D | N9: ='Statement of Investments'!I109/31006821 -> 0.0053822028 | O9: =J9 -> 26000000 | P9: =IFERROR(ROUND(S9/N9,-6),0) -> 155000000 | Q9: 1700000000 | R9: 1700000000 | S9: =INDEX('Statement of Investments'!$L$5:$L$204,MATCH('Investment Characteristics'!$L9,'Statement of Investments'!$E$5:$E$204,0)) -> 834995.61 | T9: =INDEX('Statement of Investments'!$O$5:$O$204,MATCH($L9,'Statement of Investments'!$E$5:$E$204,0)) -> 9377802.2 | U9: =T9/S9 -> 11.23096 | V9: =+$V$1/N9/10^6 -> 3901.7482 | W9: =VLOOKUP(B9,'[1]Fund I RYG'!$B$4:N$23,13,0) -> 100000000 | X9: =Q9/W9 -> 17 | Y9: =W9*10 -> 1000000000 | Z9: =IF(Y9>Q9,"Yes", "No") -> No | AB9: 1 | AC9: 1 | AD9: 1 | AE9: 0 | AF9: 0 | AG9: 0 | AH9: 1 | AI9: 1 | AJ9: 1 | AK9: 1 | AL9: 1 | AM9: AI retraining and upskilling providing tailwind, will finish Q4 with just over $70m of bookings, exceeding $62m forecast. Reported revenue was over $100m. Finished the year with Q4 growth YoY at 100%​, GM in Q4 reached 84%, +8pp YoY. Added > 250 new logos to customer list, launched in US, $38M Revenue in Q3 | AN9: 44 months
B10: Physera | C10: 43440 | D10: A | E10: Healthtech | F10: 500000 | G10: Slow Ventures, Blue Cross, Expa Capital, ID Ventures | H10: 0.0102 | I10: 0.021646627 | J10: 25000000 | L10: Physera | M10: Acquired | N10: Acquired | O10: Acquired | P10: Acquired | Q10: Acquired | R10: Acquired | S10: 500000 | T10: =INDEX('Statement of Investments'!$O$5:$O$204,MATCH($L10,'Statement of Investments'!$E$5:$E$204,0))+'Statement of Investments'!O114 -> 841423.8 | U10: =T10/S10 -> 1.6828476 | V10: =+$V$1/N10/10^6 -> #VALUE!
B11: Pill Club | C11: =INDEX('Statement of Investments'!$C$5:$C$204,MATCH('Investment Characteristics'!$B11,'Statement of Investments'!$B$5:$B$204,0)) -> 43473 | D11: B | E11: Healthtech | F11: =INDEX('Statement of Investments'!$L$5:$L$204,MATCH('Investment Characteristics'!$B11,'Statement of Investments'!$B$5:$B$204,0)) -> 999998.53 | G11: GV, Shasta Ventures, 500 Startups, VMG | H11: 0.004 | I11: 0.006 | J11: =IFERROR(ROUND(F11/H11,-6),0) -> 250000000 | L11: =B11 -> Pill Club | M11: N/A | N11: 0.004 | O11: =J11 -> 250000000 | P11: =IFERROR(ROUND(S11/N11,-6),0) -> 250000000 | Q11: 250000000 | R11: N/A | S11: =INDEX('Statement of Investments'!$L$5:$L$204,MATCH('Investment Characteristics'!$L11,'Statement of Investments'!$E$5:$E$204,0)) -> 999998.53 | T11: =INDEX('Statement of Investments'!$O$5:$O$204,MATCH($L11,'Statement of Investments'!$E$5:$E$204,0)) -> 0 | U11: =T11/S11 -> 0 | V11: =+$V$1/N11/10^6 -> 5250 | AB11: -1 | AC11: -1 | AD11: -1 | AE11: -1
B12: Pelago | C12: =INDEX('Statement of Investments'!$C$5:$C$204,MATCH('Investment Characteristics'!$B12,'Statement of Investments'!$B$5:$B$204,0)) -> 43558 | D12: Seed | E12: Healthtech | F12: =INDEX('Statement of Investments'!$L$5:$L$204,MATCH('Investment Characteristics'!$B12,'Statement of Investments'!$B$5:$B$204,0)) -> 300000 | G12: Village Global, EQT Ventures, Pioneer Fund, Y Combinator | H12: N/A | I12: N/A | J12: 18000000 | K12: Digital Therapeutic, Quit Genius | L12: =B12 -> Pelago | M12: C | N12: ='Statement of Investments'!I121/20022002 -> 0.01145385 | O12: =J12 -> 18000000 | P12: =IFERROR(ROUND(S12/N12,-6),0) -> 48000000 | Q12: =365*10^6 -> 365000000 | R12: 365000000 | S12: =INDEX('Statement of Investments'!$L$5:$L$204,MATCH('Investment Characteristics'!$L12,'Statement of Investments'!$E$5:$E$204,0)) -> 549993.11 | T12: =INDEX('Statement of Investments'!$O$5:$O$204,MATCH($L12,'Statement of Investments'!$E$5:$E$204,0)) -> 4289097.2 | U12: =T12/S12 -> 7.7984561 | V12: =+$V$1/N12/10^6 -> 1833.4447 | W12: =VLOOKUP(B12,'[1]Fund I RYG'!$B$4:N$23,13,0) -> 21150000 | X12: =Q12/W12 -> 17.257683 | Y12: =W12*10 -> 211500000 | Z12: =IF(Y12>Q12,"Yes", "No") -> No | AB12: 1 | AC12: 1 | AD12: 1 | AE12: 0 | AF12: 0 | AG12: 1 | AH12: 1 | AI12: 1 | AJ12: 1 | AK12: 1 | AL12: 0 | AM12: Revenue is down slightly, sig decrease in 2025 ARR but forecasted ARR $10M in H1 2026 | AN12: 13 months
B13: Karat | C13: =INDEX('Statement of Investments'!$C$5:$C$204,MATCH('Investment Characteristics'!$B13,'Statement of Investments'!$B$5:$B$204,0)) -> 43592 | D13: B | E13: Workforce | F13: =INDEX('Statement of Investments'!$L$5:$L$204,MATCH('Investment Characteristics'!$B13,'Statement of Investments'!$B$5:$B$204,0)) -> 499998.66 | G13: Tiger Global, Norwest VP, 8VC, Founder Collective | H13: 0.0036231999 | I13: 0.0074791174 | J13: =IFERROR(ROUND(F13/H13,-6),0) -> 138000000 | L13: =B13 -> Karat | M13: C | N13: ='Statement of Investments'!I126/92143512 -> 0.004707841 | O13: =J13 -> 138000000 | P13: =IFERROR(ROUND(S13/N13,-6),0) -> 212000000 | Q13: 1111200000 | R13: Preference Stack - $168M | S13: =INDEX('Statement of Investments'!$L$5:$L$204,MATCH('Investment Characteristics'!$L13,'Statement of Investments'!$E$5:$E$204,0)) -> 999994.83 | T13: =INDEX('Statement of Investments'!$O$5:$O$204,MATCH($L13,'Statement of Investments'!$E$5:$E$204,0)) -> 999994.83 | U13: =T13/S13 -> 1 | V13: =+$V$1/N13/10^6 -> 4460.6435 | W13: =VLOOKUP(B13,'[1]Fund I RYG'!$B$4:N$23,13,0) -> 23560937 | X13: =Q13/W13 -> 47.16281 | Y13: =W13*10 -> 235609370 | Z13: =IF(Y13>Q13,"Yes", "No") -> No | AB13: 1 | AC13: 1 | AD13: 0 | AE13: 0 | AF13: -1 | AG13: -1 | AH13: -1 | AI13: -1 | AJ13: 0 | AK13: 0 | AL13: 0 | AM13: Holding at preference stack, modest growth (1.4x) but 2+ years of runway. | AN13: 24 months
B14: Hatch | C14: =INDEX('Statement of Investments'!$C$5:$C$204,MATCH('Investment Characteristics'!$B14,'Statement of Investments'!$B$5:$B$204,0)) -> 43665 | D14: Seed | E14: Workforce | F14: =INDEX('Statement of Investments'!$L$5:$L$204,MATCH('Investment Characteristics'!$B14,'Statement of Investments'!$B$5:$B$204,0)) -> 258903.8 | G14: N/A | H14: 0.0104337 | I14: N/A | J14: =IFERROR(ROUND(F14/H14,-6),0) -> 25000000 | L14: =B14 -> Hatch | M14: Seed | N14: ='Statement of Investments'!I130/255154 -> 0.0058239338 | O14: =J14 -> 25000000 | P14: =IFERROR(ROUND(S14/N14,-6),0) -> 44000000 | Q14: 25000000 | R14: 25000000 | S14: =INDEX('Statement of Investments'!$L$5:$L$204,MATCH('Investment Characteristics'!$L14,'Statement of Investments'!$E$5:$E$204,0)) -> 258903.8 | T14: =INDEX('Statement of Investments'!$O$5:$O$204,MATCH($L14,'Statement of Investments'!$E$5:$E$204,0)) -> 133950.81 | U14: =T14/S14 -> 0.51737674 | V14: =+$V$1/N14/10^6 -> 3605.8102 | W14: =VLOOKUP(B14,'[1]Fund I RYG'!$B$4:N$23,13,0) -> 2974911 | X14: =Q14/W14 -> 8.4036127 | Y14: =W14*10 -> 29749110 | Z14: =IF(Y14>Q14,"Yes", "No") -> Yes | AB14: -1 | AC14: -1 | AD14: -1 | AE14: -1 | AF14: -1 | AG14: 0 | AH14: -1 | AI14: -1 | AJ14: 0 | AK14: 0 | AL14: -1 | AM14: Strong rev growth, ARR seems stalled ~$1M, not much info
B15: Human Interest | C15: =INDEX('Statement of Investments'!$C$5:$C$204,MATCH('Investment Characteristics'!$B15,'Statement of Investments'!$B$5:$B$204,0)) -> 43670 | D15: B | E15: Financial | F15: =INDEX('Statement of Investments'!$L$5:$L$204,MATCH('Investment Characteristics'!$B15,'Statement of Investments'!$B$5:$B$204,0)) -> 274999.89 | G15: Wing VP, Y Combinator, Softtech, Slow Ventures | H15: 0.007353 | I15: 0.0114 | J15: =IFERROR(ROUND(F15/H15,-6),0) -> 37000000 | L15: =B15 -> Human Interest | M15: D | N15: ='Statement of Investments'!I136/164819311 -> 0.0041973601 | O15: =J15 -> 37000000 | P15: =IFERROR(ROUND(S15/N15,-6),0) -> 260000000 | Q15: 3000000000 | R15: 3000000000 | S15: =INDEX('Statement of Investments'!$L$5:$L$204,MATCH('Investment Characteristics'!$L15,'Statement of Investments'!$E$5:$E$204,0)) -> 1090002.1 | T15: =INDEX('Statement of Investments'!$O$5:$O$204,MATCH($L15,'Statement of Investments'!$E$5:$E$204,0)) -> 10743747 | U15: =T15/S15 -> 9.8566302 | V15: =+$V$1/N15/10^6 -> 5003.1447 | W15: =VLOOKUP(B15,'[1]Fund I RYG'!$B$4:N$23,13,0) -> 144536000 | X15: =Q15/W15 -> 20.756075 | Y15: =W15*10 -> 1445360000 | Z15: =IF(Y15>Q15,"Yes", "No") -> No | AB15: 1 | AC15: 0 | AD15: 0 | AE15: 1 | AF15: 1 | AG15: 1 | AH15: 0 | AI15: 0 | AJ15: 0 | AK15: 0 | AL15: 1 | AM15: Strong revenue growth, working with 37% of all new 401(k) plans. Recent regulatory push to bring alternatives into plans. Q3 ARR at ~$162M
B16: Alice | C16: =INDEX('Statement of Investments'!$C$5:$C$204,MATCH('Investment Characteristics'!$B16,'Statement of Investments'!$B$5:$B$204,0)) -> 43705 | D16: A | E16: Financial | F16: =INDEX('Statement of Investments'!$L$5:$L$204,MATCH('Investment Characteristics'!$B16,'Statement of Investments'!$B$5:$B$204,0)) -> 600000.08 | G16: Trinity Ventures, Bain Capital, Bespoke | H16: 0.013036473 | I16: 0.02402046 | J16: =IFERROR(ROUND(F16/H16,-6),0) -> 46000000 | L16: =B16 -> Alice | M16: N/A | N16: N/A | O16: N/A | P16: N/A | Q16: N/A | R16: N/A | S16: =INDEX('Statement of Investments'!$L$5:$L$204,MATCH('Investment Characteristics'!$L16,'Statement of Investments'!$E$5:$E$204,0)) -> 600000.08 | T16: =INDEX('Statement of Investments'!$O$5:$O$204,MATCH($L16,'Statement of Investments'!$E$5:$E$204,0)) -> 0 | U16: =T16/S16 -> 0 | V16: =+$V$1/N16/10^6 -> #VALUE! | AB16: 0 | AC16: -1 | AD16: -1 | AE16: -1 | AF16: -1 | AG16: -1 | AH16: -1
B17: Rula | C17: =INDEX('Statement of Investments'!$C$5:$C$204,MATCH('Investment Characteristics'!$B17,'Statement of Investments'!$B$5:$B$204,0)) -> 0 | D17: Seed | E17: Healthtech | F17: 250000 | G17: Wing, Upfront VP | H17: 0.0161 | I17: 0.04572245 | J17: =IFERROR(ROUND(F17/H17,-6),0) -> 16000000 | L17: =B17 -> Rula | M17: C | N17: ='Statement of Investments'!I141/210804936 -> 0.0052560487 | O17: =J17 -> 16000000 | P17: =IFERROR(ROUND(S17/N17,-6),0) -> 144000000 | Q17: =1250*10^6 -> 1250000000 | R17: 1250000000 | S17: =INDEX('Statement of Investments'!$L$5:$L$204,MATCH('Investment Characteristics'!$L17,'Statement of Investments'!$E$5:$E$204,0))+'Statement of Investments'!L44 -> 755644.73 | T17: =INDEX('Statement of Investments'!$O$5:$O$204,MATCH($L17,'Statement of Investments'!$E$5:$E$204,0)) -> 6277910.6 | U17: =T17/S17 -> 8.3080188 | V17: =+$V$1/N17/10^6 -> 3995.3968 | W17: =VLOOKUP(B17,'[1]Fund I RYG'!$B$4:N$23,13,0) -> 236000000 | X17: =Q17/W17 -> 5.2966102 | Y17: =W17*10 -> 2360000000 | Z17: =IF(Y17>Q17,"Yes", "No") -> Yes | AB17: 1 | AC17: 1 | AD17: 1 | AE17: 1 | AF17: 1 | AG17: 1 | AH17: 1 | AI17: 1 | AJ17: 1 | AK17: 1 | AL17: 1 | AM17: Forecasting ~2x y/y growth with revenue run rate above $200M by year end
B18: Valence | C18: =INDEX('Statement of Investments'!$C$5:$C$204,MATCH('Investment Characteristics'!$B18,'Statement of Investments'!$B$5:$B$204,0)) -> 43721 | D18: Seed | E18: Workforce | F18: =INDEX('Statement of Investments'!$L$5:$L$204,MATCH('Investment Characteristics'!$B18,'Statement of Investments'!$B$5:$B$204,0)) -> 249999.49 | G18: IVP, Resolute, Magnetico Ventures | H18: 0.0141 | I18: 0.034148284 | J18: =IFERROR(ROUND(F18/H18,-6),0) -> 18000000 | L18: =B18 -> Valence | M18: Realized | N18: 0.0098479775 | O18: =J18 -> 18000000 | P18: =IFERROR(ROUND(S18/N18,-6),0) -> 25000000 | Q18: 265000000 | R18: 265000000 | S18: =INDEX('Statement of Investments'!$L$5:$L$204,MATCH('Investment Characteristics'!$L18,'Statement of Investments'!$E$5:$E$204,0)) -> 249999.49 | T18: =INDEX('Statement of Investments'!$O$5:$O$204,MATCH($L18,'Statement of Investments'!$E$5:$E$204,0)) -> 1997507.1 | U18: =T18/S18 -> 7.9900445 | V18: =+$V$1/N18/10^6 -> 2132.4175 | X18: =Q18/W18 -> #DIV/0! | Y18: =W18*10 -> 0 | Z18: =IF(Y18>Q18,"Yes", "No") -> No | AB18: -1 | AC18: 1 | AD18: 1 | AE18: 2 | AF18: 1 | AG18: 0 | AH18: 0 | AI18: 0 | AJ18: 1 | AK18: 1 | AM18: Fully Realized - Secondary at Series B
B19: Terminal | C19: =INDEX('Statement of Investments'!$C$5:$C$204,MATCH('Investment Characteristics'!$B19,'Statement of Investments'!$B$5:$B$204,0)) -> 43727 | D19: B | E19: Workforce | F19: =INDEX('Statement of Investments'!$L$5:$L$204,MATCH('Investment Characteristics'!$B19,'Statement of Investments'!$B$5:$B$204,0)) -> 599999.73 | G19: KPCB, LSVP, 8VC, Craft Ventures | H19: 0.004370656 | I19: 0.011327246 | J19: =IFERROR(ROUND(F19/H19,-6),0) -> 137000000 | L19: =B19 -> Terminal | M19: B | N19: ='Statement of Investments'!I146/278640874 -> 0.0041771259 | O19: =J19 -> 137000000 | P19: =IFERROR(ROUND(S19/N19,-6),0) -> 144000000 | Q19: 137000000 | R19: 0 | S19: =INDEX('Statement of Investments'!$L$5:$L$204,MATCH('Investment Characteristics'!$L19,'Statement of Investments'!$E$5:$E$204,0)) -> 599999.73 | T19: =INDEX('Statement of Investments'!$O$5:$O$204,MATCH($L19,'Statement of Investments'!$E$5:$E$204,0)) -> 0 | U19: =T19/S19 -> 0 | V19: =+$V$1/N19/10^6 -> 5027.3802 | W19: =VLOOKUP(B19,'[1]Fund I RYG'!$B$4:N$23,13,0) -> 47509757 | X19: =Q19/W19 -> 2.8836182 | Y19: =W19*10 -> 475097570 | Z19: =IF(Y19>Q19,"Yes", "No") -> Yes | AB19: 1 | AC19: 1 | AD19: 0 | AE19: -1 | AF19: -1 | AG19: -1 | AH19: 0 | AI19: 0 | AJ19: -1 | AK19: -1 | AL19: -1 | AM19: Cash flow positive mid-next year, revenue is flat
B20: Sapling | C20: =INDEX('Statement of Investments'!$C$5:$C$204,MATCH('Investment Characteristics'!$B20,'Statement of Investments'!$B$5:$B$204,0)) -> 43728 | D20: Seed | E20: Workforce | F20: 249998.37 | G20: Gradient Ventures, TuesdayVC | H20: 0.015179095 | I20: 0.029675863 | J20: =IFERROR(ROUND(F20/H20,-6),0) -> 16000000 | L20: =B20 -> Sapling | M20: Acquired | N20: Acquired | O20: Acquired | P20: Acquired | Q20: Acquired | R20: Acquired | S20: 249998.37 | T20: =INDEX('Statement of Investments'!$O$5:$O$204,MATCH($L20,'Statement of Investments'!$E$5:$E$204,0))+'Statement of Investments'!O151 -> 324118.28 | U20: =T20/S20 -> 1.2964816 | V20: =+$V$1/N20/10^6 -> #VALUE!
B21: Charthop | C21: =INDEX('Statement of Investments'!$C$5:$C$204,MATCH('Investment Characteristics'!$B21,'Statement of Investments'!$B$5:$B$204,0)) -> 43740 | D21: Seed | E21: Workforce | F21: =INDEX('Statement of Investments'!$L$5:$L$204,MATCH('Investment Characteristics'!$B21,'Statement of Investments'!$B$5:$B$204,0)) -> 100000.6 | G21: a16z, Cowboy, Flybridge | H21: 0.004 | I21: 0.020000121 | J21: =IFERROR(ROUND(F21/H21,-6),0) -> 25000000 | L21: =B21 -> Charthop | M21: C | N21: ='Statement of Investments'!I157/26710961 -> 0.0082354955 | O21: =J21 -> 25000000 | P21: =IFERROR(ROUND(S21/N21,-6),0) -> 146000000 | Q21: 270000000 | R21: Preference Stack - $74M | S21: =INDEX('Statement of Investments'!$L$5:$L$204,MATCH('Investment Characteristics'!$L21,'Statement of Investments'!$E$5:$E$204,0)) -> 1200001.7 | T21: =INDEX('Statement of Investments'!$O$5:$O$204,MATCH($L21,'Statement of Investments'!$E$5:$E$204,0)) -> 1200001.7 | U21: =T21/S21 -> 1 | V21: =+$V$1/N21/10^6 -> 2549.9376 | W21: =VLOOKUP(B21,'[1]Fund I RYG'!$B$4:N$23,13,0) -> 8668373 | X21: =Q21/W21 -> 31.147714 | Y21: =W21*10 -> 86683730 | Z21: =IF(Y21>Q21,"Yes", "No") -> No | AB21: 1 | AC21: 1 | AD21: 0 | AE21: 1 | AF21: 0 | AG21: -1 | AH21: -1 | AI21: -1 | AJ21: -1 | AK21: 0 | AL21: -1 | AM21: Revenue forecast is up ~9%, signed new business with Kraken, ~1.5 yrs of runway, holding at preference stack, forecasting ~12M by end of 2026. ARR up 7% YOY | AN21: 16 months
B22: Rightway Health | C22: =INDEX('Statement of Investments'!$C$5:$C$204,MATCH('Investment Characteristics'!$B22,'Statement of Investments'!$B$5:$B$204,0)) -> 43768 | D22: A | E22: Healthtech | F22: =INDEX('Statement of Investments'!$L$5:$L$204,MATCH('Investment Characteristics'!$B22,'Statement of Investments'!$B$5:$B$204,0)) -> 499999.45 | G22: Khosla Ventures, Tiger Global, Thrive Capital, Rizk Ventures | H22: 0.014478246 | I22: 0.050139539 | J22: =IFERROR(ROUND(F22/H22,-6),0) -> 35000000 | L22: =B22 -> Rightway Health | M22: D | N22: ='Statement of Investments'!I165/29998005 -> 0.022826451 | O22: =J22 -> 35000000 | P22: =IFERROR(ROUND(S22/N22,-6),0) -> 44000000 | Q22: =625*10^6 -> 625000000 | R22: 625000000 | S22: =INDEX('Statement of Investments'!$L$5:$L$204,MATCH('Investment Characteristics'!$L22,'Statement of Investments'!$E$5:$E$204,0)) -> 999998.47 | T22: =INDEX('Statement of Investments'!$O$5:$O$204,MATCH($L22,'Statement of Investments'!$E$5:$E$204,0)) -> 13426663 | U22: =T22/S22 -> 13.426684 | V22: =+$V$1/N22/10^6 -> 919.98532 | W22: =VLOOKUP(B22,'[1]Fund I RYG'!$B$4:N$23,13,0) -> 45000000 | X22: =Q22/W22 -> 13.888889 | Y22: =W22*10 -> 450000000 | Z22: =IF(Y22>Q22,"Yes", "No") -> No | AB22: 1 | AC22: 1 | AD22: 1 | AE22: 0 | AF22: 1 | AG22: 1 | AH22: 1 | AI22: 1 | AJ22: 1 | AK22: 1 | AL22: 1 | AM22: ARR is projected to to grow to $132M or by 60% by H12026. Strong retention and growth metrics | AN22: 36 months
B23: Brightside Benefit | C23: =INDEX('Statement of Investments'!$C$5:$C$204,MATCH('Investment Characteristics'!$B23,'Statement of Investments'!$B$5:$B$204,0)) -> 43775 | D23: A | E23: Financial | F23: =INDEX('Statement of Investments'!$L$5:$L$204,MATCH('Investment Characteristics'!$B23,'Statement of Investments'!$B$5:$B$204,0)) -> 499999.53 | G23: a16z, Comcast Ventures, Trinity Ventures | H23: 0.0037 | I23: 0.0065 | J23: =IFERROR(ROUND(F23/H23,-6),0) -> 135000000 | L23: =B23 -> Brightside Benefit | M23: B | N23: ='Statement of Investments'!I169/200417480 -> 0.0019878805 | O23: =J23 -> 135000000 | P23: =IFERROR(ROUND(S23/N23,-6),0) -> 252000000 | Q23: 195000000 | R23: 195000000 | S23: =INDEX('Statement of Investments'!$L$5:$L$204,MATCH('Investment Characteristics'!$L23,'Statement of Investments'!$E$5:$E$204,0)) -> 499999.53 | T23: =INDEX('Statement of Investments'!$O$5:$O$204,MATCH($L23,'Statement of Investments'!$E$5:$E$204,0)) -> 438844.21 | U23: =T23/S23 -> 0.87768924 | V23: =+$V$1/N23/10^6 -> 10564.015 | W23: =VLOOKUP(B23,'[1]Fund I RYG'!$B$4:N$23,13,0) -> 29602894 | X23: =Q23/W23 -> 6.5871938 | Y23: =W23*10 -> 296028940 | Z23: =IF(Y23>Q23,"Yes", "No") -> Yes | AB23: -1 | AC23: 0 | AD23: 0 | AE23: 1 | AF23: 1 | AG23: 0 | AH23: 0 | AI23: 0 | AJ23: -1 | AK23: 0 | AL23: 0 | AM23: Closed a round and scaled to $30M ARR with major partnerships
B24: Fountain | C24: =INDEX('Statement of Investments'!$C$5:$C$204,MATCH('Investment Characteristics'!$B24,'Statement of Investments'!$B$5:$B$204,0)) -> 43789 | D24: B | E24: Workforce | F24: =INDEX('Statement of Investments'!$L$5:$L$204,MATCH('Investment Characteristics'!$B24,'Statement of Investments'!$B$5:$B$204,0)) -> 405333.72 | G24: Softtech, Crosslink Ventures, Slow Ventures, DCM, Y Combinator | H24: 0.0051 | I24: 0.009029578 | J24: =IFERROR(ROUND(F24/H24,-6),0) -> 79000000 | L24: =B24 -> Fountain | M24: C | N24: 0.0019508497 | O24: =J24 -> 79000000 | P24: =IFERROR(ROUND(S24/N24,-6),0) -> 256000000 | Q24: 860000000 | R24: 860000000 | S24: 499996.82 | T24: =INDEX('Statement of Investments'!$O$5:$O$204,MATCH($L24,'Statement of Investments'!$E$5:$E$204,0))+'Statement of Investments'!O14 -> 1772396.1 | U24: =T24/S24 -> 3.5448147 | V24: =+$V$1/N24/10^6 -> 10764.54 | W24: =VLOOKUP(B24,'[1]Fund I RYG'!$B$4:N$23,13,0) -> 32719597 | X24: =Q24/W24 -> 26.283942 | Y24: =W24*10 -> 327195970 | Z24: =IF(Y24>Q24,"Yes", "No") -> No | AB24: 1 | AC24: 1 | AD24: 1 | AE24: 0 | AF24: 0 | AG24: 0 | AH24: 0 | AI24: 0 | AJ24: 0 | AK24: 0 | AL24: 0 | AM24: Revenue is down, ARR forecasts revised down from ~41M to $34M | AN24: 34 months
B25: XP | C25: =INDEX('Statement of Investments'!$C$5:$C$204,MATCH('Investment Characteristics'!$B25,'Statement of Investments'!$B$5:$B$204,0)) -> 43817 | D25: Seed | E25: Financial | F25: =INDEX('Statement of Investments'!$L$5:$L$204,MATCH('Investment Characteristics'!$B25,'Statement of Investments'!$B$5:$B$204,0)) -> 800000 | G25: Valor Capital, Village Global | H25: N/A | I25: N/A | J25: =12*10^6 -> 12000000 | L25: =B25 -> XP | M25: B | N25: ='Statement of Investments'!I177/24666608 -> 0.016510945 | O25: =J25 -> 12000000 | P25: =IFERROR(ROUND(S25/N25,-6),0) -> 48000000 | Q25: =120000000 -> 120000000 | R25: 120000000 | S25: =INDEX('Statement of Investments'!$L$5:$L$204,MATCH('Investment Characteristics'!$L25,'Statement of Investments'!$E$5:$E$204,0)) -> 800000 | T25: =INDEX('Statement of Investments'!$O$5:$O$204,MATCH($L25,'Statement of Investments'!$E$5:$E$204,0)) -> 1981323 | U25: =T25/S25 -> 2.4766537 | V25: =+$V$1/N25/10^6 -> 1271.8836 | W25: =VLOOKUP(B25,'[1]Fund I RYG'!$B$4:N$23,13,0) -> 12542758 | X25: =Q25/W25 -> 9.5672738 | Y25: =W25*10 -> 125427580 | Z25: =IF(Y25>Q25,"Yes", "No") -> Yes | AB25: 1 | AC25: 0 | AD25: 0 | AE25: 1 | AF25: 1 | AG25: 1 | AH25: 1 | AI25: 1 | AJ25: 1 | AK25: 1 | AL25: 0 | AM25: Slight ARR growth in Q3/25 with the launch of a few smaller clients, followed by material growth in Q4/25 . Based upon the implemented expense reductions, included a substantial reduction of our staff, we expect to reach breakeven without the need for external capital | AN25: -
B26: Enrich | C26: =INDEX('Statement of Investments'!$C$5:$C$204,MATCH('Investment Characteristics'!$B26,'Statement of Investments'!$B$5:$B$204,0)) -> 43829 | D26: Seed | E26: Workforce | F26: =INDEX('Statement of Investments'!$L$5:$L$204,MATCH('Investment Characteristics'!$B26,'Statement of Investments'!$B$5:$B$204,0)) -> 399999.44 | G26: Cowboy Ventures, Bloomberg Beta, Slow Ventures | H26: 0.038095113 | I26: 0.098002278 | J26: =IFERROR(ROUND(F26/H26,-6),0) -> 11000000 | L26: =B26 -> Enrich | M26: Seed | N26: 0.038095113 | O26: =J26 -> 11000000 | P26: =IFERROR(ROUND(S26/N26,-6),0) -> 11000000 | Q26: 11000000 | R26: 0 | S26: =INDEX('Statement of Investments'!$L$5:$L$204,MATCH('Investment Characteristics'!$L26,'Statement of Investments'!$E$5:$E$204,0)) -> 399999.44 | T26: =INDEX('Statement of Investments'!$O$5:$O$204,MATCH($L26,'Statement of Investments'!$E$5:$E$204,0)) -> 0 | U26: =T26/S26 -> 0 | V26: =+$V$1/N26/10^6 -> 551.25181 | W26: =VLOOKUP(B26,'[1]Fund I RYG'!$B$4:N$23,13,0) -> 1038000 | X26: =Q26/W26 -> 10.597303 | Y26: =W26*10 -> 10380000 | Z26: =IF(Y26>Q26,"Yes", "No") -> No | AB26: -1 | AC26: -1 | AD26: -1 | AE26: -1 | AF26: -1 | AG26: -1 | AH26: -1 | AI26: -1 | AJ26: -1 | AK26: -1 | AL26: -1 | AM26: N/A - write-off | AN26: 30 months
B27: Vetty | C27: =INDEX('Statement of Investments'!$C$5:$C$204,MATCH('Investment Characteristics'!$B27,'Statement of Investments'!$B$5:$B$204,0)) -> 43857 | D27: Seed | E27: Workforce | F27: =INDEX('Statement of Investments'!$L$5:$L$204,MATCH('Investment Characteristics'!$B27,'Statement of Investments'!$B$5:$B$204,0)) -> 255034 | G27: Quake Capital, Plug & Play Ventures, Newark Ventures | H27: N/A | I27: N/A | J27: =13*10^6 -> 13000000 | L27: =B27 -> Vetty | M27: A | N27: N/A | O27: =J27 -> 13000000 | P27: =J27 -> 13000000 | Q27: 13000000 | R27: 0 | S27: =INDEX('Statement of Investments'!$L$5:$L$204,MATCH('Investment Characteristics'!$L27,'Statement of Investments'!$E$5:$E$204,0)) -> 255034 | T27: =INDEX('Statement of Investments'!$O$5:$O$204,MATCH($L27,'Statement of Investments'!$E$5:$E$204,0)) -> 0 | U27: =T27/S27 -> 0 | V27: =+$V$1/N27/10^6 -> #VALUE! | W27: =VLOOKUP(B27,'[1]Fund I RYG'!$B$4:N$23,13,0) -> 10707807 | X27: =Q27/W27 -> 1.2140675 | Y27: =W27*10 -> 107078070 | Z27: =IF(Y27>Q27,"Yes", "No") -> Yes | AB27: 0 | AC27: 0 | AD27: 0 | AE27: -1 | AF27: -1 | AG27: -1 | AH27: 0 | AI27: 0 | AJ27: 0 | AK27: -1 | AL27: -1 | AM27: N/A - proactive write-off, ARR revised down from $14M to $12M, 4 months of runway | AN27: 4 months
B28: Ladder | C28: =INDEX('Statement of Investments'!$C$5:$C$204,MATCH('Investment Characteristics'!$B28,'Statement of Investments'!$B$5:$B$204,0)) -> 43866 | D28: C | E28: Financial | F28: =INDEX('Statement of Investments'!$L$5:$L$204,MATCH('Investment Characteristics'!$B28,'Statement of Investments'!$B$5:$B$204,0)) -> 749994.59 | G28: Canaan Partners, LSVP, RRE Ventures | H28: 0.0032007724 | I28: 0.0053509755 | J28: =IFERROR(ROUND(F28/H28,-6),0) -> 234000000 | L28: =B28 -> Ladder | M28: D | N28: 0.0024800544 | O28: =J28 -> 234000000 | P28: =IFERROR(ROUND(S28/N28,-6),0) -> 302000000 | Q28: =330*10^6 -> 330000000 | R28: 330000000 | S28: =INDEX('Statement of Investments'!$L$5:$L$204,MATCH('Investment Characteristics'!$L28,'Statement of Investments'!$E$5:$E$204,0)) -> 749994.59 | T28: =INDEX('Statement of Investments'!$O$5:$O$204,MATCH($L28,'Statement of Investments'!$E$5:$E$204,0)) -> 759917.21 | U28: =T28/S28 -> 1.0132302 | V28: =+$V$1/N28/10^6 -> 8467.5563 | W28: =VLOOKUP(B28,'[1]Fund I RYG'!$B$4:N$23,13,0) -> 52027760 | X28: =Q28/W28 -> 6.3427678 | Y28: =W28*10 -> 520277600 | Z28: =IF(Y28>Q28,"Yes", "No") -> Yes | AB28: 1 | AC28: 1 | AD28: 1 | AE28: 2 | AF28: 0 | AG28: 0 | AH28: 0 | AI28: 0 | AJ28: 0 | AK28: 0 | AL28: 0 | AM28: Recapitalized business, at $50M revenue run rate
