Workbook
Name SummaryCapTableFullyDilutedShares: 'Investment Characteristics'!$D$31

Sheet Fund Dashboard
B2: SemperVirens Fund II Summary
C3: ="As of "&TEXT('Statement of Investments'!$C$1,"mm/dd/yyyy") -> As of 12/31/2025 | F3: ="As of "&TEXT('Statement of Investments'!$C$1,"mm/dd/yyyy") -> As of 12/31/2025
B5: Fund Capital: | E5: Quarterly Invested Capital:
B6: Committed Capital | C6: 20730000 | E6: New Investments | F6: =SUMIF('Investment Rollover'!$C$4:$C$31,"=0",'Investment Rollover'!$D$4:$D$31) -> 0
B7: Capital Called | C7: =-SUM(#REF!) -> #REF! | E7: Follow-Ons | F7: =SUMIF('Investment Rollover'!$C$4:$C$31,">0",'Investment Rollover'!$D$4:$D$31) -> 163902.45
B8: Percent Called | C8: =C7/C6 -> #REF! | E8: Total New Investments | F8: =SUM(F6:F7) -> 163902.45
B10: Investment Summary: | E10: Pro-Forma Net Peformance:
B11: Invested Capital | C11: ='Investment Performance Summary'!E45 -> 67089185 | E11: Contributions | F11: =-#REF! -> #REF!
B12: Total Value | C12: ='Investment Performance Summary'!H45 -> 1.4466024e+08 | E12: Distributions | F12: =#REF! -> #REF!
B13: MOIC | C13: =C12/C11 -> 2.1562379 | E13: NAV | F13: =#REF! -> #REF!
B14: Gross IRR | C14: ='Investment Performance Summary'!J45 -> 0.23819565 | E14: TVPI | F14: =(F13+F12)/F11 -> #REF!
E15: DPI | F15: =F12/F11 -> #REF!
E16: Net IRR | F16: =#REF! -> #REF!

Sheet Investment Performance Summary
B2: SemperVirens Fund II Investment Summary
B4: ="As of "&TEXT('Statement of Investments'!$C$1,"mm/dd/yyyy") -> As of 12/31/2025 | C4: Initial Inv. | D4: Initial Exit | E4: Dollars | F4: Unrealized | G4: Realized | H4: Total | I4: Gross | J4: Gross
B5: Company | C5: Date | D5: Date | E5: Invested | F5: Value | G5: Value | H5: Value | I5: Multiple | J5: IRR
B6: Realized Portfolio
B8: Easop | C8: =INDEX('Statement of Investments'!$C$5:$C$220,MATCH('Investment Performance Summary'!$B8,'Statement of Investments'!$B$5:$B$220,0)) -> 45065 | D8: =INDEX('Statement of Investments'!$D$5:$D$220,MATCH('Investment Performance Summary'!$B8,'Statement of Investments'!$B$5:$B$220,0)) -> 45393 | E8: =INDEX('Statement of Investments'!$L$5:$L$220,MATCH($B8,'Statement of Investments'!$E$5:$E$220,0)) -> 218533.69 | F8: 0 | G8: =INDEX('Statement of Investments'!$O$5:$O$220,MATCH($B8,'Statement of Investments'!$E$5:$E$220,0)) -> 263324.5 | H8: =F8+G8 -> 263324.5 | I8: =H8/E8 -> 1.2049607 | J8: =INDEX('Statement of Investments'!$R$5:$R$220,MATCH($B8,'Statement of Investments'!$E$5:$E$220,0)) -> 0.18573675
B9: Mathison | C9: =INDEX('Statement of Investments'!$C$5:$C$220,MATCH('Investment Performance Summary'!$B9,'Statement of Investments'!$B$5:$B$220,0)) -> 44176 | D9: =INDEX('Statement of Investments'!$D$5:$D$220,MATCH('Investment Performance Summary'!$B9,'Statement of Investments'!$B$5:$B$220,0)) -> 45548 | E9: =INDEX('Statement of Investments'!$L$5:$L$220,MATCH($B9,'Statement of Investments'!$E$5:$E$220,0)) -> 2049994.2 | F9: 0 | G9: =INDEX('Statement of Investments'!$O$5:$O$220,MATCH($B9,'Statement of Investments'!$E$5:$E$220,0)) -> 272298.82 | H9: =F9+G9 -> 272298.82 | I9: =H9/E9 -> 0.13282907 | J9: =INDEX('Statement of Investments'!$R$5:$R$220,MATCH($B9,'Statement of Investments'!$E$5:$E$220,0)) -> -0.38768249
B10: Patch Caregiving | C10: =INDEX('Statement of Investments'!$C$5:$C$220,MATCH('Investment Performance Summary'!$B10,'Statement of Investments'!$B$5:$B$220,0)) -> 44879 | D10: =INDEX('Statement of Investments'!$D$5:$D$220,MATCH('Investment Performance Summary'!$B10,'Statement of Investments'!$B$5:$B$220,0)) -> 45897 | E10: =INDEX('Statement of Investments'!$L$5:$L$220,MATCH($B10,'Statement of Investments'!$E$5:$E$220,0)) -> 88754 | F10: 0 | G10: =INDEX('Statement of Investments'!$O$5:$O$220,MATCH($B10,'Statement of Investments'!$E$5:$E$220,0)) -> 88754 | H10: =F10+G10 -> 88754 | I10: =H10/E10 -> 1 | J10: =INDEX('Statement of Investments'!$R$5:$R$220,MATCH($B10,'Statement of Investments'!$E$5:$E$220,0)) -> 0.26417754
B11: Total Realized Portfolio | E11: =SUM(E6:E10) -> 2357281.9 | F11: =SUM(F6:F10) -> 0 | G11: =SUM(G6:G10) -> 624377.32 | H11: =SUM(H6:H10) -> 624377.32 | I11: =H11/E11 -> 0.26487173 | J11: ='Statement of Investments'!R77 -> -0.29641202
B13: Unrealized Portfolio
B15: Brightline | C15: =INDEX('Statement of Investments'!$C$5:$C$220,MATCH('Investment Performance Summary'!$B15,'Statement of Investments'!$B$5:$B$220,0)) -> 44047 | D15: - | E15: =INDEX('Statement of Investments'!$L$5:$L$220,MATCH($B15,'Statement of Investments'!$E$5:$E$220,0)) -> 1499987 | F15: =INDEX('Statement of Investments'!$O$5:$O$220,MATCH($B15,'Statement of Investments'!$E$5:$E$220,0)) -> 4521963.7 | G15: 0 | H15: =F15+G15 -> 4521963.7 | I15: =H15/E15 -> 3.0146685 | J15: =INDEX('Statement of Investments'!$R$5:$R$220,MATCH($B15,'Statement of Investments'!$E$5:$E$220,0)) -> 0.25233288
B16: Murmur | C16: =INDEX('Statement of Investments'!$C$5:$C$220,MATCH('Investment Performance Summary'!$B16,'Statement of Investments'!$B$5:$B$220,0)) -> 44098 | D16: - | E16: =INDEX('Statement of Investments'!$L$5:$L$220,MATCH($B16,'Statement of Investments'!$E$5:$E$220,0)) -> 1574998 | F16: =INDEX('Statement of Investments'!$O$5:$O$220,MATCH($B16,'Statement of Investments'!$E$5:$E$220,0)) -> 0 | G16: 0 | H16: =F16+G16 -> 0 | I16: =H16/E16 -> 0 | J16: =INDEX('Statement of Investments'!$R$5:$R$220,MATCH($B16,'Statement of Investments'!$E$5:$E$220,0)) -> -1 | K16: x
B17: Pinwheel | C17: =INDEX('Statement of Investments'!$C$5:$C$220,MATCH('Investment Performance Summary'!$B17,'Statement of Investments'!$B$5:$B$220,0)) -> 44105 | D17: - | E17: =INDEX('Statement of Investments'!$L$5:$L$220,MATCH($B17,'Statement of Investments'!$E$5:$E$220,0)) -> 1453156.1 | F17: =INDEX('Statement of Investments'!$O$5:$O$220,MATCH($B17,'Statement of Investments'!$E$5:$E$220,0)) -> 1453156.1 | G17: 0 | H17: =F17+G17 -> 1453156.1 | I17: =H17/E17 -> 1 | J17: =INDEX('Statement of Investments'!$R$5:$R$220,MATCH($B17,'Statement of Investments'!$E$5:$E$220,0)) -> 4.8828125e-09
B18: Cleo | C18: =INDEX('Statement of Investments'!$C$5:$C$220,MATCH('Investment Performance Summary'!$B18,'Statement of Investments'!$B$5:$B$220,0)) -> 44155 | D18: - | E18: =INDEX('Statement of Investments'!$L$5:$L$220,MATCH($B18,'Statement of Investments'!$E$5:$E$220,0)) -> 599997.84 | F18: =INDEX('Statement of Investments'!$O$5:$O$220,MATCH($B18,'Statement of Investments'!$E$5:$E$220,0)) -> 0 | G18: 0 | H18: =F18+G18 -> 0 | I18: =H18/E18 -> 0 | J18: =INDEX('Statement of Investments'!$R$5:$R$220,MATCH($B18,'Statement of Investments'!$E$5:$E$220,0)) -> -1 | K18: x
B19: Rightfoot | C19: =INDEX('Statement of Investments'!$C$5:$C$220,MATCH('Investment Performance Summary'!$B19,'Statement of Investments'!$B$5:$B$220,0)) -> 44175 | D19: - | E19: =INDEX('Statement of Investments'!$L$5:$L$220,MATCH($B19,'Statement of Investments'!$E$5:$E$220,0)) -> 399999.32 | F19: =INDEX('Statement of Investments'!$O$5:$O$220,MATCH($B19,'Statement of Investments'!$E$5:$E$220,0)) -> 0 | G19: 0 | H19: =F19+G19 -> 0 | I19: =H19/E19 -> 0 | J19: -1 | K19: x
B20: Galileo | C20: =INDEX('Statement of Investments'!$C$5:$C$220,MATCH('Investment Performance Summary'!$B20,'Statement of Investments'!$B$5:$B$220,0)) -> 44232 | D20: - | E20: =INDEX('Statement of Investments'!$L$5:$L$220,MATCH($B20,'Statement of Investments'!$E$5:$E$220,0)) -> 2163901.7 | F20: =INDEX('Statement of Investments'!$O$5:$O$220,MATCH($B20,'Statement of Investments'!$E$5:$E$220,0)) -> 1724878.8 | G20: 0 | H20: =F20+G20 -> 1724878.8 | I20: =H20/E20 -> 0.79711515 | J20: =INDEX('Statement of Investments'!$R$5:$R$220,MATCH($B20,'Statement of Investments'!$E$5:$E$220,0)) -> -0.048803942
B21: Cocoon | C21: =INDEX('Statement of Investments'!$C$5:$C$220,MATCH('Investment Performance Summary'!$B21,'Statement of Investments'!$B$5:$B$220,0)) -> 44232 | D21: - | E21: =INDEX('Statement of Investments'!$L$5:$L$220,MATCH($B21,'Statement of Investments'!$E$5:$E$220,0)) -> 4224996.6 | F21: =INDEX('Statement of Investments'!$O$5:$O$220,MATCH($B21,'Statement of Investments'!$E$5:$E$220,0)) -> 4224996.6 | G21: 0 | H21: =F21+G21 -> 4224996.6 | I21: =H21/E21 -> 1 | J21: =INDEX('Statement of Investments'!$R$5:$R$220,MATCH($B21,'Statement of Investments'!$E$5:$E$220,0)) -> 0.31390677
B22: Rula | C22: =INDEX('Statement of Investments'!$C$5:$C$220,MATCH('Investment Performance Summary'!$B22,'Statement of Investments'!$B$5:$B$220,0)) -> 44265 | D22: - | E22: =INDEX('Statement of Investments'!$L$5:$L$220,MATCH($B22,'Statement of Investments'!$E$5:$E$220,0)) -> 4500000 | F22: =INDEX('Statement of Investments'!$O$5:$O$220,MATCH($B22,'Statement of Investments'!$E$5:$E$220,0)) -> 25285301 | G22: 0 | H22: =F22+G22 -> 25285301 | I22: =H22/E22 -> 5.6189558 | J22: =INDEX('Statement of Investments'!$R$5:$R$220,MATCH($B22,'Statement of Investments'!$E$5:$E$220,0)) -> 0.50046626
B23: Origin | C23: =INDEX('Statement of Investments'!$C$5:$C$220,MATCH('Investment Performance Summary'!$B23,'Statement of Investments'!$B$5:$B$220,0)) -> 44307 | D23: - | E23: =INDEX('Statement of Investments'!$L$5:$L$220,MATCH($B23,'Statement of Investments'!$E$5:$E$220,0)) -> 3699992.1 | F23: =INDEX('Statement of Investments'!$O$5:$O$220,MATCH($B23,'Statement of Investments'!$E$5:$E$220,0)) -> 3699992.1 | G23: 0 | H23: =F23+G23 -> 3699992.1 | I23: =H23/E23 -> 1 | J23: =INDEX('Statement of Investments'!$R$5:$R$220,MATCH($B23,'Statement of Investments'!$E$5:$E$220,0)) -> 4.8828125e-09
B24: Nayya | C24: =INDEX('Statement of Investments'!$C$5:$C$220,MATCH('Investment Performance Summary'!$B24,'Statement of Investments'!$B$5:$B$220,0)) -> 44344 | D24: - | E24: =INDEX('Statement of Investments'!$L$5:$L$220,MATCH($B24,'Statement of Investments'!$E$5:$E$220,0)) -> 2699987.1 | F24: =INDEX('Statement of Investments'!$O$5:$O$220,MATCH($B24,'Statement of Investments'!$E$5:$E$220,0)) -> 3853385.4 | G24: 0 | H24: =F24+G24 -> 3853385.4 | I24: =H24/E24 -> 1.4271866 | J24: =INDEX('Statement of Investments'!$R$5:$R$220,MATCH($B24,'Statement of Investments'!$E$5:$E$220,0)) -> 0.09124564
B25: Praisidio | C25: =INDEX('Statement of Investments'!$C$5:$C$220,MATCH('Investment Performance Summary'!$B25,'Statement of Investments'!$B$5:$B$220,0)) -> 44370 | D25: - | E25: =INDEX('Statement of Investments'!$L$5:$L$220,MATCH($B25,'Statement of Investments'!$E$5:$E$220,0)) -> 200000 | F25: =INDEX('Statement of Investments'!$O$5:$O$220,MATCH($B25,'Statement of Investments'!$E$5:$E$220,0)) -> 0 | G25: 0 | H25: =F25+G25 -> 0 | I25: =H25/E25 -> 0 | J25: =INDEX('Statement of Investments'!$R$5:$R$220,MATCH($B25,'Statement of Investments'!$E$5:$E$220,0)) -> -1 | K25: x
B26: Bravely | C26: =INDEX('Statement of Investments'!$C$5:$C$220,MATCH('Investment Performance Summary'!$B26,'Statement of Investments'!$B$5:$B$220,0)) -> 44379 | D26: - | E26: =INDEX('Statement of Investments'!$L$5:$L$220,MATCH($B26,'Statement of Investments'!$E$5:$E$220,0)) -> 1249999.6 | F26: =INDEX('Statement of Investments'!$O$5:$O$220,MATCH($B26,'Statement of Investments'!$E$5:$E$220,0)) -> 1249999.6 | G26: 0 | H26: =F26+G26 -> 1249999.6 | I26: =H26/E26 -> 1 | J26: =INDEX('Statement of Investments'!$R$5:$R$220,MATCH($B26,'Statement of Investments'!$E$5:$E$220,0)) -> 4.8828125e-09
B27: Remote | C27: =INDEX('Statement of Investments'!$C$5:$C$220,MATCH('Investment Performance Summary'!$B27,'Statement of Investments'!$B$5:$B$220,0)) -> 44398 | D27: - | E27: =INDEX('Statement of Investments'!$L$5:$L$220,MATCH($B27,'Statement of Investments'!$E$5:$E$220,0)) -> 4781446 | F27: =INDEX('Statement of Investments'!$O$5:$O$220,MATCH($B27,'Statement of Investments'!$E$5:$E$220,0)) -> 10354762 | G27: 0 | H27: =F27+G27 -> 10354762 | I27: =H27/E27 -> 2.165613 | J27: =INDEX('Statement of Investments'!$R$5:$R$220,MATCH($B27,'Statement of Investments'!$E$5:$E$220,0)) -> 0.20782523
B28: Finch | C28: =INDEX('Statement of Investments'!$C$5:$C$220,MATCH('Investment Performance Summary'!$B28,'Statement of Investments'!$B$5:$B$220,0)) -> 44435 | D28: - | E28: =INDEX('Statement of Investments'!$L$5:$L$220,MATCH($B28,'Statement of Investments'!$E$5:$E$220,0)) -> 500003.42 | F28: =INDEX('Statement of Investments'!$O$5:$O$220,MATCH($B28,'Statement of Investments'!$E$5:$E$220,0)) -> 740862.12 | G28: 0 | H28: =F28+G28 -> 740862.12 | I28: =H28/E28 -> 1.4817141 | J28: =INDEX('Statement of Investments'!$R$5:$R$220,MATCH($B28,'Statement of Investments'!$E$5:$E$220,0)) -> 0.094648638
B29: Midi | C29: =INDEX('Statement of Investments'!$C$5:$C$220,MATCH('Investment Performance Summary'!$B29,'Statement of Investments'!$B$5:$B$220,0)) -> 44455 | D29: - | E29: =INDEX('Statement of Investments'!$L$5:$L$220,MATCH($B29,'Statement of Investments'!$E$5:$E$220,0)) -> 5531507 | F29: =INDEX('Statement of Investments'!$O$5:$O$220,MATCH($B29,'Statement of Investments'!$E$5:$E$220,0)) -> 48185999 | G29: 0 | H29: =F29+G29 -> 48185999 | I29: =H29/E29 -> 8.7111883 | J29: =INDEX('Statement of Investments'!$R$5:$R$220,MATCH($B29,'Statement of Investments'!$E$5:$E$220,0)) -> 0.95959565
B30: ianacare | C30: =INDEX('Statement of Investments'!$C$5:$C$220,MATCH('Investment Performance Summary'!$B30,'Statement of Investments'!$B$5:$B$220,0)) -> 44547 | D30: - | E30: =INDEX('Statement of Investments'!$L$5:$L$220,MATCH($B30,'Statement of Investments'!$E$5:$E$220,0)) -> 2999984.9 | F30: =INDEX('Statement of Investments'!$O$5:$O$220,MATCH($B30,'Statement of Investments'!$E$5:$E$220,0)) -> 2999984.9 | G30: 0 | H30: =F30+G30 -> 2999984.9 | I30: =H30/E30 -> 1 | J30: =INDEX('Statement of Investments'!$R$5:$R$220,MATCH($B30,'Statement of Investments'!$E$5:$E$220,0)) -> 4.8828125e-09
B31: Vivante | C31: =INDEX('Statement of Investments'!$C$5:$C$220,MATCH('Investment Performance Summary'!$B31,'Statement of Investments'!$B$5:$B$220,0)) -> 44552 | D31: - | E31: =INDEX('Statement of Investments'!$L$5:$L$220,MATCH($B31,'Statement of Investments'!$E$5:$E$220,0)) -> 2204142.3 | F31: =INDEX('Statement of Investments'!$O$5:$O$220,MATCH($B31,'Statement of Investments'!$E$5:$E$220,0)) -> 3130662 | G31: 0 | H31: =F31+G31 -> 3130662 | I31: =H31/E31 -> 1.4203538 | J31: =INDEX('Statement of Investments'!$R$5:$R$220,MATCH($B31,'Statement of Investments'!$E$5:$E$220,0)) -> 0.11739947
B32: a.team | C32: =INDEX('Statement of Investments'!$C$5:$C$220,MATCH('Investment Performance Summary'!$B32,'Statement of Investments'!$B$5:$B$220,0)) -> 44567 | D32: - | E32: =INDEX('Statement of Investments'!$L$5:$L$220,MATCH($B32,'Statement of Investments'!$E$5:$E$220,0)) -> 999998.86 | F32: =INDEX('Statement of Investments'!$O$5:$O$220,MATCH($B32,'Statement of Investments'!$E$5:$E$220,0)) -> 999998.86 | G32: 0 | H32: =F32+G32 -> 999998.86 | I32: =H32/E32 -> 1 | J32: =INDEX('Statement of Investments'!$R$5:$R$220,MATCH($B32,'Statement of Investments'!$E$5:$E$220,0)) -> 4.8828125e-09
B33: CoverGo | C33: =INDEX('Statement of Investments'!$C$5:$C$220,MATCH('Investment Performance Summary'!$B33,'Statement of Investments'!$B$5:$B$220,0)) -> 44621 | D33: - | E33: =INDEX('Statement of Investments'!$L$5:$L$220,MATCH($B33,'Statement of Investments'!$E$5:$E$220,0)) -> 4000000 | F33: =INDEX('Statement of Investments'!$O$5:$O$220,MATCH($B33,'Statement of Investments'!$E$5:$E$220,0)) -> 5294506.9 | G33: 0 | H33: =F33+G33 -> 5294506.9 | I33: =H33/E33 -> 1.3236267 | J33: =INDEX('Statement of Investments'!$R$5:$R$220,MATCH($B33,'Statement of Investments'!$E$5:$E$220,0)) -> 0.083919224
B34: Ashby | C34: =INDEX('Statement of Investments'!$C$5:$C$220,MATCH('Investment Performance Summary'!$B34,'Statement of Investments'!$B$5:$B$220,0)) -> 44599 | D34: - | E34: =INDEX('Statement of Investments'!$L$5:$L$220,MATCH($B34,'Statement of Investments'!$E$5:$E$220,0)) -> 5000000 | F34: =INDEX('Statement of Investments'!$O$5:$O$220,MATCH($B34,'Statement of Investments'!$E$5:$E$220,0)) -> 10135319 | G34: 0 | H34: =F34+G34 -> 10135319 | I34: =H34/E34 -> 2.0270638 | J34: =INDEX('Statement of Investments'!$R$5:$R$220,MATCH($B34,'Statement of Investments'!$E$5:$E$220,0)) -> 0.21993771
B35: Delfina | C35: =INDEX('Statement of Investments'!$C$5:$C$220,MATCH('Investment Performance Summary'!$B35,'Statement of Investments'!$B$5:$B$220,0)) -> 44621 | D35: - | E35: =INDEX('Statement of Investments'!$L$5:$L$220,MATCH($B35,'Statement of Investments'!$E$5:$E$220,0)) -> 1549999.9 | F35: =INDEX('Statement of Investments'!$O$5:$O$220,MATCH($B35,'Statement of Investments'!$E$5:$E$220,0)) -> 2097344.6 | G35: 0 | H35: =F35+G35 -> 2097344.6 | I35: =H35/E35 -> 1.3531256 | J35: =INDEX('Statement of Investments'!$R$5:$R$220,MATCH($B35,'Statement of Investments'!$E$5:$E$220,0)) -> 0.11896514
B36: Mosey | C36: =INDEX('Statement of Investments'!$C$5:$C$220,MATCH('Investment Performance Summary'!$B36,'Statement of Investments'!$B$5:$B$220,0)) -> 44707 | D36: - | E36: =INDEX('Statement of Investments'!$L$5:$L$220,MATCH($B36,'Statement of Investments'!$E$5:$E$220,0)) -> 3999998.9 | F36: =INDEX('Statement of Investments'!$O$5:$O$220,MATCH($B36,'Statement of Investments'!$E$5:$E$220,0)) -> 3999998.9 | G36: 0 | H36: =F36+G36 -> 3999998.9 | I36: =H36/E36 -> 1 | J36: =INDEX('Statement of Investments'!$R$5:$R$220,MATCH($B36,'Statement of Investments'!$E$5:$E$220,0)) -> 4.8828125e-09
B37: Violet | C37: =INDEX('Statement of Investments'!$C$5:$C$220,MATCH('Investment Performance Summary'!$B37,'Statement of Investments'!$B$5:$B$220,0)) -> 44722 | D37: - | E37: =INDEX('Statement of Investments'!$L$5:$L$220,MATCH($B37,'Statement of Investments'!$E$5:$E$220,0)) -> 2599995.3 | F37: =INDEX('Statement of Investments'!$O$5:$O$220,MATCH($B37,'Statement of Investments'!$E$5:$E$220,0)) -> 2599995.3 | G37: 0 | H37: =F37+G37 -> 2599995.3 | I37: =H37/E37 -> 1 | J37: =INDEX('Statement of Investments'!$R$5:$R$220,MATCH($B37,'Statement of Investments'!$E$5:$E$220,0)) -> 4.8828125e-09
B38: Gable | C38: =INDEX('Statement of Investments'!$C$5:$C$220,MATCH('Investment Performance Summary'!$B38,'Statement of Investments'!$B$5:$B$220,0)) -> 44848 | D38: - | E38: =INDEX('Statement of Investments'!$L$5:$L$220,MATCH($B38,'Statement of Investments'!$E$5:$E$220,0)) -> 4000000 | F38: =INDEX('Statement of Investments'!$O$5:$O$220,MATCH($B38,'Statement of Investments'!$E$5:$E$220,0)) -> 4000000 | G38: 0 | H38: =F38+G38 -> 4000000 | I38: =H38/E38 -> 1 | J38: =INDEX('Statement of Investments'!$R$5:$R$220,MATCH($B38,'Statement of Investments'!$E$5:$E$220,0)) -> -4.8828125e-09
B39: Patch Caregiving | C39: =INDEX('Statement of Investments'!$C$5:$C$220,MATCH('Investment Performance Summary'!$B39,'Statement of Investments'!$B$5:$B$220,0)) -> 44879 | D39: - | E39: ='Statement of Investments'!L204 -> 411245.85 | F39: ='Statement of Investments'!O204 -> 586415.29 | G39: 0 | H39: =F39+G39 -> 586415.29 | I39: =H39/E39 -> 1.4259482 | J39: =INDEX('Statement of Investments'!$R$5:$R$220,MATCH($B39,'Statement of Investments'!$E$5:$E$220,0)) -> 0.26417754
B40: Formally | C40: =INDEX('Statement of Investments'!$C$5:$C$220,MATCH('Investment Performance Summary'!$B40,'Statement of Investments'!$B$5:$B$220,0)) -> 45006 | D40: - | E40: =INDEX('Statement of Investments'!$L$5:$L$220,MATCH($B40,'Statement of Investments'!$E$5:$E$220,0)) -> 1000000 | F40: =INDEX('Statement of Investments'!$O$5:$O$220,MATCH($B40,'Statement of Investments'!$E$5:$E$220,0)) -> 1000000 | G40: 0 | H40: =F40+G40 -> 1000000 | I40: =H40/E40 -> 1 | J40: =INDEX('Statement of Investments'!$R$5:$R$220,MATCH($B40,'Statement of Investments'!$E$5:$E$220,0)) -> 4.8828125e-09
B41: Liftoff | C41: =INDEX('Statement of Investments'!$C$5:$C$220,MATCH('Investment Performance Summary'!$B41,'Statement of Investments'!$B$5:$B$220,0)) -> 45064 | D41: - | E41: =INDEX('Statement of Investments'!$L$5:$L$220,MATCH($B41,'Statement of Investments'!$E$5:$E$220,0)) -> 886565.66 | F41: =INDEX('Statement of Investments'!$O$5:$O$220,MATCH($B41,'Statement of Investments'!$E$5:$E$220,0)) -> 1896344.2 | G41: 0 | H41: =F41+G41 -> 1896344.2 | I41: =H41/E41 -> 2.1389777 | J41: =INDEX('Statement of Investments'!$R$5:$R$220,MATCH($B41,'Statement of Investments'!$E$5:$E$220,0)) -> 0.42452904
B43: Total Unrealized Portfolio | E43: =SUM(E15:E42) -> 64731903 | F43: =SUM(F15:F42) -> 1.4403587e+08 | G43: =SUM(G15:G42) -> 0 | H43: =SUM(H15:H42) -> 1.4403587e+08 | I43: =H43/E43 -> 2.225114 | J43: ='Statement of Investments'!R218 -> 0.24891897
B45: Total Portfolio | E45: =+E43+E11 -> 67089185 | F45: =+F43+F11 -> 1.4403587e+08 | G45: =+G43+G11 -> 624377.32 | H45: =+H43+H11 -> 1.4466024e+08 | I45: =H45/E45 -> 2.1562379 | J45: ='Statement of Investments'!R220 -> 0.23819565
E49: =E45/73293334 -> 0.9153518 | J49: =SUMIF(K15:K41,"x",E15:E41) -> 2774995.2
J50: =J49/E45 -> 0.041362779

Sheet Supporting Worksheets -->

Sheet Statement of Investments
A1: 46022 | B1: As of | C1: =IF(TODAY()<$A$1,TODAY(),A1) -> 46022
C2: Investment | D2: Liquidity | K2: Original Cost | N2: Current Value | Q2: Gross
C3: Date | D3: Date | F3: Security | G3: Stock Certificates | I3: Shares | K3: Per Share | L3: Total Dollars | N3: Per Share | O3: Total Dollars | Q3: MOIC | R3: IRR
S4: 43101 | T4: -0.1
A5: REALIZED
B7: Easop | C7: 45065 | D7: 45393 | F7: SAFE - Cash proceeds | L7: 218533.69 | O7: =L7 -> 218533.69 | S7: =IFERROR(C7,0) -> 45065 | T7: =-L7 -> -218533.69
C8: 45065 | D8: 45852 | F8: Escrow Cash Proceeds | O8: 44790.81 | S8: =D7 -> 45393 | T8: =O7 -> 218533.69
E9: =B7 -> Easop | F9: Total | L9: =SUM(L7:L8) -> 218533.69 | O9: =SUM(O7:O8) -> 263324.5 | Q9: =O9/L9 -> 1.2049607 | R9: =XIRR(T7:T9,S7:S9,0) -> 0.18573675 | S9: =D8 -> 45852 | T9: =O8 -> 44790.81
B11: Mathison | C11: 44176 | D11: 45548 | F11: Series Seed-2 Preferred Stock | G11: SS2-8 | I11: 329525 | K11: =L11/I11 -> 0.9104 | L11: 299999.56 | N11: 0 | O11: 39848.7 | S11: =IFERROR(C11,0) -> 44176 | T11: =-L11 -> -299999.56
C12: 44470 | D12: 45548 | F12: Series A-1 Preferred Stock | G12: PA-16 | I12: 316902 | K12: =L12/I12 -> 2.3666622 | L12: =0.75*10^6 -> 750000 | N12: 0 | O12: 99621.61 | S12: =IFERROR(C12,0) -> 44470 | T12: =-L12 -> -750000 | U12: Secondary (67,605 shares) | W12: =67605/316902 -> 0.21333094 | X12: =W12*L12 -> 159998.2
D13: 45548 | F13: Common Warrants | I13: 54377 | N13: 0 | O13: =I13*N13 -> 0 | S13: =IFERROR(C13,0) -> 0 | T13: =-L13 -> 0
C14: 44630 | D14: 45548 | F14: Series A Preferred Stock | I14: 338028 | K14: =L14/I14 -> 2.9583189 | L14: 999994.63 | N14: 0 | O14: 132828.51 | S14: =IFERROR(C14,0) -> 44630 | T14: =-L14 -> -999994.63
E16: =B11 -> Mathison | F16: Total | L16: =SUM(L11:L15) -> 2049994.2 | O16: =SUM(O11:O15) -> 272298.82 | Q16: =O16/L16 -> 0.13282907 | R16: =XIRR(T11:T16,S11:S16,-0.1) -> -0.38768249 | S16: =$C$1 -> 46022 | T16: =O16 -> 272298.82
B18: Patch Caregiving | C18: 44879 | D18: 45897 | F18: SAFE - Cash proceeds | L18: 88754 | O18: 88754 | S18: =IFERROR(C18,0) -> 44879 | T18: =-L18 -> -88754 | U18: 675000
S19: =D18 -> 45897 | T19: =O18 -> 88754
B20: (Wellthy Merger) | E20: =B18 -> Patch Caregiving | F20: Total | L20: =SUM(L18:L19) -> 88754 | O20: =SUM(O18:O19) -> 88754 | Q20: =O20/L20 -> 1 | R20: =XIRR(T18:T20,S18:S20,0) -> 0.26417754 | S20: =$C$1 -> 46022 | T20: =O20 -> 88754
B77: Total Realized Portfolio | L77: =SUMIF($F$6:$F$76,"Total",L6:L76) -> 2357281.9 | O77: =SUMIF($F$6:$F$76,"Total",O6:O76) -> 624377.32 | Q77: =IFERROR(O77/L77,0) -> 0.26487173 | R77: =+XIRR(T7:T76,S7:S76,-0.1) -> -0.29641202
A79: UNREALIZED
S80: 43101 | T80: -0.1
B81: Brightline | C81: 44047 | F81: Series A Preferred Stock | G81: PA-3 | I81: =93937*3 -> 281811 | K81: =L81/I81 -> 1.7742333 | L81: 499998.47 | N81: 8.7256 | O81: =$I81*N81 -> 2458970.1 | S81: =IFERROR(C81,0) -> 44047 | T81: =-L81 -> -499998.47
C82: 44333 | F82: Series B Preferred Stock | G82: PB-5 | I82: =78810*3 -> 236430 | K82: =L82/I82 -> 4.2295334 | L82: 999988.57 | N82: =N81 -> 8.7256 | O82: =$I82*N82 -> 2062993.6 | S82: =IFERROR(C82,0) -> 44333 | T82: =-L82 -> -999988.57
E84: =B81 -> Brightline | F84: Total | I84: =I81+I82 -> 518241 | L84: =SUM(L81:L83) -> 1499987 | O84: =SUM(O81:O83) -> 4521963.7 | Q84: =O84/L84 -> 3.0146685 | R84: =XIRR(T81:T84,S81:S84,) -> 0.25233288 | S84: =$C$1 -> 46022 | T84: =O84 -> 4521963.7
B86: Murmur | C86: 44098 | F86: Series Seed Preferred Stock | G86: SSPS-2 | I86: 192884 | K86: =L86/I86 -> 1.1665042 | L86: 225000 | N86: 0 | O86: =$I86*N86 -> 0 | S86: =IFERROR(C86,0) -> 44098 | T86: =-L86 -> -225000
C87: 44406 | F87: Series Seed-1 Preferred Stock | G87: SN-8 | I87: 63431 | K87: =+L87/I87 -> 1.5765162 | L87: 100000 | N87: 0 | O87: =$I87*N87 -> 0 | S87: =IFERROR(C87,0) -> 44406 | T87: =-L87 -> -100000
C88: 44784 | F88: Series Seed-2 Preferred Stock | G88: SN-8 | I88: 589011.99 | K88: =+L88/I88 -> 2.1221945 | L88: 1249998 | N88: 0 | O88: =$I88*N88 -> 0 | S88: =IFERROR(C88,0) -> 44784 | T88: =-L88 -> -1249998
E90: =B86 -> Murmur | F90: Total | I90: =SUM(I86:I88) -> 845326.99 | L90: =SUM(L86:L89) -> 1574998 | O90: =SUM(O86:O89) -> 0 | Q90: =O90/L90 -> 0 | R90: -1 | S90: =$C$1 -> 46022 | T90: =O90 -> 0
B92: Pinwheel | C92: 44105 | F92: Series A Preferred Stock | G92: PA-16 | I92: 118435 | K92: =L92/I92 -> 4.2217 | L92: 499997.04 | N92: =K92 -> 4.2217 | O92: =$I92*N92 -> 499997.04 | S92: =IFERROR(C92,0) -> 44105 | T92: =-L92 -> -499997.04
C93: 44593 | F93: Series B Preferred Stock | G93: PA-16 | I93: 54200 | K93: =L93/I93 -> 17.58596 | L93: 953159.03 | N93: =K93 -> 17.58596 | O93: =$I93*N93 -> 953159.03 | S93: =IFERROR(C93,0) -> 44593 | T93: =-L93 -> -953159.03 | U93: Secondary | X93: =L93 -> 953159.03
E95: =B92 -> Pinwheel | F95: Total | I95: =I92+I93 -> 172635 | L95: =SUM(L92:L94) -> 1453156.1 | O95: =SUM(O92:O94) -> 1453156.1 | Q95: =O95/L95 -> 1 | R95: =XIRR(T92:T95,S92:S95,0) -> 4.8828125e-09 | S95: =$C$1 -> 46022 | T95: =O95 -> 1453156.1
B97: Cleo | C97: 44155 | F97: Series B Preferred Stock | G97: PB-16 | I97: =L97/K97 -> 143061 | K97: 4.194 | L97: 599997.84 | N97: 0 | O97: =I97*N97 -> 0 | S97: =IFERROR(C97,0) -> 44155 | T97: =-L97 -> -599997.84
E99: =B97 -> Cleo | F99: Total | I99: =I97 -> 143061 | L99: =SUM(L97:L98) -> 599997.84 | O99: =SUM(O97:O98) -> 0 | Q99: =O99/L99 -> 0 | R99: -1 | S99: =$C$1 -> 46022 | T99: =O99 -> 0
B101: Rightfoot | C101: 44175 | F101: Series Seed Stock | G101: PS-19 | I101: 372127 | K101: =L101/I101 -> 1.0749 | L101: 399999.32 | N101: 0 | O101: =$I101*N101 -> 0 | S101: =IFERROR(C101,0) -> 44175 | T101: =-L101 -> -399999.32
E103: =B101 -> Rightfoot | F103: Total | I103: =I101 -> 372127 | L103: =SUM(L101:L102) -> 399999.32 | O103: =SUM(O101:O102) -> 0 | Q103: =O103/L103 -> 0 | R103: -1 | S103: =$C$1 -> 46022 | T103: =O103 -> 0
B105: Galileo | C105: 44232 | F105: Series C Preferred Stock | G105: PC-7 | I105: 307749 | K105: =L105/I105 -> 6.4988 | L105: 1999999.2 | N105: =N106 -> 0.45682001 | O105: =$I105*N105 -> 140585.9 | S105: =IFERROR(C105,0) -> 44232 | T105: =-L105 -> -1999999.2
C106: 45849 | F106: Series E-2 Preferred | I106: 358790 | K106: =L106/I106 -> 0.45682001 | L106: 163902.45 | N106: =K106 -> 0.45682001 | O106: =$I106*N106 -> 163902.45 | S106: =IFERROR(C106,0) -> 45849 | T106: =-L106 -> -163902.45 | U106: Warehoused | X106: =L106 -> 163902.45
C107: 45849 | F107: Class A Common Stock Warrants | I107: 3109300 | N107: =N106 -> 0.45682001 | O107: =$I107*N107 -> 1420390.4 | S107: =IFERROR(C107,0) -> 45849 | T107: =-L107 -> 0
E108: =B105 -> Galileo | F108: Total | I108: =SUM(I105:I107) -> 3775839 | L108: =SUM(L105:L106) -> 2163901.7 | O108: =SUM(O105:O107) -> 1724878.8 | Q108: =O108/L108 -> 0.79711515 | R108: =XIRR(T105:T108,S105:S108,0) -> -0.048803942 | S108: =$C$1 -> 46022 | T108: =O108 -> 1724878.8
B110: Cocoon | C110: 44232 | F110: Series Seed Preferred Stock | G110: PS1-2 | I110: 260145 | K110: =L110/I110 -> 0.86490004 | L110: 224999.42 | N110: =+K110 -> 0.86490004 | O110: =$I110*N110 -> 224999.42 | S110: =IFERROR(C110,0) -> 44232 | T110: =-L110 -> -224999.42
C111: 44399 | F111: Series A Preferred Stock | G111: PA-6 | I111: 251971 | K111: =L111/I111 -> 3.9687 | L111: 999997.31 | N111: =+K111 -> 3.9687 | O111: =$I111*N111 -> 999997.31 | S111: =IFERROR(C111,0) -> 44399 | T111: =-L111 -> -999997.31
C112: 44862 | F112: Series A Preferred Stock | I112: =L112/K112 -> 755915 | K112: =N111 -> 3.9687 | L112: 2999999.9 | N112: =+K112 -> 3.9687 | O112: =$I112*N112 -> 2999999.9
...

Sheet Portfolio Construction
D1: =20600000 -> 20600000 | F1: 73000000
D2: Fund I | F2: Fund II | G2: % change
B3: Seed | C3: # of Deals | D3: 14 | F3: ='Investment Characteristics'!C72 -> 12 | G3: =F3/D3-1 -> -0.14285714
C4: % of Portfolio | D4: =D3/$D$30 -> 0.5 | F4: =F3/$F$30 -> 0.4137931 | G4: =F4/D4-1 -> -0.17241379
C5: Avg. Initital Inv. | D5: 258412.48 | F5: ='Investment Characteristics'!C69 -> 688344.2 | G5: =F5/D5-1 -> 1.6637421
C6: Inv. % of Fund Size | D6: =D5/$D$1 -> 0.012544295 | F6: =F5/$F$1 -> 0.0094293726 | G6: =F6/D6-1 -> -0.24831388
C7: Median FD% | D7: 0.0104 | F7: ='Investment Characteristics'!C81 -> 0.045 | G7: =F7/D7-1 -> 3.3269231
C8: Avg. FD% | D8: 0.014 | F8: ='Investment Characteristics'!C80 -> 0.043795119 | G8: =F8/D8-1 -> 2.1282228
C9: Median Valuation | D9: 16000000 | F9: ='Investment Characteristics'!C78 -> 15000000 | G9: =F9/D9-1 -> -0.0625
C10: Avg. Valuation | D10: 16642857 | F10: ='Investment Characteristics'!C77 -> 16583333 | G10: =F10/D10-1 -> -0.0035765379
B12: A | C12: # of Deals | D12: 7 | F12: ='Investment Characteristics'!D72 -> 12 | G12: =F12/D12-1 -> 0.71428571
C13: % of Portfolio | D13: =D12/$D$30 -> 0.25 | F13: =F12/$F$30 -> 0.4137931 | G13: =F13/D13-1 -> 0.65517241
C14: Avg. Initital Inv. | D14: 492857.33 | F14: ='Investment Characteristics'!D69 -> 1579164.8 | G14: =F14/D14-1 -> 2.2041012
C15: Inv. % of Fund Size | D15: =D14/D1 -> 0.023925113 | F15: =F14/F1 -> 0.021632394 | G15: =F15/D15-1 -> -0.095828969
C16: Median FD% | D16: 0.0079999296 | F16: ='Investment Characteristics'!D81 -> 0.017592499 | G16: =F16/D16-1 -> 1.1990817
C17: Avg. FD% | D17: 0.0084 | F17: ='Investment Characteristics'!D80 -> 0.02963664 | G17: =F17/D17-1 -> 2.5281714
C18: Median Valuation | D18: 39000000 | F18: ='Investment Characteristics'!D78 -> 73750000 | G18: =F18/D18-1 -> 0.89102564
C19: Avg. Valuation | D19: 62571429 | F19: ='Investment Characteristics'!D77 -> 94866667 | G19: =F19/D19-1 -> 0.51613394
B21: B+ | C21: # of Deals | D21: 7 | F21: ='Investment Characteristics'!E72 -> 5 | G21: =F21/D21-1 -> -0.28571429
C22: % of Portfolio | D22: =D21/$D$30 -> 0.25 | F22: =F21/$F$30 -> 0.17241379 | G22: =F22/D22-1 -> -0.31034483
C23: Avg. Initital Inv. | D23: 611474.83 | F23: ='Investment Characteristics'!E69 -> 2019995.3 | G23: =F23/D23-1 -> 2.3034808
C24: Inv. % of Fund Size | D24: =D23/D1 -> 0.029683244 | F24: =F23/F1 -> 0.027671169 | G24: =F24/D24-1 -> -0.067784875
C25: Median FD% | D25: 0.004370656 | F25: ='Investment Characteristics'!E81 -> 0.0050633027 | G25: =F25/D25-1 -> 0.15847659
C26: Avg. FD% | D26: 0.005 | F26: ='Investment Characteristics'!E80 -> 0.0067194849 | G26: =F26/D26-1 -> 0.34389697
C27: Median Valuation | D27: 137000000 | F27: ='Investment Characteristics'!E78 -> 230000000 | G27: =F27/D27-1 -> 0.67883212
C28: Avg. Valuation | D28: 1.4014286e+08 | F28: ='Investment Characteristics'!E77 -> 383000000 | G28: =F28/D28-1 -> 1.7329256
B30: Total | C30: # of Deals | D30: 28 | F30: ='Investment Characteristics'!F72 -> 29 | G30: =F30/D30-1 -> 0.035714286
C31: Avg. Initital Inv. | D31: 405289.28 | F31: ='Investment Characteristics'!F69 -> 1286554.6 | G31: =F31/D31-1 -> 2.1744107
C32: Inv. % of Fund Size | D32: =D31/D1 -> 0.019674237 | F32: =F31/F1 -> 0.017624036 | G32: =F32/D32-1 -> -0.10420739
C33: Median FD% | D33: 0.0071 | F33: ='Investment Characteristics'!H35 -> 0.02 | G33: =F33/D33-1 -> 1.8169014
C34: Avg. FD% | D34: 0.0091946146 | F34: ='Investment Characteristics'!H34 -> 0.031544087 | G34: =F34/D34-1 -> 2.4307134
C35: Median Valuation | D35: 25500000 | F35: ='Investment Characteristics'!I35 -> 50000000 | G35: =F35/D35-1 -> 0.96078431
C36: Avg. Valuation | D36: 59000000 | F36: ='Investment Characteristics'!I34 -> 1.1215172e+08 | G36: =F36/D36-1 -> 0.90087668

Sheet Investment Characteristics
N1: Updated as of 9.30 | V1: =74*10^6 -> 74000000
B2: Initial Investment Characteristics | K2: Current Investment Characteristics | AM2: VOTING - "overall" by IC member | AU2: Avg Vote - by category | AY2: *Missing Vote | AZ2: Double-check | BD2: Scorecards - by category
B3: Company | C3: Date | D3: Series | E3: Sector | F3: $ Invested | G3: VC Syndicate | H3: FD% | I3: Avg. Cost | K3: Company | L3: Series | M3: $ Invested | N3: FD% | O3: Initital Cost | P3: Avg. Cost | Q3: Last Valuation | R3: Holding Value | S3: $ Invested | T3: Market Value | U3: Multiple | V3: RTF | X3: 44285 | Y3: 44469 | Z3: 44742 | AA3: 44926 | AB3: 45107 | AC3: 45291 | AD3: 45473 | AE3: 45565 | AF3: 45657 | AG3: 45838 | AH3: 45930 | AI3: Rationale | AJ3: Runway | AM3: ABG | AN3: CBOU | AO3: Colin | AP3: Greg | AQ3: Robby | AS3: Overall | AT3: Team | AU3: Tech | AV3: TAM | AW3: Timing | AX3: Terms | BB3: Lead | BC3: Qual. Total | BD3: Quant. Total | BE3: Deal Terms | BF3: Total | BG3: Notes
B4: Brightline | C4: =INDEX('Statement of Investments'!$C$5:$C$220,MATCH('Investment Characteristics'!$B4,'Statement of Investments'!$B$5:$B$220,0)) -> 44047 | D4: A | E4: Healthtech | F4: =INDEX('Statement of Investments'!$L$5:$L$220,MATCH('Investment Characteristics'!$B4,'Statement of Investments'!$B$5:$B$220,0)) -> 499998.47 | G4: GV, Oak HC/FT, Threshold | H4: 0.006249969 | I4: 80000000 | K4: =B4 -> Brightline | L4: C | M4: =INDEX('Statement of Investments'!$L$5:$L$220,MATCH('Investment Characteristics'!$K4,'Statement of Investments'!$E$5:$E$220,0)) -> 1499987 | N4: 0.0060300575 | O4: =I4 -> 80000000 | P4: =IFERROR(ROUND(S4/N4,-5),0) -> 248800000 | Q4: 757442906 | R4: =+Q4 -> 757442906 | S4: =INDEX('Statement of Investments'!$L$5:$L$220,MATCH(B4,'Statement of Investments'!$E$5:$E$220,0)) -> 1499987 | T4: =INDEX('Statement of Investments'!$O$5:$O$220,MATCH(B4,'Statement of Investments'!$E$5:$E$220,0)) -> 4521963.7 | U4: =T4/S4 -> 3.0146685 | V4: =+$V$1/N4/10^6 -> 12271.857 | X4: 0 | Y4: 0 | Z4: -1 | AA4: 0 | AB4: 0 | AC4: 1 | AD4: 1 | AE4: 1 | AF4: 1 | AG4: 1 | AH4: 0 | AI4: Revenue is down slightly yoy, profitable this year. Focusing on delivering care in person, opened 3rd clinic in NY, leadership change, revenue growth -ve, have they de-risked the hybrid model yet? Can it grow and scale? Valuation multiple seems high given the fact pattern | AM4: 2 | AN4: 1 | AO4: 2 | AP4: 1 | AQ4: 2 | AS4: 1.6 | AT4: 1.8 | AU4: 0.6 | AV4: 2 | AW4: 2 | AX4: 0.2 | BB4: ABG | BC4: 49.8 | BD4: 6.5 | BE4: 7 | BF4: 63.3
B5: Murmur | C5: =INDEX('Statement of Investments'!$C$5:$C$220,MATCH('Investment Characteristics'!$B5,'Statement of Investments'!$B$5:$B$220,0)) -> 44098 | D5: Seed | E5: Workforce | F5: =INDEX('Statement of Investments'!$L$5:$L$220,MATCH('Investment Characteristics'!$B5,'Statement of Investments'!$B$5:$B$220,0)) -> 225000 | G5: Lerer Hippeau, Human Ventures | H5: 0.026471511 | I5: =IFERROR(ROUND(F5/H5,-5),0) -> 8500000 | K5: Murmur | L5: Seed | M5: =INDEX('Statement of Investments'!$L$5:$L$220,MATCH('Investment Characteristics'!$K5,'Statement of Investments'!$E$5:$E$220,0)) -> 1574998 | N5: 0.064069691 | O5: =I5 -> 8500000 | P5: =IFERROR(ROUND(S5/N5,-5),0) -> 24600000 | Q5: =28*10^6 -> 28000000 | R5: 0 | S5: =INDEX('Statement of Investments'!$L$5:$L$220,MATCH(B5,'Statement of Investments'!$E$5:$E$220,0)) -> 1574998 | T5: =INDEX('Statement of Investments'!$O$5:$O$220,MATCH(B5,'Statement of Investments'!$E$5:$E$220,0)) -> 0 | U5: =T5/S5 -> 0 | V5: =+$V$1/N5/10^6 -> 1154.9923 | X5: 0 | Y5: 0 | Z5: 1 | AA5: 0 | AB5: 0 | AC5: 1 | AD5: 0 | AE5: 0 | AF5: -1 | AG5: -1 | AH5: -1 | AI5: N/A - shutdown | AM5: 1 | AN5: 1 | AO5: 1 | AP5: 1 | AQ5: 1 | AS5: 1 | AT5: 1.3 | AU5: 0.7 | AV5: 1.7 | AW5: 2 | AX5: 2 | BB5: ABG | BC5: 44 | BD5: 8 | BE5: 9 | BF5: 61
B6: Pinwheel | C6: =INDEX('Statement of Investments'!$C$5:$C$220,MATCH('Investment Characteristics'!$B6,'Statement of Investments'!$B$5:$B$220,0)) -> 44105 | D6: A | E6: Financial | F6: =INDEX('Statement of Investments'!$L$5:$L$220,MATCH('Investment Characteristics'!$B6,'Statement of Investments'!$B$5:$B$220,0)) -> 499997.04 | G6: Coatue, First Round, Upfront | H6: 0.005 | I6: =IFERROR(ROUND(F6/H6,-5),0) -> 100000000 | K6: Pinwheel | L6: B | M6: =INDEX('Statement of Investments'!$L$5:$L$220,MATCH('Investment Characteristics'!$K6,'Statement of Investments'!$E$5:$E$220,0)) -> 1453156.1 | N6: 0.0057927248 | O6: =I6 -> 100000000 | P6: =IFERROR(ROUND(S6/N6,-5),0) -> 250900000 | Q6: 5.0637434e+08 | R6: Pref Stack - $78M | S6: =INDEX('Statement of Investments'!$L$5:$L$220,MATCH(B6,'Statement of Investments'!$E$5:$E$220,0)) -> 1453156.1 | T6: =INDEX('Statement of Investments'!$O$5:$O$220,MATCH(B6,'Statement of Investments'!$E$5:$E$220,0)) -> 1453156.1 | U6: =T6/S6 -> 1 | V6: =+$V$1/N6/10^6 -> 12774.644 | X6: 0 | Y6: 1 | Z6: 1 | AA6: 1 | AB6: 0 | AC6: 0 | AD6: 0 | AE6: 0 | AF6: 0 | AG6: 0 | AH6: 0 | AI6: 30 months of runway, undergoing CEO change, written-down to cost in Q3 | AJ6: 30 months | AM6: 2 | AN6: 1 | AO6: 1 | AP6: 1 | AQ6: 1 | AS6: 1.2 | AT6: 1 | AU6: 0.6 | AV6: 2 | AW6: 1.8 | AX6: 0.2 | BB6: RP/ABG | BC6: 46.5 | BD6: 10.5 | BE6: 7 | BF6: 64
B7: Cleo | C7: =INDEX('Statement of Investments'!$C$5:$C$220,MATCH('Investment Characteristics'!$B7,'Statement of Investments'!$B$5:$B$220,0)) -> 44155 | D7: B | E7: Healthtech | F7: =INDEX('Statement of Investments'!$L$5:$L$220,MATCH('Investment Characteristics'!$B7,'Statement of Investments'!$B$5:$B$220,0)) -> 599997.84 | G7: Felicis, Forerunner, Greylock | H7: =F7/115000000 -> 0.0052173725 | I7: =IFERROR(ROUND(F7/H7,-5),0) -> 115000000 | K7: Cleo | L7: C | M7: =INDEX('Statement of Investments'!$L$5:$L$220,MATCH('Investment Characteristics'!$K7,'Statement of Investments'!$E$5:$E$220,0)) -> 599997.84 | N7: 0.0040460588 | O7: =I7 -> 115000000 | P7: =IFERROR(ROUND(S7/N7,-5),0) -> 148300000 | Q7: 231000000 | R7: 0 | S7: =INDEX('Statement of Investments'!$L$5:$L$220,MATCH(B7,'Statement of Investments'!$E$5:$E$220,0)) -> 599997.84 | T7: =INDEX('Statement of Investments'!$O$5:$O$220,MATCH(B7,'Statement of Investments'!$E$5:$E$220,0)) -> 0 | U7: =T7/S7 -> 0 | V7: =+$V$1/N7/10^6 -> 18289.403 | X7: 1 | Y7: 1 | Z7: 1 | AA7: 0 | AB7: -1 | AC7: 0 | AD7: -1 | AE7: -1 | AF7: -1 | AG7: -1 | AH7: -1 | AI7: N/A - proactive write-off | AM7: 1 | AN7: 2 | AO7: 1 | AP7: 1 | AQ7: 2 | AS7: 1.4 | AT7: 1.4 | AU7: 1 | AV7: 1.2 | AW7: 2 | AX7: 1.8 | BB7: RP | BC7: 35.3 | BD7: 12 | BE7: 7 | BF7: 54.3
B8: Rightfoot | C8: =INDEX('Statement of Investments'!$C$5:$C$220,MATCH('Investment Characteristics'!$B8,'Statement of Investments'!$B$5:$B$220,0)) -> 44175 | D8: Seed | E8: Financial | F8: =INDEX('Statement of Investments'!$L$5:$L$220,MATCH('Investment Characteristics'!$B8,'Statement of Investments'!$B$5:$B$220,0)) -> 399999.32 | G8: Bain Capital, LSVP | H8: 0.02 | I8: =IFERROR(ROUND(F8/H8,-5),0) -> 20000000 | K8: Rightfoot | L8: A | M8: =INDEX('Statement of Investments'!$L$5:$L$220,MATCH('Investment Characteristics'!$K8,'Statement of Investments'!$E$5:$E$220,0)) -> 399999.32 | N8: 0.012564741 | O8: =I8 -> 20000000 | P8: =IFERROR(ROUND(S8/N8,-5),0) -> 31800000 | Q8: =55*10^6 -> 55000000 | R8: 0 | S8: =INDEX('Statement of Investments'!$L$5:$L$220,MATCH(B8,'Statement of Investments'!$E$5:$E$220,0)) -> 399999.32 | T8: =INDEX('Statement of Investments'!$O$5:$O$220,MATCH(B8,'Statement of Investments'!$E$5:$E$220,0)) -> 0 | U8: =T8/S8 -> 0 | V8: =+$V$1/N8/10^6 -> 5889.4968 | X8: 0 | Y8: 0 | Z8: 1 | AA8: 0 | AB8: 0 | AC8: -1 | AD8: -1 | AE8: -1 | AF8: -1 | AG8: 0 | AH8: 0 | AI8: Showing signs of significant growth after undergoing pivot, monitoring to write back up to cost | AM8: 1 | AN8: 2 | AO8: 1 | AP8: 1 | AQ8: 1 | AS8: 1.2 | AT8: 1.2 | AU8: 1.4 | AV8: 1 | AW8: 1.6 | AX8: 1.8 | BB8: CH | BC8: 41 | BD8: 9.8 | BE8: 4 | BF8: 54.8
B9: Mathison | C9: =INDEX('Statement of Investments'!$C$5:$C$220,MATCH('Investment Characteristics'!$B9,'Statement of Investments'!$B$5:$B$220,0)) -> 44176 | D9: Seed | E9: Workforce | F9: =INDEX('Statement of Investments'!$L$5:$L$220,MATCH('Investment Characteristics'!$B9,'Statement of Investments'!$B$5:$B$220,0)) -> 299999.56 | G9: Bain Capital | H9: 0.020000165 | I9: =IFERROR(ROUND(F9/H9,-5),0) -> 15000000 | K9: Mathison | L9: Acq. | M9: =INDEX('Statement of Investments'!$L$5:$L$220,MATCH('Investment Characteristics'!$K9,'Statement of Investments'!$E$5:$E$220,0)) -> 2049994.2 | N9: 0.04 | O9: =I9 -> 15000000 | P9: =IFERROR(ROUND(S9/N9,-5),0) -> 51200000 | Q9: 70000000 | R9: =+Q9 -> 70000000 | S9: =INDEX('Statement of Investments'!$L$5:$L$220,MATCH(B9,'Statement of Investments'!$E$5:$E$220,0)) -> 2049994.2 | T9: =INDEX('Statement of Investments'!$O$5:$O$220,MATCH(B9,'Statement of Investments'!$E$5:$E$220,0)) -> 272298.82 | U9: =T9/S9 -> 0.13282907 | V9: =+$V$1/N9/10^6 -> 1850 | X9: 1 | Y9: 1 | Z9: 1 | AA9: -1 | AB9: -1 | AC9: -1 | AM9: 2 | AN9: 2 | AO9: 2 | AP9: 1 | AQ9: 1 | AS9: 1.6 | AT9: 0.8 | AU9: 1 | AV9: 1.2 | AW9: 2 | AX9: 1.8 | BB9: ABG | BC9: 46 | BD9: 15 | BE9: 4 | BF9: 65
B10: Galileo | C10: =INDEX('Statement of Investments'!$C$5:$C$220,MATCH('Investment Characteristics'!$B10,'Statement of Investments'!$B$5:$B$220,0)) -> 44232 | D10: C | E10: Healthtech | F10: =INDEX('Statement of Investments'!$L$5:$L$220,MATCH('Investment Characteristics'!$B10,'Statement of Investments'!$B$5:$B$220,0)) -> 1999999.2 | G10: Foresite Capital, Oak HC/FT, 8VC | H10: 0.0050633027 | I10: =IFERROR(ROUND(F10/H10,-5),0) -> 395000000 | K10: Galileo | L10: E | M10: =INDEX('Statement of Investments'!$L$5:$L$220,MATCH('Investment Characteristics'!$K10,'Statement of Investments'!$E$5:$E$220,0)) -> 2163901.7 | N10: 0.0041856851 | O10: =I10 -> 395000000 | P10: =IFERROR(ROUND(S10/N10,-5),0) -> 517000000 | Q10: 361500000 | R10: =+Q10 -> 361500000 | S10: =INDEX('Statement of Investments'!$L$5:$L$220,MATCH(B10,'Statement of Investments'!$E$5:$E$220,0)) -> 2163901.7 | T10: =INDEX('Statement of Investments'!$O$5:$O$220,MATCH(B10,'Statement of Investments'!$E$5:$E$220,0)) -> 1724878.8 | U10: =T10/S10 -> 0.79711515 | V10: =+$V$1/N10/10^6 -> 17679.304 | X10: 1 | Y10: 0 | Z10: 0 | AA10: 2 | AB10: 0 | AC10: -1 | AD10: -1 | AE10: -1 | AF10: -1 | AG10: -1 | AH10: 0 | AI10: Completed recap in Q3, completing transition away from shared savings to FFS / Capitated | AM10: 1 | AN10: 1 | AO10: 1 | AP10: 2 | AQ10: 2 | AS10: 1.4 | AT10: 2 | AU10: 1.2 | AV10: 2 | AW10: 1.8 | AX10: -0.4 | BB10: GG | BC10: 45.5 | BD10: 10.5 | BE10: 7 | BF10: 63
B11: Cocoon | C11: =INDEX('Statement of Investments'!$C$5:$C$220,MATCH('Investment Characteristics'!$B11,'Statement of Investments'!$B$5:$B$220,0)) -> 44232 | D11: Seed | E11: Workforce | F11: =INDEX('Statement of Investments'!$L$5:$L$220,MATCH('Investment Characteristics'!$B11,'Statement of Investments'!$B$5:$B$220,0)) -> 224999.42 | G11: Index Ventures, XYZ Capital | H11: 0.0073744678 | I11: =IFERROR(ROUND(F11/H11,-5),0) -> 30500000 | K11: Cocoon | L11: A | M11: =INDEX('Statement of Investments'!$L$5:$L$220,MATCH('Investment Characteristics'!$K11,'Statement of Investments'!$E$5:$E$220,0)) -> 4224996.6 | N11: 0.027242491 | O11: =I11 -> 30500000 | P11: =IFERROR(ROUND(S11/N11,-5),0) -> 155100000 | Q11: 1.6250158e+08 | R11: Pref Stack - $26M | S11: =INDEX('Statement of Investments'!$L$5:$L$220,MATCH(B11,'Statement of Investments'!$E$5:$E$220,0)) -> 4224996.6 | T11: =INDEX('Statement of Investments'!$O$5:$O$220,MATCH(B11,'Statement of Investments'!$E$5:$E$220,0)) -> 4224996.6 | U11: =T11/S11 -> 1 | V11: =+$V$1/N11/10^6 -> 2716.3448 | X11: 1 | Y11: 1 | Z11: 1 | AA11: 1 | AB11: 1 | AC11: 1 | AD11: 0 | AE11: 0 | AF11: 0 | AG11: 0 | AH11: 0 | AI11: Contracted ARR at ~$10M, strong product expansion and channel traction with Gurdian/Sedgewick moving into enterprises, moved into variable hourly workers market (increased TAM?). Increased distribution scale + partner validation should move this into green? Rev multiple seems high | AJ11: 8 months | AM11: 1 | AN11: 1 | AO11: 1 | AQ11: 1 | AS11: 1 | AT11: 1.5 | AU11: 0.8 | AV11: 1.5 | AW11: 1.5 | AX11: 1 | BB11: RP | BC11: 48.5 | BD11: 11.3 | BF11: 59.8
A12: x | B12: Rula | C12: =INDEX('Statement of Investments'!$C$5:$C$220,MATCH('Investment Characteristics'!$B12,'Statement of Investments'!$B$5:$B$220,0)) -> 44265 | D12: A | E12: Healthtech | F12: =INDEX('Statement of Investments'!$L$5:$L$220,MATCH('Investment Characteristics'!$B12,'Statement of Investments'!$B$5:$B$220,0)) -> 1500000 | G12: Wing Ventures, Upfront Ventures | H12: 0.023774266 | I12: =IFERROR(ROUND(F12/H12,-5),0) -> 63100000 | K12: Rula | L12: C | M12: =INDEX('Statement of Investments'!$L$5:$L$220,MATCH('Investment Characteristics'!$K12,'Statement of Investments'!$E$5:$E$220,0)) -> 4500000 | N12: 0.0207 | O12: =I12 -> 63100000 | P12: =IFERROR(ROUND(S12/N12,-5),0) -> 217400000 | Q12: 1250000000 | R12: =+Q12 -> 1250000000 | S12: =INDEX('Statement of Investments'!$L$5:$L$220,MATCH(B12,'Statement of Investments'!$E$5:$E$220,0)) -> 4500000 | T12: =INDEX('Statement of Investments'!$O$5:$O$220,MATCH(B12,'Statement of Investments'!$E$5:$E$220,0)) -> 25285301 | U12: =T12/S12 -> 5.6189558 | V12: =+$V$1/N12/10^6 -> 3574.8792 | X12: 1 | Y12: 1 | Z12: 1 | AA12: 1 | AB12: 1 | AC12: 1 | AD12: 1 | AE12: 1 | AF12: 1 | AG12: 1 | AH12: 1 | AI12: Forecasting 2x y/y growth with revenue run rate above $200M by year end | AM12: 1 | AN12: 1 | AP12: 1 | AQ12: 2 | AS12: 1.3 | AT12: 1.3 | AU12: 0 | AV12: 1.5 | AW12: 2 | AX12: 1 | BB12: RP | BC12: 45.5 | BD12: 10 | BE12: 7 | BF12: 62.5
B13: Origin | C13: =INDEX('Statement of Investments'!$C$5:$C$220,MATCH('Investment Characteristics'!$B13,'Statement of Investments'!$B$5:$B$220,0)) -> 44307 | D13: A | E13: Financial | F13: =INDEX('Statement of Investments'!$L$5:$L$220,MATCH('Investment Characteristics'!$B13,'Statement of Investments'!$B$5:$B$220,0)) -> 1699997.1 | G13: Felicis, 01 Advisors, General Catalyst | H13: 0.013599977 | I13: =IFERROR(ROUND(F13/H13,-5),0) -> 125000000 | K13: Origin | L13: B | M13: =INDEX('Statement of Investments'!$L$5:$L$220,MATCH('Investment Characteristics'!$K13,'Statement of Investments'!$E$5:$E$220,0)) -> 3699992.1 | N13: 0.027099272 | O13: =I13 -> 125000000 | P13: =IFERROR(ROUND(S13/N13,-5),0) -> 136500000 | Q13: 401250000 | R13: =P13 -> 136500000 | S13: =INDEX('Statement of Investments'!$L$5:$L$220,MATCH(B13,'Statement of Investments'!$E$5:$E$220,0)) -> 3699992.1 | T13: =INDEX('Statement of Investments'!$O$5:$O$220,MATCH(B13,'Statement of Investments'!$E$5:$E$220,0)) -> 3699992.1 | U13: =T13/S13 -> 1 | V13: =+$V$1/N13/10^6 -> 2730.7007 | X13: 1 | Y13: 1 | Z13: 1 | AA13: 0 | AB13: 0 | AC13: 0 | AD13: 0 | AE13: 0 | AF13: 0 | AG13: 0 | AH13: 0 | AI13: Wrote down to preference stack, undergoing pivot away from B2B model | AJ13: 19 months | AM13: 1 | AN13: 2 | AQ13: 2 | AS13: 1.7 | AT13: 2 | AU13: 1 | AV13: 1.7 | AW13: 1.3 | AX13: 1 | BB13: CH/RP | BC13: 50.5 | BD13: 8 | BE13: 6.5 | BF13: 65
B14: Nayya | C14: =INDEX('Statement of Investments'!$C$5:$C$220,MATCH('Investment Characteristics'!$B14,'Statement of Investments'!$B$5:$B$220,0)) -> 44344 | D14: B | E14: Healthtech | F14: =INDEX('Statement of Investments'!$L$5:$L$220,MATCH('Investment Characteristics'!$B14,'Statement of Investments'!$B$5:$B$220,0)) -> 500000 | G14: Felicis, Iconiq, SVB Capital | H14: 0.002173913 | I14: =IFERROR(ROUND(F14/H14,-5),0) -> 230000000 | K14: Nayya | L14: C | M14: =INDEX('Statement of Investments'!$L$5:$L$220,MATCH('Investment Characteristics'!$K14,'Statement of Investments'!$E$5:$E$220,0)) -> 2699987.1 | N14: 0.0076636442 | O14: =I14 -> 230000000 | P14: =IFERROR(ROUND(S14/N14,-5),0) -> 352300000 | Q14: 5.049535e+08 | R14: =+Q14 -> 5.049535e+08 | S14: =INDEX('Statement of Investments'!$L$5:$L$220,MATCH(B14,'Statement of Investments'!$E$5:$E$220,0)) -> 2699987.1 | T14: =INDEX('Statement of Investments'!$O$5:$O$220,MATCH(B14,'Statement of Investments'!$E$5:$E$220,0)) -> 3853385.4 | U14: =T14/S14 -> 1.4271866 | V14: =+$V$1/N14/10^6 -> 9655.9806 | X14: 1 | Y14: 1 | Z14: 0 | AA14: 0 | AB14: 0 | AC14: 1 | AD14: 1 | AE14: 1 | AF14: 1 | AG14: 1 | AH14: 0 | AI14: Reduced ARR forecast by 20%, reduced growth <2x, strong partnerships are encouraging but needs to convert to ARR contribution and signed deployments. Would suggest yellow. | AJ14: 17 months | AM14: 1 | AN14: 1 | AP14: 1 | AQ14: 1 | AS14: 1 | AT14: 1 | AU14: 1.5 | AV14: 1.8 | AW14: 1.5 | AX14: 0.3 | BB14: RP | BC14: 47.5 | BF14: 47.5
B15: Praisidio | C15: =INDEX('Statement of Investments'!$C$5:$C$220,MATCH('Investment Characteristics'!$B15,'Statement of Investments'!$B$5:$B$220,0)) -> 44370 | D15: Seed | E15: Workforce | F15: =INDEX('Statement of Investments'!$L$5:$L$220,MATCH('Investment Characteristics'!$B15,'Statement of Investments'!$B$5:$B$220,0)) -> 200000 | G15: Signal Fire, Storm Ventures | H15: 0.01 | I15: =IFERROR(ROUND(F15/H15,-5),0) -> 20000000 | K15: Praisidio | L15: Seed | M15: =INDEX('Statement of Investments'!$L$5:$L$220,MATCH('Investment Characteristics'!$K15,'Statement of Investments'!$E$5:$E$220,0)) -> 200000 | N15: 0.01 | O15: =I15 -> 20000000 | P15: =IFERROR(ROUND(S15/N15,-5),0) -> 20000000 | Q15: 20000000 | R15: 0 | S15: =INDEX('Statement of Investments'!$L$5:$L$220,MATCH(B15,'Statement of Investments'!$E$5:$E$220,0)) -> 200000 | T15: =INDEX('Statement of Investments'!$O$5:$O$220,MATCH(B15,'Statement of Investments'!$E$5:$E$220,0)) -> 0 | U15: =T15/S15 -> 0 | V15: =+$V$1/N15/10^6 -> 7400 | X15: 1 | Y15: 1 | Z15: 0 | AA15: 0 | AB15: 0 | AC15: 0 | AD15: 0 | AE15: 0 | AF15: -1 | AG15: -1 | AH15: -1 | AI15: N/A - proactive write-off | AM15: 2 | AN15: 2 | AP15: 1 | AQ15: 1 | AS15: 1.5 | AT15: 1.5 | AU15: 1 | AV15: 1 | AW15: 2 | AX15: 1.8 | BB15: ABG | BC15: 46.5 | BD15: 13 | BE15: 9 | BF15: 68.5
B16: Bravely | C16: =INDEX('Statement of Investments'!$C$5:$C$220,MATCH('Investment Characteristics'!$B16,'Statement of Investments'!$B$5:$B$220,0)) -> 44379 | D16: A | E16: Workforce | F16: =INDEX('Statement of Investments'!$L$5:$L$220,MATCH('Investment Characteristics'!$B16,'Statement of Investments'!$B$5:$B$220,0)) -> 1249999.6 | G16: Telescope Partners, Primary Venture Partners | H16: 0.018518542 | I16: =IFERROR(ROUND(F16/H16,-5),0) -> 67500000 | K16: Bravely | L16: A | M16: =INDEX('Statement of Investments'!$L$5:$L$220,MATCH('Investment Characteristics'!$K16,'Statement of Investments'!$E$5:$E$220,0)) -> 1249999.6 | N16: 0.018518542 | O16: =I16 -> 67500000 | P16: =IFERROR(ROUND(S16/N16,-5),0) -> 67500000 | Q16: 67500000 | R16: =+Q16 -> 67500000 | S16: =INDEX('Statement of Investments'!$L$5:$L$220,MATCH(B16,'Statement of Investments'!$E$5:$E$220,0)) -> 1249999.6 | T16: =INDEX('Statement of Investments'!$O$5:$O$220,MATCH(B16,'Statement of Investments'!$E$5:$E$220,0)) -> 1249999.6 | U16: =T16/S16 -> 1 | V16: =+$V$1/N16/10^6 -> 3995.995 | X16: 1 | Y16: 1 | Z16: 0 | AA16: -1 | AB16: -1 | AC16: -1 | AD16: -1 | AE16: -1 | AF16: -1 | AG16: -1 | AH16: -1 | AI16: Looking to capture AI tailwinds with a $5M+ install base | AM16: 2 | AN16: 1 | AO16: 1 | AP16: 1 | AQ16: 1 | AS16: 1.2 | AT16: 1.2 | AU16: 0.4 | AV16: 1.4 | AW16: 2 | AX16: 1.6 | BB16: ABG | BC16: 45 | BD16: 13.5 | BF16: 58.5 | BG16: No scorecard, pulled from Investment Diligence
A17: x | B17: Remote | C17: =INDEX('Statement of Investments'!$C$5:$C$220,MATCH('Investment Characteristics'!$B17,'Statement of Investments'!$B$5:$B$220,0)) -> 44398 | D17: B | E17: Workforce | F17: =INDEX('Statement of Investments'!$L$5:$L$220,MATCH('Investment Characteristics'!$B17,'Statement of Investments'!$B$5:$B$220,0)) -> 3999979.6 | G17: Accel, General Catalyst, Index, Sequoia | H17: 0.0039999789 | I17: =IFERROR(ROUND(F17/H17,-5),0) -> 1000000000 | K17: Remote | L17: C | M17: =INDEX('Statement of Investments'!$L$5:$L$220,MATCH('Investment Characteristics'!$K17,'Statement of Investments'!$E$5:$E$220,0)) -> 4781446 | N17: 0.003599981 | O17: =I17 -> 1000000000 | P17: =IFERROR(ROUND(S17/N17,-5),0) -> 1328200000 | Q17: 3000000000 | R17: =+Q17 -> 3000000000 | S17: =INDEX('Statement of Investments'!$L$5:$L$220,MATCH(B17,'Statement of Investments'!$E$5:$E$220,0)) -> 4781446 | T17: =INDEX('Statement of Investments'!$O$5:$O$220,MATCH(B17,'Statement of Investments'!$E$5:$E$220,0)) -> 10354762 | U17: =T17/S17 -> 2.165613 | V17: =+$V$1/N17/10^6 -> 20555.664 | X17: 1 | Y17: 1 | Z17: 0 | AA17: 0 | AB17: 1 | AC17: 1 | AD17: 1 | AE17: 1 | AF17: 1 | AG17: 1 | AH17: 1 | AI17: Forecasting to accelerate above $350M ARR, continued tailwinds from global workforce | AM17: 2 | AN17: 1 | AP17: 1 | AQ17: 2 | AS17: 1.5 | AT17: 2 | AU17: 1.8 | AV17: 2 | AW17: 1.8 | AX17: 0.3 | BB17: RP | BC17: 52.5 | BD17: 14.3 | BF17: 66.8
B18: Finch | C18: =INDEX('Statement of Investments'!$C$5:$C$220,MATCH('Investment Characteristics'!$B18,'Statement of Investments'!$B$5:$B$220,0)) -> 44435 | D18: A | E18: Financial | F18: =INDEX('Statement of Investments'!$L$5:$L$220,MATCH('Investment Characteristics'!$B18,'Statement of Investments'!$B$5:$B$220,0)) -> 500003.42 | G18: Menlo, General Catalyst, Box Group | H18: 0.0043467434 | I18: =IFERROR(ROUND(F18/H18,-5),0) -> 115000000 | K18: Finch | L18: B | M18: =INDEX('Statement of Investments'!$L$5:$L$220,MATCH('Investment Characteristics'!$K18,'Statement of Investments'!$E$5:$E$220,0)) -> 500003.42 | N18: 0.0032205422 | O18: =I18 -> 115000000 | P18: =IFERROR(ROUND(S18/N18,-5),0) -> 155300000 | Q18: 230000392 | R18: =+Q18 -> 230000392 | S18: =INDEX('Statement of Investments'!$L$5:$L$220,MATCH(B18,'Statement of Investments'!$E$5:$E$220,0)) -> 500003.42 | T18: =INDEX('Statement of Investments'!$O$5:$O$220,MATCH(B18,'Statement of Investments'!$E$5:$E$220,0)) -> 740862.12 | U18: =T18/S18 -> 1.4817141 | V18: =+$V$1/N18/10^6 -> 22977.498 | X18: 1 | Y18: 1 | Z18: 1 | AA18: 1 | AB18: 1 | AC18: 1 | AD18: 1 | AE18: 1 | AF18: 1 | AG18: 1 | AH18: 0 | AI18: HR Tech API, Modest growth in Rev, ARR is down ~10% when compared to product traction (seems substantial), high growth margins ~80%, val multiples seem high when compared to industry (peaking at ~20x), retention/churn metrics and high val multiple would suggest yellow (high yellow - cautious but positive) | AJ18: 34 months | AM18: 1 | AN18: 1 | AQ18: 1 | AS18: 1 | AT18: 1 | AU18: 1.7 | AV18: 1.3 | AW18: 1.7 | AX18: 0.3 | BB18: RP | BC18: 46.5 | BD18: 14 | BE18: 2 | BF18: 62.5
A19: x | B19: Midi | C19: =INDEX('Statement of Investments'!$C$5:$C$220,MATCH('Investment Characteristics'!$B19,'Statement of Investments'!$B$5:$B$220,0)) -> 44455 | D19: Seed | E19: Healthtech | F19: =INDEX('Statement of Investments'!$L$5:$L$220,MATCH('Investment Characteristics'!$B19,'Statement of Investments'!$B$5:$B$220,0)) -> 510137 | G19: Icon Ventures | H19: =F19/10000000 -> 0.0510137 | I19: =IFERROR(ROUND(F19/H19,-5),0) -> 10000000 | K19: Midi | L19: D | M19: =INDEX('Statement of Investments'!$L$5:$L$220,MATCH('Investment Characteristics'!$K19,'Statement of Investments'!$E$5:$E$220,0)) -> 5531507 | N19: 0.0483 | O19: =I19 -> 10000000 | P19: =IFERROR(ROUND(S19/N19,-5),0) -> 114500000 | Q19: 1150000000 | R19: =+Q19 -> 1150000000 | S19: =INDEX('Statement of Investments'!$L$5:$L$220,MATCH(B19,'Statement of Investments'!$E$5:$E$220,0)) -> 5531507 | T19: =INDEX('Statement of Investments'!$O$5:$O$220,MATCH(B19,'Statement of Investments'!$E$5:$E$220,0)) -> 48185999 | U19: =T19/S19 -> 8.7111883 | V19: =+$V$1/N19/10^6 -> 1532.0911 | X19: 1 | Y19: 1 | Z19: 1 | AA19: 1 | AB19: 1 | AC19: 1 | AD19: 1 | AE19: 1 | AF19: 1 | AG19: 1 | AH19: 1 | AI19: Beating and raising, ~$190M in revenue growing ~5x y/y | AM19: 2 | AN19: 2 | AO19: 1 | AP19: 1 | AQ19: 1 | AS19: 1.4 | AT19: 1.6 | AU19: 0.2 | AV19: 1.8 | AW19: 1.4 | AX19: 1.8 | BB19: ABG | BC19: 41.5 | BD19: 8 | BF19: 49.5 | BG19: No scorecard, pulled from Investment Diligence
B20: ianacare | C20: =INDEX('Statement of Investments'!$C$5:$C$220,MATCH('Investment Characteristics'!$B20,'Statement of Investments'!$B$5:$B$220,0)) -> 44547 | D20: A | E20: Healthtech | F20: =INDEX('Statement of Investments'!$L$5:$L$220,MATCH('Investment Characteristics'!$B20,'Statement of Investments'!$B$5:$B$220,0)) -> 999984.87 | G20: Greycroft, 8VC | H20: 0.016666456 | I20: =IFERROR(ROUND(F20/H20,-5),0) -> 60000000 | K20: ianacare | L20: A | M20: =INDEX('Statement of Investments'!$L$5:$L$220,MATCH('Investment Characteristics'!$K20,'Statement of Investments'!$E$5:$E$220,0)) -> 2999984.9 | N20: 0.01664562 | O20: =I20 -> 60000000 | P20: =+O20 -> 60000000 | Q20: =P20 -> 60000000 | R20: =+Q20 -> 60000000 | S20: =INDEX('Statement of Investments'!$L$5:$L$220,MATCH(B20,'Statement of Investments'!$E$5:$E$220,0)) -> 2999984.9 | T20: =INDEX('Statement of Investments'!$O$5:$O$220,MATCH(B20,'Statement of Investments'!$E$5:$E$220,0)) -> 2999984.9 | U20: =T20/S20 -> 1 | V20: =+$V$1/N20/10^6 -> 4445.6139 | Y20: 1 | Z20: 1 | AA20: 1 | AB20: 1 | AC20: 0 | AD20: -1 | AE20: -1 | AF20: 0 | AG20: 0 | AH20: 0 | AI20: Regulatory tailwinds from GUIDE program driving growth as company shifts away from employer. Expect GUIDE revenue to ramp from 6 digit ARR to 7 digit ARR in the next 6-9 months. They revised 2025E ARR projectons down by 25% but expect visibility into GUIDE related ARR to dramatically increase over next 12 months. | AJ20: 12 months | AM20: 2 | AN20: 1 | AO20: 2 | AP20: 1 | AQ20: 1 | AS20: 1.4 | AT20: 2 | AU20: 1.4 | AV20: 1 | AW20: 1.8 | AX20: 1 | BB20: ABG | BC20: 47.8 | BD20: 15 | BF20: 62.8
B21: Vivante | C21: =INDEX('Statement of Investments'!$C$5:$C$220,MATCH('Investment Characteristics'!$B21,'Statement of Investments'!$B$5:$B$220,0)) -> 44552 | D21: A | E21: Healthtech | F21: =INDEX('Statement of Investments'!$L$5:$L$220,MATCH('Investment Characteristics'!$B21,'Statement of Investments'!$B$5:$B$220,0)) -> 999999 | G21: 7Wire, NFP | H21: 0.045928552 | I21: =IFERROR(ROUND(F21/H21,-5),0) -> 21800000 | K21: Vivante | L21: B | M21: =INDEX('Statement of Investments'!$L$5:$L$220,MATCH('Investment Characteristics'!$K21,'Statement of Investments'!$E$5:$E$220,0)) -> 2204142.3 | N21: 0.037179658 | O21: =I21 -> 21800000 | P21: =IFERROR(ROUND(S21/N21,-5),0) -> 59300000 | Q21: 84077296 | R21: =+Q21 -> 84077296 | S21: =INDEX('Statement of Investments'!$L$5:$L$220,MATCH(B21,'Statement of Investments'!$E$5:$E$220,0)) -> 2204142.3 | T21: =INDEX('Statement of Investments'!$O$5:$O$220,MATCH(B21,'Statement of Investments'!$E$5:$E$220,0)) -> 3130662 | U21: =T21/S21 -> 1.4203538 | V21: =+$V$1/N21/10^6 -> 1990.3357 | Y21: 1 | Z21: 1 | AA21: -1 | AB21: 1 | AC21: 1 | AD21: 1 | AE21: 1 | AF21: 1 | AG21: 1 | AH21: -1 | AI21: Down round, strucured pay to play with punitive provisions | AM21: 1 | AN21: 2 | AP21: 1 | AQ21: 2 | AS21: 1.5 | AT21: 1.3 | AU21: 1 | AV21: 1.8 | AW21: 1.5 | AX21: 2 | BB21: RP | BC21: 49.5 | BF21: 49.5
B22: a.team | C22: =INDEX('Statement of Investments'!$C$5:$C$220,MATCH('Investment Characteristics'!$B22,'Statement of Investments'!$B$5:$B$220,0)) -> 44567 | D22: A | E22: Workforce | F22: =INDEX('Statement of Investments'!$L$5:$L$220,MATCH('Investment Characteristics'!$B22,'Statement of Investments'!$B$5:$B$220,0)) -> 999998.86 | G22: Spruce, Tiger, Insight, BoxGroup | H22: 0.003076922 | I22: =IFERROR(ROUND(F22/H22,-5),0) -> 325000000 | K22: a.team | L22: A | M22: =INDEX('Statement of Investments'!$L$5:$L$220,MATCH('Investment Characteristics'!$K22,'Statement of Investments'!$E$5:$E$220,0)) -> 999998.86 | N22: 0.0030769253 | O22: =I22 -> 325000000 | P22: =IFERROR(ROUND(S22/N22,-5),0) -> 325000000 | Q22: =P22 -> 325000000 | R22: =+Q22 -> 325000000 | S22: =INDEX('Statement of Investments'!$L$5:$L$220,MATCH(B22,'Statement of Investments'!$E$5:$E$220,0)) -> 999998.86 | T22: =INDEX('Statement of Investments'!$O$5:$O$220,MATCH(B22,'Statement of Investments'!$E$5:$E$220,0)) -> 999998.86 | U22: =T22/S22 -> 1 | V22: =+$V$1/N22/10^6 -> 24049.983 | Y22: 1 | Z22: 1 | AA22: 1 | AB22: 0 | AC22: 1 | AD22: 0 | AE22: 0 | AF22: 0 | AG22: 0 | AH22: 0 | AI22: Over 2 years of runway, $10M+ ARR, Company is running talent marketplace and the model is aligned with usage based model, rather than classic ARR | AY22: Double-check | BB22: ABG | BC22: 51.5 | BD22: 17.8 | BF22: 69.3
